Workbook
Name Demand: 'Data'!$B$18:$B$121
Name HorizonQ: 'Horizon'!$A$18:$A$718
Name HorizonLoss: 'Horizon'!$D$18:$D$718
Name HorizonReached: 'Horizon'!$E$18:$E$718
Name Candidate: 'Discrete'!$A$18:$A$33
Name Reached: 'Discrete'!$F$18:$F$33

Sheet Notes
A1: Chapter 7, single-period stochastic inventory
A3: Five sheets, in the order the chapter works.
A5: Data 104 weeks of demand for the belt, its summary statistics and its histogram.
A6: Nothing here assumes a distribution.
A7: Fit The variance to mean ratio, the family it leaves standing, and the fitted
A8: parameters. Then the horizon, and what each model would have you order.
A9: Horizon The fitted model aggregated over fourteen weeks and walked one belt at a
A10: time, which gives the exact answer the approximations are measured against.
A11: Newsvendor The decision. Inputs are an invoice; the model's costs are derived from them.
A12: Both forms of the expected cost are computed and their difference is displayed.
A13: Discrete The same decision on a small count, walked one unit at a time.
A15: Blue cells are inputs. Grey cells are computed. Yellow cells are a choice the sheet made.
... A22: ones in the chapter. See inventory.newsvendor.FinalBuy in the course code project.

Sheet Data
A1: What was observed
A2: Chapter 7, section 7.3. One hundred and four weeks of demand for the belt. Nothing on this sheet assumes a distribution.
A4: SUMMARY computed from the history below, and nothing else
A5: The median sits beside the mean on purpose. A median well below a mean says the distribution is right-skewed, which rules out the normal before any test is run.
A6: Weeks observed | B6: =COUNT(Demand)
A7: Mean | B7: =AVERAGE(Demand)
A8: Median | B8: =MEDIAN(Demand)
A9: Variance | B9: =_xlfn.VAR.S(Demand)
A10: Standard deviation | B10: =SQRT(_xlfn.VAR.S(Demand))
A11: Coefficient of variation | B11: =SQRT(_xlfn.VAR.S(Demand))/AVERAGE(Demand)
A12: Smallest week | B12: =MIN(Demand)
A13: Largest week | B13: =MAX(Demand)
A15: THE HISTORY week by week, and its shape
A16: Columns C and D bin the same numbers, ten belts to a bin: the row marked 10 counts the weeks that sold 10 through 19. These are the bars of Figure 7.2.
A17: Week | B17: Demand | C17: From | D17: Weeks
A18: 1 | B18: 94 | C18: 0 | D18: =COUNTIFS(Demand,">=0",Demand,"<10")
A19: 2 | B19: 67 | C19: 10 | D19: =COUNTIFS(Demand,">=10",Demand,"<20")
A20: 3 | B20: 31 | C20: 20 | D20: =COUNTIFS(Demand,">=20",Demand,"<30")
A21: 4 | B21: 35 | C21: 30 | D21: =COUNTIFS(Demand,">=30",Demand,"<40")
A22: 5 | B22: 37 | C22: 40 | D22: =COUNTIFS(Demand,">=40",Demand,"<50")
A23: 6 | B23: 2 | C23: 50 | D23: =COUNTIFS(Demand,">=50",Demand,"<60")
A24: 7 | B24: 110 | C24: 60 | D24: =COUNTIFS(Demand,">=60",Demand,"<70")
A25: 8 | B25: 29 | C25: 70 | D25: =COUNTIFS(Demand,">=70",Demand,"<80")
A26: 9 | B26: 8 | C26: 80 | D26: =COUNTIFS(Demand,">=80",Demand,"<90")
A27: 10 | B27: 23 | C27: 90 | D27: =COUNTIFS(Demand,">=90",Demand,"<100")
A28: 11 | B28: 59 | C28: 100 | D28: =COUNTIFS(Demand,">=100",Demand,"<110")
A29: 12 | B29: 29 | C29: 110 | D29: =COUNTIFS(Demand,">=110",Demand,"<120")
A30: 13 | B30: 26
A31: 14 | B31: 78
A32: 15 | B32: 68
A33: 16 | B33: 30
A34: 17 | B34: 40
A35: 18 | B35: 37
A36: 19 | B36: 36
A37: 20 | B37: 18
A38: 21 | B38: 76
A39: 22 | B39: 95
A40: 23 | B40: 66
A41: 24 | B41: 38
... A121: 104 | B121: 27

Sheet Fit
A1: Which family
A2: Chapter 7, section 7.3. Demand for the belt is a COUNT, so the first question is which discrete family, and the diagnostic that answers it is the variance to mean ratio.
A4: THE DIAGNOSTIC one number, three verdicts
A5: Each family below either fixes the ratio or bounds it on one side, so the ratio rules families out before any of them is fitted. Equation C.1 of the appendix.
A6: Mean | B6: =AVERAGE(Demand)
A7: Variance | B7: =_xlfn.VAR.S(Demand)
A8: Variance to mean ratio | B8: =B7/B6
B10: Poisson | C10: Binomial | D10: Negative binomial
A11: What the family requires | B11: ratio = 1 | C11: ratio < 1 | D11: ratio > 1
A12: Does the history satisfy it? | B12: =IF(ABS($B$8-1)<0.1,"yes","no") | C12: =IF($B$8<1,"yes","no") | D12: =IF($B$8>1,"yes","no")
A13: Row 12 is section 7.3's Step 2 done by the sheet. The KSL's binomial estimator refuses this data for the same reason row 12 says no: a binomial cannot have a variance above its mean.
A15: THE FIT method of moments, Equation 7.6
A16: The negative binomial is the one family left. Its two parameters come from the two moments above, and nothing else.
A17: p, probability of success | B17: =B6/B7
A18: r, number of successes | B18: =B6^2/(B7-B6)
A19: Check: 1/p is the ratio | B19: =1/B17-B8
A20: Fitted mean, r(1-p)/p | B20: =B18*(1-B17)/B17
A21: Fitted variance, r(1-p)/p^2 | B21: =B18*(1-B17)/B17^2
A22: Rows 20 and 21 must return the mean and variance the fit was made from. Row 19 must read zero. Neither is decoration: they are how you catch the other convention for p.
A24: OVER THE HORIZON fourteen weeks of it
A25: Weekly demands are independent, so the mean and the variance of the total both multiply by the number of weeks. The critical ratio comes from the Newsvendor sheet.
A26: Weeks remaining | B26: 14 | C26: weeks
A27: Mean over the horizon | B27: =B26*B6
A28: Variance over the horizon | B28: =B26*B7
A29: Standard deviation | B29: =SQRT(B28)
A30: Coefficient of variation | B30: =B29/B27
A31: One belt, as a share of the deviation | B31: =1/B29
A32: Critical ratio | B32: =Newsvendor!B10
A33: Row 31 is why section 7.7 may treat the total as continuous and why it may not treat a single week that way. Compare it with 1/SQRT(B7), which is 4% on the weekly data.
A35: WHAT EACH MODEL WOULD HAVE YOU ORDER
A36: Three continuous approximations, and the exact answer from the Horizon sheet. Every quantity is rounded to whole belts before it is priced, because a fraction of a belt cannot be ordered.
B37: Normal | C37: Lognormal | D37: Gamma | E37: Exact
A38: Order quantity | B38: =$B$27+_xlfn.NORM.S.INV($B$32)*$B$29 | C38: =EXP(LN($B$27)-LN($B$28/$B$27^2+1)/2+_xlfn.NORM.S.INV($B$32)*SQRT(LN($B$28/$B$27^2+1))) | D38: =_xlfn.GAMMA.INV($B$32,$B$27^2/$B$28,$B$28/$B$27) | E38: =Horizon!B10
A39: Rounded to whole belts | B39: =ROUND(B38,0) | C39: =ROUND(C38,0) | D39: =ROUND(D38,0) | E39: =ROUND(E38,0)
A40: Expected cost under the exact model | B40: =(Newsvendor!$B$12+Newsvendor!$B$11)*INDEX(HorizonLoss,MATCH(B39,HorizonQ,0))+Newsvendor!$B$11*(B39-Horizon!$B$8) | C40: =(Newsvendor!$B$12+Newsvendor!$B$11)*INDEX(HorizonLoss,MATCH(C39,HorizonQ,0))+Newsvendor!$B$11*(C39-Horizon!$B$8) | D40: =(Newsvendor!$B$12+Newsvendor!$B$11)*INDEX(HorizonLoss,MATCH(D39,HorizonQ,0))+Newsvendor!$B$11*(D39-Horizon!$B$8) | E40: =(Newsvendor!$B$12+Newsvendor!$B$11)*INDEX(HorizonLoss,MATCH(E39,HorizonQ,0))+Newsvendor!$B$11*(E39-Horizon!$B$8)
A41: Penalty against the exact answer | B41: =B40/$E$40-1 | C41: =C40/$E$40-1 | D41: =D40/$E$40-1 | E41: =E40/$E$40-1
A42: Row 41 is the price of choosing the wrong family, in the only currency that settles the question. Notice it is smaller than the rounding.

Sheet Horizon
A1: The exact answer
A2: Chapter 7, section 7.7 and Table 7.5. No new distribution function is needed: the mass function is a recursion and the rest is running sums.
A4: THE AGGREGATED MODEL
A5: p, from the weekly fit | B5: =Fit!B17
A6: r, weekly | B6: =Fit!B18
A7: r over the horizon, 14r | B7: =Fit!B26*B6
A8: Mean, r(1-p)/p | B8: =B7*(1-B5)/B5
A9: Variance, r(1-p)/p^2 | B9: =B7*(1-B5)/B5^2
A10: Order quantity, Q* | B10: =INDEX(HorizonQ,MATCH(TRUE,HorizonReached,0))
A11: Check: mean matches the Fit sheet | B11: =B8-Fit!B27
A12: Check: variance matches the Fit sheet | B12: =B9-Fit!B28
A13: Rows 11 and 12 read zero. They are what proves the aggregation rule was applied to the right parameter. Row 14 is the tail the walk does not reach, which is why column C stops short of one.
A14: Mass beyond the last row of the walk | B14: =1-C718
A15: THE WALK one belt at a time, from zero
A16: g(0) = p^r, then g(x) = g(x-1)(x+r-1)(1-p)/x. The loss function is the recursion of Equation C.6, G1(Q) = G1(Q-1) - (1 - F(Q-1)), started at the mean. Both are arithmetic a reader can check.
A17: Q | B17: g(Q) | C17: F(Q) | D17: G1(Q) | E17: Reached?
A18: 0 | B18: =$B$5^$B$7 | C18: =B18 | D18: =$B$8 | E18: =C18>=Fit!$B$32
A19: 1 | B19: =B18*(A19+$B$7-1)*(1-$B$5)/A19 | C19: =C18+B19 | D19: =D18-(1-C18) | E19: =C19>=Fit!$B$32
A20: 2 | B20: =B19*(A20+$B$7-1)*(1-$B$5)/A20 | C20: =C19+B20 | D20: =D19-(1-C19) | E20: =C20>=Fit!$B$32
A21: 3 | B21: =B20*(A21+$B$7-1)*(1-$B$5)/A21 | C21: =C20+B21 | D21: =D20-(1-C20) | E21: =C21>=Fit!$B$32
A22: 4 | B22: =B21*(A22+$B$7-1)*(1-$B$5)/A22 | C22: =C21+B22 | D22: =D21-(1-C21) | E22: =C22>=Fit!$B$32
A23: 5 | B23: =B22*(A23+$B$7-1)*(1-$B$5)/A23 | C23: =C22+B23 | D23: =D22-(1-C22) | E23: =C23>=Fit!$B$32
A24: 6 | B24: =B23*(A24+$B$7-1)*(1-$B$5)/A24 | C24: =C23+B24 | D24: =D23-(1-C23) | E24: =C24>=Fit!$B$32
A25: 7 | B25: =B24*(A25+$B$7-1)*(1-$B$5)/A25 | C25: =C24+B25 | D25: =D24-(1-C24) | E25: =C25>=Fit!$B$32
A26: 8 | B26: =B25*(A26+$B$7-1)*(1-$B$5)/A26 | C26: =C25+B26 | D26: =D25-(1-C25) | E26: =C26>=Fit!$B$32
A27: 9 | B27: =B26*(A27+$B$7-1)*(1-$B$5)/A27 | C27: =C26+B27 | D27: =D26-(1-C26) | E27: =C27>=Fit!$B$32
A28: 10 | B28: =B27*(A28+$B$7-1)*(1-$B$5)/A28 | C28: =C27+B28 | D28: =D27-(1-C27) | E28: =C28>=Fit!$B$32
A29: 11 | B29: =B28*(A29+$B$7-1)*(1-$B$5)/A29 | C29: =C28+B29 | D29: =D28-(1-C28) | E29: =C29>=Fit!$B$32
A30: 12 | B30: =B29*(A30+$B$7-1)*(1-$B$5)/A30 | C30: =C29+B30 | D30: =D29-(1-C29) | E30: =C30>=Fit!$B$32
... A718: 700 | B718: =B717*(A718+$B$7-1)*(1-$B$5)/A718 | C718: =C717+B718 | D718: =D717-(1-C717) | E718: =C718>=Fit!$B$32

Sheet Newsvendor
A1: The decision
A2: Chapter 7, sections 7.5 to 7.9. The final buy for the belt, in the profit quantities an invoice carries and the cost quantities the model uses.
A4: WHAT AN INVOICE SAYS
A5: Selling price, s | B5: 95 | C5: $/belt
A6: Purchase cost, c | B6: 50 | C6: $/belt
A7: Salvage value, u | B7: 12 | C7: $/belt
A8: Stockout penalty, pi | B8: 0 | C8: $/belt beyond the lost margin
A9: WHAT THE MODEL USES
A10: Critical ratio | B10: =B12/(B12+B11)
A11: Overage cost, co = c - u | B11: =B6-B7
A12: Underage cost, cu = s - c + pi | B12: =B5-B6+B8
A13: Both are strictly positive or the model has nothing to trade. Row 14 says so rather than leaving a reader to notice.
A14: Is the problem well posed? | B14: =IF(OR(B11<=0,B12<=0),"REFUSED: see section 7.9.3","admissible")
A16: DEMAND OVER THE PERIOD
A17: Mean | B17: =Fit!B27
A18: Standard deviation | B18: =Fit!B29
A20: THE ANSWER
A21: z at the critical ratio | B21: =_xlfn.NORM.S.INV(B10)
A22: Order quantity, Q* | B22: =B17+B21*B18
A23: The loss function is arithmetic and not a macro. Phi1(z) = phi(z) - z(1 - Phi(z)), and G1 = sigma times that.
A24: phi(z) | B24: =_xlfn.NORM.S.DIST(B21,FALSE)
A25: 1 - Phi(z) | B25: =1-_xlfn.NORM.S.DIST(B21,TRUE)
A26: Phi1(z) | B26: =B24-B21*B25
A27: Expected shortage, G1(Q*) | B27: =B18*B26
A28: Expected leftover | B28: =B22-B17+B27
A30: WHAT IT COSTS, TWICE
A31: Equation 7.9 has two forms and they must agree. Row 34 is that check wired into the sheet: it reads zero or something is wrong.
A32: Expected cost, co(leftover) + cu(shortage) | B32: =B11*B28+B12*B27
A33: Expected cost, (cu+co)G1 + co(Q-mean) | B33: =(B12+B11)*B27+B11*(B22-B17)
A34: Difference, which must be zero | B34: =B32-B33
A35: Expected profit | B35: =(B5-B6)*B17-B32
A36: Cash committed at Q* | B36: =B6*B22
A38: TYPE A QUANTITY OF YOUR OWN
A39: The block above solves. This one prices whatever you type, so a reader can see how flat the optimum is by trying numbers either side of it. It starts at the mean, rounded to a whole belt.
A40: Quantity | B40: 465 | C40: belts
A41: z at that quantity | B41: =(B40-B17)/B18
A42: Expected shortage | B42: =B18*(_xlfn.NORM.S.DIST(B41,FALSE)-B41*(1-_xlfn.NORM.S.DIST(B41,TRUE)))
A43: Expected cost | B43: =(B12+B11)*B42+B11*(B40-B17)
A44: Penalty against the optimum | B44: =B43/B32-1
A46: STOCK ALREADY ON HAND
...

Sheet Discrete
A1: When demand is counted
A2: Chapter 7, section 7.8. The spare transformer. A staircase distribution function rarely lands on the critical ratio, so the answer is the smallest quantity that reaches it.
A4: THE ITEM
A5: Expected failures over the window | B5: 6 | C5: transformers
A6: Purchase cost | B6: 3800 | C6: $ each
A7: Scrap value | B7: 900 | C7: $ each
A8: Emergency purchase price | B8: 9500 | C8: $ each
A9: Overage cost, co | B9: =B6-B7
A10: Underage cost, cu | B10: =B8-B6
A11: Critical ratio | B11: =B10/(B10+B9)
A12: Order quantity, Q* | B12: =INDEX(Candidate,MATCH(TRUE,Reached,0))
A13: Row 12 reads the table below rather than repeating its logic. Change a price and watch both move.
A15: THE WALK one transformer at a time
A16: The loss function is the recursion of Equation C.6: G1(Q) = G1(Q-1) - (1 - F(Q-1)), starting from G1(0) = the mean. The cost column is not used by the rule. It is there so the two agree.
A17: Q | B17: g(Q) | C17: F(Q) | D17: G1(Q) | E17: Expected cost | F17: Reached?
A18: 0 | B18: =_xlfn.POISSON.DIST(A18,$B$5,FALSE) | C18: =_xlfn.POISSON.DIST(A18,$B$5,TRUE) | D18: =$B$5 | E18: =$B$9*(A18-$B$5+D18)+$B$10*D18 | F18: =C18>=$B$11 | G18: =IF(F18,"<--","")
A19: 1 | B19: =_xlfn.POISSON.DIST(A19,$B$5,FALSE) | C19: =_xlfn.POISSON.DIST(A19,$B$5,TRUE) | D19: =D18-(1-C18) | E19: =$B$9*(A19-$B$5+D19)+$B$10*D19 | F19: =C19>=$B$11 | G19: =IF(AND(F19,NOT(F18)),"<--","")
A20: 2 | B20: =_xlfn.POISSON.DIST(A20,$B$5,FALSE) | C20: =_xlfn.POISSON.DIST(A20,$B$5,TRUE) | D20: =D19-(1-C19) | E20: =$B$9*(A20-$B$5+D20)+$B$10*D20 | F20: =C20>=$B$11 | G20: =IF(AND(F20,NOT(F19)),"<--","")
A21: 3 | B21: =_xlfn.POISSON.DIST(A21,$B$5,FALSE) | C21: =_xlfn.POISSON.DIST(A21,$B$5,TRUE) | D21: =D20-(1-C20) | E21: =$B$9*(A21-$B$5+D21)+$B$10*D21 | F21: =C21>=$B$11 | G21: =IF(AND(F21,NOT(F20)),"<--","")
A22: 4 | B22: =_xlfn.POISSON.DIST(A22,$B$5,FALSE) | C22: =_xlfn.POISSON.DIST(A22,$B$5,TRUE) | D22: =D21-(1-C21) | E22: =$B$9*(A22-$B$5+D22)+$B$10*D22 | F22: =C22>=$B$11 | G22: =IF(AND(F22,NOT(F21)),"<--","")
A23: 5 | B23: =_xlfn.POISSON.DIST(A23,$B$5,FALSE) | C23: =_xlfn.POISSON.DIST(A23,$B$5,TRUE) | D23: =D22-(1-C22) | E23: =$B$9*(A23-$B$5+D23)+$B$10*D23 | F23: =C23>=$B$11 | G23: =IF(AND(F23,NOT(F22)),"<--","")
A24: 6 | B24: =_xlfn.POISSON.DIST(A24,$B$5,FALSE) | C24: =_xlfn.POISSON.DIST(A24,$B$5,TRUE) | D24: =D23-(1-C23) | E24: =$B$9*(A24-$B$5+D24)+$B$10*D24 | F24: =C24>=$B$11 | G24: =IF(AND(F24,NOT(F23)),"<--","")
A25: 7 | B25: =_xlfn.POISSON.DIST(A25,$B$5,FALSE) | C25: =_xlfn.POISSON.DIST(A25,$B$5,TRUE) | D25: =D24-(1-C24) | E25: =$B$9*(A25-$B$5+D25)+$B$10*D25 | F25: =C25>=$B$11 | G25: =IF(AND(F25,NOT(F24)),"<--","")
A26: 8 | B26: =_xlfn.POISSON.DIST(A26,$B$5,FALSE) | C26: =_xlfn.POISSON.DIST(A26,$B$5,TRUE) | D26: =D25-(1-C25) | E26: =$B$9*(A26-$B$5+D26)+$B$10*D26 | F26: =C26>=$B$11 | G26: =IF(AND(F26,NOT(F25)),"<--","")
A27: 9 | B27: =_xlfn.POISSON.DIST(A27,$B$5,FALSE) | C27: =_xlfn.POISSON.DIST(A27,$B$5,TRUE) | D27: =D26-(1-C26) | E27: =$B$9*(A27-$B$5+D27)+$B$10*D27 | F27: =C27>=$B$11 | G27: =IF(AND(F27,NOT(F26)),"<--","")
A28: 10 | B28: =_xlfn.POISSON.DIST(A28,$B$5,FALSE) | C28: =_xlfn.POISSON.DIST(A28,$B$5,TRUE) | D28: =D27-(1-C27) | E28: =$B$9*(A28-$B$5+D28)+$B$10*D28 | F28: =C28>=$B$11 | G28: =IF(AND(F28,NOT(F27)),"<--","")
A29: 11 | B29: =_xlfn.POISSON.DIST(A29,$B$5,FALSE) | C29: =_xlfn.POISSON.DIST(A29,$B$5,TRUE) | D29: =D28-(1-C28) | E29: =$B$9*(A29-$B$5+D29)+$B$10*D29 | F29: =C29>=$B$11 | G29: =IF(AND(F29,NOT(F28)),"<--","")
A30: 12 | B30: =_xlfn.POISSON.DIST(A30,$B$5,FALSE) | C30: =_xlfn.POISSON.DIST(A30,$B$5,TRUE) | D30: =D29-(1-C29) | E30: =$B$9*(A30-$B$5+D30)+$B$10*D30 | F30: =C30>=$B$11 | G30: =IF(AND(F30,NOT(F29)),"<--","")
... A33: 15 | B33: =_xlfn.POISSON.DIST(A33,$B$5,FALSE) | C33: =_xlfn.POISSON.DIST(A33,$B$5,TRUE) | D33: =D32-(1-C32) | E33: =$B$9*(A33-$B$5+D33)+$B$10*D33 | F33: =C33>=$B$11 | G33: =IF(AND(F33,NOT(F32)),"<--","")
