Workbook
Name DepotPipelineMean: 'Depot'!$B$13
Name DepotDemandRate: 'Depot'!$B$12
Name DepotLoss: 'Depot'!$D$24:$D$84
Name DepotSecondMoment: 'Depot'!$E$24:$E$84

Sheet Depot
A1: The depot, and the delay it imposes
A2: @sec-multiechelon-palm and @sec-multiechelon-delay. The depot depends on no storeroom, so it is solved first.
A4: The item and the network
A5: failures per storeroom | B5: 45 | C5: per year
A6: storerooms J | B6: 4 | C6: locations
A7: fraction rebuilt locally | B7: 0.3 | C7: phi_j
A8: local repair time | B8: 30 | C8: days
A9: order and ship time | B9: 10 | C9: days
A10: depot repair time | B10: 60 | C10: days
A11: requests per storeroom | B11: =(1-B7)*B5 | C11: lambda_j0 = (1-phi_j)*lambda_j, @eq-repairable-passup
A12: depot demand rate | B12: =B6*B11 | C12: lambda_0, @eq-repairable-depotrate
A13: depot pipeline mu_0 | B13: =B12*B10/365 | C13: Palm's theorem, @eq-depot-pipeline
A15: Depot policy
A16: depot stock S_0 | B16: 16 | C16: units
A17: Bbar_0 | B17: =INDEX($D$24:$D$84,$B$16+1) | C17: units the depot owes, @eq-repairable-backorders at S_0
A18: Var[B_0] | B18: =INDEX($E$24:$E$84,$B$16+1)-B17^2 | C18: Sherbrooke's recursion, @eq-backorder-secondmoment
A19: Wbar, years | B19: =B17/B12 | C19: Little's Law, @eq-depot-wait
A20: Wbar, days | B20: =B19*365
A22: Poisson at mu_0. G1 and E[B^2] are recursions; each row reads the row above.
A23: x | B23: G(x) | C23: G0(x) | D23: G1(x) | E23: E[B^2(x)]
A24: 0 | B24: =_xlfn.POISSON.DIST(A24,$B$13,TRUE) | C24: =1-B24 | D24: =$B$13 | E24: =$B$13+$B$13^2
A25: 1 | B25: =_xlfn.POISSON.DIST(A25,$B$13,TRUE) | C25: =1-B25 | D25: =D24-C24 | E25: =E24-D25-D24
A26: 2 | B26: =_xlfn.POISSON.DIST(A26,$B$13,TRUE) | C26: =1-B26 | D26: =D25-C25 | E26: =E25-D26-D25
A27: 3 | B27: =_xlfn.POISSON.DIST(A27,$B$13,TRUE) | C27: =1-B27 | D27: =D26-C26 | E27: =E26-D27-D26
A28: 4 | B28: =_xlfn.POISSON.DIST(A28,$B$13,TRUE) | C28: =1-B28 | D28: =D27-C27 | E28: =E27-D28-D27
A29: 5 | B29: =_xlfn.POISSON.DIST(A29,$B$13,TRUE) | C29: =1-B29 | D29: =D28-C28 | E29: =E28-D29-D28
A30: 6 | B30: =_xlfn.POISSON.DIST(A30,$B$13,TRUE) | C30: =1-B30 | D30: =D29-C29 | E30: =E29-D30-D29
A31: 7 | B31: =_xlfn.POISSON.DIST(A31,$B$13,TRUE) | C31: =1-B31 | D31: =D30-C30 | E31: =E30-D31-D30
A32: 8 | B32: =_xlfn.POISSON.DIST(A32,$B$13,TRUE) | C32: =1-B32 | D32: =D31-C31 | E32: =E31-D32-D31
A33: 9 | B33: =_xlfn.POISSON.DIST(A33,$B$13,TRUE) | C33: =1-B33 | D33: =D32-C32 | E33: =E32-D33-D32
A34: 10 | B34: =_xlfn.POISSON.DIST(A34,$B$13,TRUE) | C34: =1-B34 | D34: =D33-C33 | E34: =E33-D34-D33
A35: 11 | B35: =_xlfn.POISSON.DIST(A35,$B$13,TRUE) | C35: =1-B35 | D35: =D34-C34 | E35: =E34-D35-D34
A36: 12 | B36: =_xlfn.POISSON.DIST(A36,$B$13,TRUE) | C36: =1-B36 | D36: =D35-C35 | E36: =E35-D36-D35
... A84: 60 | B84: =_xlfn.POISSON.DIST(A84,$B$13,TRUE) | C84: =1-B84 | D84: =D83-C83 | E84: =E83-D84-D83
A86: Change S_0 above and the four figures move; the block below never does.

Sheet Storeroom
A1: One storeroom, both models
A2: @sec-multiechelon-metric and @sec-multiechelon-varimetric. The means agree; only the second moment differs.
A4: The item and the network
A5: failures per storeroom | B5: 45 | C5: per year
A6: storerooms J | B6: 4 | C6: locations
A7: fraction rebuilt locally | B7: 0.3 | C7: phi_j
A8: local repair time | B8: 30 | C8: days
A9: order and ship time | B9: 10 | C9: days
A10: depot repair time | B10: 60 | C10: days
A11: requests per storeroom | B11: =(1-B7)*B5 | C11: lambda_j0 = (1-phi_j)*lambda_j, @eq-repairable-passup
A12: depot demand rate | B12: =B6*B11 | C12: lambda_0, @eq-repairable-depotrate
A13: depot pipeline mu_0 | B13: =B12*B10/365 | C13: Palm's theorem, @eq-palm-pipeline
A15: Read from the Depot sheet
A16: Bbar_0 | B16: =Depot!B17
A17: Var[B_0] | B17: =Depot!B18
A18: share f_j | B18: =B11/B12 | C18: @eq-varimetric-share, this storeroom's share of depot demand
A20: The storeroom's pipeline
A21: local and in transit | B21: =B5*(B7*B8+(1-B7)*B9)/365 | C21: the part Palm's theorem covers exactly
A22: mu_j | B22: =B21+B18*B16 | C22: @eq-varimetric-mean; METRIC and VARI-METRIC share it
A23: sigma^2_j | B23: =B21+B18*(1-B18)*B16+B18^2*B17 | C23: @eq-varimetric-variance; METRIC drops the last two terms
A24: variance to mean | B24: =B23/B22
A26: Negative binomial fit, @eq-varimetric-fit
A27: p | B27: =B22/B23
A28: beta | B28: =(1-B27)/B27
A29: r | B29: =B22/B28 | C29: not an integer, which is why the block below is a recursion
A31: Storeroom policy
A32: storeroom stock S_j | B32: 4 | C32: units
A33: METRIC Bbar_j | B33: =IF(B32=0,B22,B22*(1-_xlfn.POISSON.DIST(B32-1,B22,TRUE))-B32*(1-_xlfn.POISSON.DIST(B32,B22,TRUE))) | C33: Poisson, closed in one cell; variance forced equal to the mean
A34: VARI-METRIC Bbar_j | B34: =INDEX($D$41:$D$65,B32+1) | C34: read out of the block below, on both moments
A35: VARI over METRIC | B35: =B34/B33
A36: Ibar_j, VARI-METRIC | B36: =B32-B22+B34
A37: check, Ibar-Bbar-(S-mu) | B37: =B36-B34-(B32-B22) | C37: an identity, so this reads zero whatever the model
A39: The negative binomial, built by its own recursion. No distribution function is used.
A40: x | B40: g(x) | C40: G0(x) | D40: G1(x)
A41: 0 | B41: =$B$27^$B$29 | C41: =1-B41 | D41: =$B$22
A42: 1 | B42: =B41*($B$29+A42-1)/A42*(1-$B$27) | C42: =C41-B42 | D42: =D41-C41
A43: 2 | B43: =B42*($B$29+A43-1)/A43*(1-$B$27) | C43: =C42-B43 | D43: =D42-C42
A44: 3 | B44: =B43*($B$29+A44-1)/A44*(1-$B$27) | C44: =C43-B44 | D44: =D43-C43
A45: 4 | B45: =B44*($B$29+A45-1)/A45*(1-$B$27) | C45: =C44-B45 | D45: =D44-C44
A46: 5 | B46: =B45*($B$29+A46-1)/A46*(1-$B$27) | C46: =C45-B46 | D46: =D45-C45
...

Sheet Allocate
A1: Allocating stock across the two levels
A2: @sec-multiechelon-allocation, run with METRIC. @sec-multiechelon-build-allocate says why not VARI-METRIC.
A4: unit cost | B4: 3800 | C4: dollars
A5: Storerooms are alike, so a plan is a depot level S_0 and a common level s_j.
A6: Each column is a way to split the same total. The sheet takes the best.
A7: total | B7: s_j = 0 | C7: s_j = 1 | D7: s_j = 2 | E7: s_j = 3 | F7: s_j = 4 | G7: s_j = 5 | H7: s_j = 6 | I7: best EBO | J7: best s_j | K7: best S_0 | L7: reduction | M7: convex? | N7: delta per $1,000
A8: 0 | B8: =Depot!$B$6*((Depot!$B$5*(Depot!$B$7*Depot!$B$8+(1-Depot!$B$7)*Depot!$B$9)/365+INDEX(DepotLoss,1)/Depot!$B$6)) | I8: =MIN(B8:H8) | J8: =MATCH(I8,B8:H8,0)-1 | K8: =A8-Depot!$B$6*J8
A9: 1 | B9: =Depot!$B$6*((Depot!$B$5*(Depot!$B$7*Depot!$B$8+(1-Depot!$B$7)*Depot!$B$9)/365+INDEX(DepotLoss,2)/Depot!$B$6)) | I9: =MIN(B9:H9) | J9: =MATCH(I9,B9:H9,0)-1 | K9: =A9-Depot!$B$6*J9 | L9: =I8-I9 | M9: =IF(OR(L9="",L10=""),"",IF(L10>L9,"drop","")) | N9: =L9/($B$4/1000)
A10: 2 | B10: =Depot!$B$6*((Depot!$B$5*(Depot!$B$7*Depot!$B$8+(1-Depot!$B$7)*Depot!$B$9)/365+INDEX(DepotLoss,3)/Depot!$B$6)) | I10: =MIN(B10:H10) | J10: =MATCH(I10,B10:H10,0)-1 | K10: =A10-Depot!$B$6*J10 | L10: =I9-I10 | M10: =IF(OR(L10="",L11=""),"",IF(L11>L10,"drop","")) | N10: =L10/($B$4/1000)
A11: 3 | B11: =Depot!$B$6*((Depot!$B$5*(Depot!$B$7*Depot!$B$8+(1-Depot!$B$7)*Depot!$B$9)/365+INDEX(DepotLoss,4)/Depot!$B$6)) | I11: =MIN(B11:H11) | J11: =MATCH(I11,B11:H11,0)-1 | K11: =A11-Depot!$B$6*J11 | L11: =I10-I11 | M11: =IF(OR(L11="",L12=""),"",IF(L12>L11,"drop","")) | N11: =L11/($B$4/1000)
A12: 4 | B12: =Depot!$B$6*((Depot!$B$5*(Depot!$B$7*Depot!$B$8+(1-Depot!$B$7)*Depot!$B$9)/365+INDEX(DepotLoss,5)/Depot!$B$6)) | C12: =Depot!$B$6*((Depot!$B$5*(Depot!$B$7*Depot!$B$8+(1-Depot!$B$7)*Depot!$B$9)/365+INDEX(DepotLoss,1)/Depot!$B$6)*(1-_xlfn.POISSON.DIST(0,(Depot!$B$5*(Depot!$B$7*Depot!$B$8+(1-Depot!$B$7)*Depot!$B$9)/365+INDEX(DepotLoss,1)/Depot!$B$6),TRUE))-1*(1-_xlfn.POISSON.DIST(1,(Depot!$B$5*(Depot!$B$7*Depot!$B$8+(1-Depot!$B$7)*Depot!$B$9)/365+INDEX(DepotLoss,1)/Depot!$B$6),TRUE))) | I12: =MIN(B12:H12) | J12: =MATCH(I12,B12:H12,0)-1 | K12: =A12-Depot!$B$6*J12 | L12: =I11-I12 | M12: =IF(OR(L12="",L13=""),"",IF(L13>L12,"drop","")) | N12: =L12/($B$4/1000)
A13: 5 | B13: =Depot!$B$6*((Depot!$B$5*(Depot!$B$7*Depot!$B$8+(1-Depot!$B$7)*Depot!$B$9)/365+INDEX(DepotLoss,6)/Depot!$B$6)) | C13: =Depot!$B$6*((Depot!$B$5*(Depot!$B$7*Depot!$B$8+(1-Depot!$B$7)*Depot!$B$9)/365+INDEX(DepotLoss,2)/Depot!$B$6)*(1-_xlfn.POISSON.DIST(0,(Depot!$B$5*(Depot!$B$7*Depot!$B$8+(1-Depot!$B$7)*Depot!$B$9)/365+INDEX(DepotLoss,2)/Depot!$B$6),TRUE))-1*(1-_xlfn.POISSON.DIST(1,(Depot!$B$5*(Depot!$B$7*Depot!$B$8+(1-Depot!$B$7)*Depot!$B$9)/365+INDEX(DepotLoss,2)/Depot!$B$6),TRUE))) | I13: =MIN(B13:H13) | J13: =MATCH(I13,B13:H13,0)-1 | K13: =A13-Depot!$B$6*J13 | L13: =I12-I13 | M13: =IF(OR(L13="",L14=""),"",IF(L14>L13,"drop","")) | N13: =L13/($B$4/1000)
A14: 6 | B14: =Depot!$B$6*((Depot!$B$5*(Depot!$B$7*Depot!$B$8+(1-Depot!$B$7)*Depot!$B$9)/365+INDEX(DepotLoss,7)/Depot!$B$6)) | C14: =Depot!$B$6*((Depot!$B$5*(Depot!$B$7*Depot!$B$8+(1-Depot!$B$7)*Depot!$B$9)/365+INDEX(DepotLoss,3)/Depot!$B$6)*(1-_xlfn.POISSON.DIST(0,(Depot!$B$5*(Depot!$B$7*Depot!$B$8+(1-Depot!$B$7)*Depot!$B$9)/365+INDEX(DepotLoss,3)/Depot!$B$6),TRUE))-1*(1-_xlfn.POISSON.DIST(1,(Depot!$B$5*(Depot!$B$7*Depot!$B$8+(1-Depot!$B$7)*Depot!$B$9)/365+INDEX(DepotLoss,3)/Depot!$B$6),TRUE))) | I14: =MIN(B14:H14) | J14: =MATCH(I14,B14:H14,0)-1 | K14: =A14-Depot!$B$6*J14 | L14: =I13-I14 | M14: =IF(OR(L14="",L15=""),"",IF(L15>L14,"drop","")) | N14: =L14/($B$4/1000)
A15: 7 | B15: =Depot!$B$6*((Depot!$B$5*(Depot!$B$7*Depot!$B$8+(1-Depot!$B$7)*Depot!$B$9)/365+INDEX(DepotLoss,8)/Depot!$B$6)) | C15: =Depot!$B$6*((Depot!$B$5*(Depot!$B$7*Depot!$B$8+(1-Depot!$B$7)*Depot!$B$9)/365+INDEX(DepotLoss,4)/Depot!$B$6)*(1-_xlfn.POISSON.DIST(0,(Depot!$B$5*(Depot!$B$7*Depot!$B$8+(1-Depot!$B$7)*Depot!$B$9)/365+INDEX(DepotLoss,4)/Depot!$B$6),TRUE))-1*(1-_xlfn.POISSON.DIST(1,(Depot!$B$5*(Depot!$B$7*Depot!$B$8+(1-Depot!$B$7)*Depot!$B$9)/365+INDEX(DepotLoss,4)/Depot!$B$6),TRUE))) | I15: =MIN(B15:H15) | J15: =MATCH(I15,B15:H15,0)-1 | K15: =A15-Depot!$B$6*J15 | L15: =I14-I15 | M15: =IF(OR(L15="",L16=""),"",IF(L16>L15,"drop","")) | N15: =L15/($B$4/1000)
A16: 8 | B16: =Depot!$B$6*((Depot!$B$5*(Depot!$B$7*Depot!$B$8+(1-Depot!$B$7)*Depot!$B$9)/365+INDEX(DepotLoss,9)/Depot!$B$6)) | C16: =Depot!$B$6*((Depot!$B$5*(Depot!$B$7*Depot!$B$8+(1-Depot!$B$7)*Depot!$B$9)/365+INDEX(DepotLoss,5)/Depot!$B$6)*(1-_xlfn.POISSON.DIST(0,(Depot!$B$5*(Depot!$B$7*Depot!$B$8+(1-Depot!$B$7)*Depot!$B$9)/365+INDEX(DepotLoss,5)/Depot!$B$6),TRUE))-1*(1-_xlfn.POISSON.DIST(1,(Depot!$B$5*(Depot!$B$7*Depot!$B$8+(1-Depot!$B$7)*Depot!$B$9)/365+INDEX(DepotLoss,5)/Depot!$B$6),TRUE))) | D16: =Depot!$B$6*((Depot!$B$5*(Depot!$B$7*Depot!$B$8+(1-Depot!$B$7)*Depot!$B$9)/365+INDEX(DepotLoss,1)/Depot!$B$6)*(1-_xlfn.POISSON.DIST(1,(Depot!$B$5*(Depot!$B$7*Depot!$B$8+(1-Depot!$B$7)*Depot!$B$9)/365+INDEX(DepotLoss,1)/Depot!$B$6),TRUE))-2*(1-_xlfn.POISSON.DIST(2,(Depot!$B$5*(Depot!$B$7*Depot!$B$8+(1-Depot!$B$7)*Depot!$B$9)/365+INDEX(DepotLoss,1)/Depot!$B$6),TRUE))) | I16: =MIN(B16:H16) | J16: =MATCH(I16,B16:H16,0)-1 | K16: =A16-Depot!$B$6*J16 | L16: =I15-I16 | M16: =IF(OR(L16="",L17=""),"",IF(L17>L16,"drop","")) | N16: =L16/($B$4/1000)
A17: 9 | B17: =Depot!$B$6*((Depot!$B$5*(Depot!$B$7*Depot!$B$8+(1-Depot!$B$7)*Depot!$B$9)/365+INDEX(DepotLoss,10)/Depot!$B$6)) | C17: =Depot!$B$6*((Depot!$B$5*(Depot!$B$7*Depot!$B$8+(1-Depot!$B$7)*Depot!$B$9)/365+INDEX(DepotLoss,6)/Depot!$B$6)*(1-_xlfn.POISSON.DIST(0,(Depot!$B$5*(Depot!$B$7*Depot!$B$8+(1-Depot!$B$7)*Depot!$B$9)/365+INDEX(DepotLoss,6)/Depot!$B$6),TRUE))-1*(1-_xlfn.POISSON.DIST(1,(Depot!$B$5*(Depot!$B$7*Depot!$B$8+(1-Depot!$B$7)*Depot!$B$9)/365+INDEX(DepotLoss,6)/Depot!$B$6),TRUE))) | D17: =Depot!$B$6*((Depot!$B$5*(Depot!$B$7*Depot!$B$8+(1-Depot!$B$7)*Depot!$B$9)/365+INDEX(DepotLoss,2)/Depot!$B$6)*(1-_xlfn.POISSON.DIST(1,(Depot!$B$5*(Depot!$B$7*Depot!$B$8+(1-Depot!$B$7)*Depot!$B$9)/365+INDEX(DepotLoss,2)/Depot!$B$6),TRUE))-2*(1-_xlfn.POISSON.DIST(2,(Depot!$B$5*(Depot!$B$7*Depot!$B$8+(1-Depot!$B$7)*Depot!$B$9)/365+INDEX(DepotLoss,2)/Depot!$B$6),TRUE))) | I17: =MIN(B17:H17) | J17: =MATCH(I17,B17:H17,0)-1 | K17: =A17-Depot!$B$6*J17 | L17: =I16-I17 | M17: =IF(OR(L17="",L18=""),"",IF(L18>L17,"drop","")) | N17: =L17/($B$4/1000)
A18: 10 | B18: =Depot!$B$6*((Depot!$B$5*(Depot!$B$7*Depot!$B$8+(1-Depot!$B$7)*Depot!$B$9)/365+INDEX(DepotLoss,11)/Depot!$B$6)) | C18: =Depot!$B$6*((Depot!$B$5*(Depot!$B$7*Depot!$B$8+(1-Depot!$B$7)*Depot!$B$9)/365+INDEX(DepotLoss,7)/Depot!$B$6)*(1-_xlfn.POISSON.DIST(0,(Depot!$B$5*(Depot!$B$7*Depot!$B$8+(1-Depot!$B$7)*Depot!$B$9)/365+INDEX(DepotLoss,7)/Depot!$B$6),TRUE))-1*(1-_xlfn.POISSON.DIST(1,(Depot!$B$5*(Depot!$B$7*Depot!$B$8+(1-Depot!$B$7)*Depot!$B$9)/365+INDEX(DepotLoss,7)/Depot!$B$6),TRUE))) | D18: =Depot!$B$6*((Depot!$B$5*(Depot!$B$7*Depot!$B$8+(1-Depot!$B$7)*Depot!$B$9)/365+INDEX(DepotLoss,3)/Depot!$B$6)*(1-_xlfn.POISSON.DIST(1,(Depot!$B$5*(Depot!$B$7*Depot!$B$8+(1-Depot!$B$7)*Depot!$B$9)/365+INDEX(DepotLoss,3)/Depot!$B$6),TRUE))-2*(1-_xlfn.POISSON.DIST(2,(Depot!$B$5*(Depot!$B$7*Depot!$B$8+(1-Depot!$B$7)*Depot!$B$9)/365+INDEX(DepotLoss,3)/Depot!$B$6),TRUE))) | I18: =MIN(B18:H18) | J18: =MATCH(I18,B18:H18,0)-1 | K18: =A18-Depot!$B$6*J18 | L18: =I17-I18 | M18: =IF(OR(L18="",L19=""),"",IF(L19>L18,"drop","")) | N18: =L18/($B$4/1000)
A19: 11 | B19: =Depot!$B$6*((Depot!$B$5*(Depot!$B$7*Depot!$B$8+(1-Depot!$B$7)*Depot!$B$9)/365+INDEX(DepotLoss,12)/Depot!$B$6)) | C19: =Depot!$B$6*((Depot!$B$5*(Depot!$B$7*Depot!$B$8+(1-Depot!$B$7)*Depot!$B$9)/365+INDEX(DepotLoss,8)/Depot!$B$6)*(1-_xlfn.POISSON.DIST(0,(Depot!$B$5*(Depot!$B$7*Depot!$B$8+(1-Depot!$B$7)*Depot!$B$9)/365+INDEX(DepotLoss,8)/Depot!$B$6),TRUE))-1*(1-_xlfn.POISSON.DIST(1,(Depot!$B$5*(Depot!$B$7*Depot!$B$8+(1-Depot!$B$7)*Depot!$B$9)/365+INDEX(DepotLoss,8)/Depot!$B$6),TRUE))) | D19: =Depot!$B$6*((Depot!$B$5*(Depot!$B$7*Depot!$B$8+(1-Depot!$B$7)*Depot!$B$9)/365+INDEX(DepotLoss,4)/Depot!$B$6)*(1-_xlfn.POISSON.DIST(1,(Depot!$B$5*(Depot!$B$7*Depot!$B$8+(1-Depot!$B$7)*Depot!$B$9)/365+INDEX(DepotLoss,4)/Depot!$B$6),TRUE))-2*(1-_xlfn.POISSON.DIST(2,(Depot!$B$5*(Depot!$B$7*Depot!$B$8+(1-Depot!$B$7)*Depot!$B$9)/365+INDEX(DepotLoss,4)/Depot!$B$6),TRUE))) | I19: =MIN(B19:H19) | J19: =MATCH(I19,B19:H19,0)-1 | K19: =A19-Depot!$B$6*J19 | L19: =I18-I19 | M19: =IF(OR(L19="",L20=""),"",IF(L20>L19,"drop","")) | N19: =L19/($B$4/1000)
A20: 12 | B20: =Depot!$B$6*((Depot!$B$5*(Depot!$B$7*Depot!$B$8+(1-Depot!$B$7)*Depot!$B$9)/365+INDEX(DepotLoss,13)/Depot!$B$6)) | C20: =Depot!$B$6*((Depot!$B$5*(Depot!$B$7*Depot!$B$8+(1-Depot!$B$7)*Depot!$B$9)/365+INDEX(DepotLoss,9)/Depot!$B$6)*(1-_xlfn.POISSON.DIST(0,(Depot!$B$5*(Depot!$B$7*Depot!$B$8+(1-Depot!$B$7)*Depot!$B$9)/365+INDEX(DepotLoss,9)/Depot!$B$6),TRUE))-1*(1-_xlfn.POISSON.DIST(1,(Depot!$B$5*(Depot!$B$7*Depot!$B$8+(1-Depot!$B$7)*Depot!$B$9)/365+INDEX(DepotLoss,9)/Depot!$B$6),TRUE))) | D20: =Depot!$B$6*((Depot!$B$5*(Depot!$B$7*Depot!$B$8+(1-Depot!$B$7)*Depot!$B$9)/365+INDEX(DepotLoss,5)/Depot!$B$6)*(1-_xlfn.POISSON.DIST(1,(Depot!$B$5*(Depot!$B$7*Depot!$B$8+(1-Depot!$B$7)*Depot!$B$9)/365+INDEX(DepotLoss,5)/Depot!$B$6),TRUE))-2*(1-_xlfn.POISSON.DIST(2,(Depot!$B$5*(Depot!$B$7*Depot!$B$8+(1-Depot!$B$7)*Depot!$B$9)/365+INDEX(DepotLoss,5)/Depot!$B$6),TRUE))) | E20: =Depot!$B$6*((Depot!$B$5*(Depot!$B$7*Depot!$B$8+(1-Depot!$B$7)*Depot!$B$9)/365+INDEX(DepotLoss,1)/Depot!$B$6)*(1-_xlfn.POISSON.DIST(2,(Depot!$B$5*(Depot!$B$7*Depot!$B$8+(1-Depot!$B$7)*Depot!$B$9)/365+INDEX(DepotLoss,1)/Depot!$B$6),TRUE))-3*(1-_xlfn.POISSON.DIST(3,(Depot!$B$5*(Depot!$B$7*Depot!$B$8+(1-Depot!$B$7)*Depot!$B$9)/365+INDEX(DepotLoss,1)/Depot!$B$6),TRUE))) | I20: =MIN(B20:H20) | J20: =MATCH(I20,B20:H20,0)-1 | K20: =A20-Depot!$B$6*J20 | L20: =I19-I20 | M20: =IF(OR(L20="",L21=""),"",IF(L21>L20,"drop","")) | N20: =L20/($B$4/1000)
A21: 13 | B21: =Depot!$B$6*((Depot!$B$5*(Depot!$B$7*Depot!$B$8+(1-Depot!$B$7)*Depot!$B$9)/365+INDEX(DepotLoss,14)/Depot!$B$6)) | C21: =Depot!$B$6*((Depot!$B$5*(Depot!$B$7*Depot!$B$8+(1-Depot!$B$7)*Depot!$B$9)/365+INDEX(DepotLoss,10)/Depot!$B$6)*(1-_xlfn.POISSON.DIST(0,(Depot!$B$5*(Depot!$B$7*Depot!$B$8+(1-Depot!$B$7)*Depot!$B$9)/365+INDEX(DepotLoss,10)/Depot!$B$6),TRUE))-1*(1-_xlfn.POISSON.DIST(1,(Depot!$B$5*(Depot!$B$7*Depot!$B$8+(1-Depot!$B$7)*Depot!$B$9)/365+INDEX(DepotLoss,10)/Depot!$B$6),TRUE))) | D21: =Depot!$B$6*((Depot!$B$5*(Depot!$B$7*Depot!$B$8+(1-Depot!$B$7)*Depot!$B$9)/365+INDEX(DepotLoss,6)/Depot!$B$6)*(1-_xlfn.POISSON.DIST(1,(Depot!$B$5*(Depot!$B$7*Depot!$B$8+(1-Depot!$B$7)*Depot!$B$9)/365+INDEX(DepotLoss,6)/Depot!$B$6),TRUE))-2*(1-_xlfn.POISSON.DIST(2,(Depot!$B$5*(Depot!$B$7*Depot!$B$8+(1-Depot!$B$7)*Depot!$B$9)/365+INDEX(DepotLoss,6)/Depot!$B$6),TRUE))) | E21: =Depot!$B$6*((Depot!$B$5*(Depot!$B$7*Depot!$B$8+(1-Depot!$B$7)*Depot!$B$9)/365+INDEX(DepotLoss,2)/Depot!$B$6)*(1-_xlfn.POISSON.DIST(2,(Depot!$B$5*(Depot!$B$7*Depot!$B$8+(1-Depot!$B$7)*Depot!$B$9)/365+INDEX(DepotLoss,2)/Depot!$B$6),TRUE))-3*(1-_xlfn.POISSON.DIST(3,(Depot!$B$5*(Depot!$B$7*Depot!$B$8+(1-Depot!$B$7)*Depot!$B$9)/365+INDEX(DepotLoss,2)/Depot!$B$6),TRUE))) | I21: =MIN(B21:H21) | J21: =MATCH(I21,B21:H21,0)-1 | K21: =A21-Depot!$B$6*J21 | L21: =I20-I21 | M21: =IF(OR(L21="",L22=""),"",IF(L22>L21,"drop","")) | N21: =L21/($B$4/1000)
A22: 14 | B22: =Depot!$B$6*((Depot!$B$5*(Depot!$B$7*Depot!$B$8+(1-Depot!$B$7)*Depot!$B$9)/365+INDEX(DepotLoss,15)/Depot!$B$6)) | C22: =Depot!$B$6*((Depot!$B$5*(Depot!$B$7*Depot!$B$8+(1-Depot!$B$7)*Depot!$B$9)/365+INDEX(DepotLoss,11)/Depot!$B$6)*(1-_xlfn.POISSON.DIST(0,(Depot!$B$5*(Depot!$B$7*Depot!$B$8+(1-Depot!$B$7)*Depot!$B$9)/365+INDEX(DepotLoss,11)/Depot!$B$6),TRUE))-1*(1-_xlfn.POISSON.DIST(1,(Depot!$B$5*(Depot!$B$7*Depot!$B$8+(1-Depot!$B$7)*Depot!$B$9)/365+INDEX(DepotLoss,11)/Depot!$B$6),TRUE))) | D22: =Depot!$B$6*((Depot!$B$5*(Depot!$B$7*Depot!$B$8+(1-Depot!$B$7)*Depot!$B$9)/365+INDEX(DepotLoss,7)/Depot!$B$6)*(1-_xlfn.POISSON.DIST(1,(Depot!$B$5*(Depot!$B$7*Depot!$B$8+(1-Depot!$B$7)*Depot!$B$9)/365+INDEX(DepotLoss,7)/Depot!$B$6),TRUE))-2*(1-_xlfn.POISSON.DIST(2,(Depot!$B$5*(Depot!$B$7*Depot!$B$8+(1-Depot!$B$7)*Depot!$B$9)/365+INDEX(DepotLoss,7)/Depot!$B$6),TRUE))) | E22: =Depot!$B$6*((Depot!$B$5*(Depot!$B$7*Depot!$B$8+(1-Depot!$B$7)*Depot!$B$9)/365+INDEX(DepotLoss,3)/Depot!$B$6)*(1-_xlfn.POISSON.DIST(2,(Depot!$B$5*(Depot!$B$7*Depot!$B$8+(1-Depot!$B$7)*Depot!$B$9)/365+INDEX(DepotLoss,3)/Depot!$B$6),TRUE))-3*(1-_xlfn.POISSON.DIST(3,(Depot!$B$5*(Depot!$B$7*Depot!$B$8+(1-Depot!$B$7)*Depot!$B$9)/365+INDEX(DepotLoss,3)/Depot!$B$6),TRUE))) | I22: =MIN(B22:H22) | J22: =MATCH(I22,B22:H22,0)-1 | K22: =A22-Depot!$B$6*J22 | L22: =I21-I22 | M22: =IF(OR(L22="",L23=""),"",IF(L23>L22,"drop","")) | N22: =L22/($B$4/1000)
A23: 15 | B23: =Depot!$B$6*((Depot!$B$5*(Depot!$B$7*Depot!$B$8+(1-Depot!$B$7)*Depot!$B$9)/365+INDEX(DepotLoss,16)/Depot!$B$6)) | C23: =Depot!$B$6*((Depot!$B$5*(Depot!$B$7*Depot!$B$8+(1-Depot!$B$7)*Depot!$B$9)/365+INDEX(DepotLoss,12)/Depot!$B$6)*(1-_xlfn.POISSON.DIST(0,(Depot!$B$5*(Depot!$B$7*Depot!$B$8+(1-Depot!$B$7)*Depot!$B$9)/365+INDEX(DepotLoss,12)/Depot!$B$6),TRUE))-1*(1-_xlfn.POISSON.DIST(1,(Depot!$B$5*(Depot!$B$7*Depot!$B$8+(1-Depot!$B$7)*Depot!$B$9)/365+INDEX(DepotLoss,12)/Depot!$B$6),TRUE))) | D23: =Depot!$B$6*((Depot!$B$5*(Depot!$B$7*Depot!$B$8+(1-Depot!$B$7)*Depot!$B$9)/365+INDEX(DepotLoss,8)/Depot!$B$6)*(1-_xlfn.POISSON.DIST(1,(Depot!$B$5*(Depot!$B$7*Depot!$B$8+(1-Depot!$B$7)*Depot!$B$9)/365+INDEX(DepotLoss,8)/Depot!$B$6),TRUE))-2*(1-_xlfn.POISSON.DIST(2,(Depot!$B$5*(Depot!$B$7*Depot!$B$8+(1-Depot!$B$7)*Depot!$B$9)/365+INDEX(DepotLoss,8)/Depot!$B$6),TRUE))) | E23: =Depot!$B$6*((Depot!$B$5*(Depot!$B$7*Depot!$B$8+(1-Depot!$B$7)*Depot!$B$9)/365+INDEX(DepotLoss,4)/Depot!$B$6)*(1-_xlfn.POISSON.DIST(2,(Depot!$B$5*(Depot!$B$7*Depot!$B$8+(1-Depot!$B$7)*Depot!$B$9)/365+INDEX(DepotLoss,4)/Depot!$B$6),TRUE))-3*(1-_xlfn.POISSON.DIST(3,(Depot!$B$5*(Depot!$B$7*Depot!$B$8+(1-Depot!$B$7)*Depot!$B$9)/365+INDEX(DepotLoss,4)/Depot!$B$6),TRUE))) | I23: =MIN(B23:H23) | J23: =MATCH(I23,B23:H23,0)-1 | K23: =A23-Depot!$B$6*J23 | L23: =I22-I23 | M23: =IF(OR(L23="",L24=""),"",IF(L24>L23,"drop","")) | N23: =L23/($B$4/1000)
A24: 16 | B24: =Depot!$B$6*((Depot!$B$5*(Depot!$B$7*Depot!$B$8+(1-Depot!$B$7)*Depot!$B$9)/365+INDEX(DepotLoss,17)/Depot!$B$6)) | C24: =Depot!$B$6*((Depot!$B$5*(Depot!$B$7*Depot!$B$8+(1-Depot!$B$7)*Depot!$B$9)/365+INDEX(DepotLoss,13)/Depot!$B$6)*(1-_xlfn.POISSON.DIST(0,(Depot!$B$5*(Depot!$B$7*Depot!$B$8+(1-Depot!$B$7)*Depot!$B$9)/365+INDEX(DepotLoss,13)/Depot!$B$6),TRUE))-1*(1-_xlfn.POISSON.DIST(1,(Depot!$B$5*(Depot!$B$7*Depot!$B$8+(1-Depot!$B$7)*Depot!$B$9)/365+INDEX(DepotLoss,13)/Depot!$B$6),TRUE))) | D24: =Depot!$B$6*((Depot!$B$5*(Depot!$B$7*Depot!$B$8+(1-Depot!$B$7)*Depot!$B$9)/365+INDEX(DepotLoss,9)/Depot!$B$6)*(1-_xlfn.POISSON.DIST(1,(Depot!$B$5*(Depot!$B$7*Depot!$B$8+(1-Depot!$B$7)*Depot!$B$9)/365+INDEX(DepotLoss,9)/Depot!$B$6),TRUE))-2*(1-_xlfn.POISSON.DIST(2,(Depot!$B$5*(Depot!$B$7*Depot!$B$8+(1-Depot!$B$7)*Depot!$B$9)/365+INDEX(DepotLoss,9)/Depot!$B$6),TRUE))) | E24: =Depot!$B$6*((Depot!$B$5*(Depot!$B$7*Depot!$B$8+(1-Depot!$B$7)*Depot!$B$9)/365+INDEX(DepotLoss,5)/Depot!$B$6)*(1-_xlfn.POISSON.DIST(2,(Depot!$B$5*(Depot!$B$7*Depot!$B$8+(1-Depot!$B$7)*Depot!$B$9)/365+INDEX(DepotLoss,5)/Depot!$B$6),TRUE))-3*(1-_xlfn.POISSON.DIST(3,(Depot!$B$5*(Depot!$B$7*Depot!$B$8+(1-Depot!$B$7)*Depot!$B$9)/365+INDEX(DepotLoss,5)/Depot!$B$6),TRUE))) | F24: =Depot!$B$6*((Depot!$B$5*(Depot!$B$7*Depot!$B$8+(1-Depot!$B$7)*Depot!$B$9)/365+INDEX(DepotLoss,1)/Depot!$B$6)*(1-_xlfn.POISSON.DIST(3,(Depot!$B$5*(Depot!$B$7*Depot!$B$8+(1-Depot!$B$7)*Depot!$B$9)/365+INDEX(DepotLoss,1)/Depot!$B$6),TRUE))-4*(1-_xlfn.POISSON.DIST(4,(Depot!$B$5*(Depot!$B$7*Depot!$B$8+(1-Depot!$B$7)*Depot!$B$9)/365+INDEX(DepotLoss,1)/Depot!$B$6),TRUE))) | I24: =MIN(B24:H24) | J24: =MATCH(I24,B24:H24,0)-1 | K24: =A24-Depot!$B$6*J24 | L24: =I23-I24 | M24: =IF(OR(L24="",L25=""),"",IF(L25>L24,"drop","")) | N24: =L24/($B$4/1000)
A25: 17 | B25: =Depot!$B$6*((Depot!$B$5*(Depot!$B$7*Depot!$B$8+(1-Depot!$B$7)*Depot!$B$9)/365+INDEX(DepotLoss,18)/Depot!$B$6)) | C25: =Depot!$B$6*((Depot!$B$5*(Depot!$B$7*Depot!$B$8+(1-Depot!$B$7)*Depot!$B$9)/365+INDEX(DepotLoss,14)/Depot!$B$6)*(1-_xlfn.POISSON.DIST(0,(Depot!$B$5*(Depot!$B$7*Depot!$B$8+(1-Depot!$B$7)*Depot!$B$9)/365+INDEX(DepotLoss,14)/Depot!$B$6),TRUE))-1*(1-_xlfn.POISSON.DIST(1,(Depot!$B$5*(Depot!$B$7*Depot!$B$8+(1-Depot!$B$7)*Depot!$B$9)/365+INDEX(DepotLoss,14)/Depot!$B$6),TRUE))) | D25: =Depot!$B$6*((Depot!$B$5*(Depot!$B$7*Depot!$B$8+(1-Depot!$B$7)*Depot!$B$9)/365+INDEX(DepotLoss,10)/Depot!$B$6)*(1-_xlfn.POISSON.DIST(1,(Depot!$B$5*(Depot!$B$7*Depot!$B$8+(1-Depot!$B$7)*Depot!$B$9)/365+INDEX(DepotLoss,10)/Depot!$B$6),TRUE))-2*(1-_xlfn.POISSON.DIST(2,(Depot!$B$5*(Depot!$B$7*Depot!$B$8+(1-Depot!$B$7)*Depot!$B$9)/365+INDEX(DepotLoss,10)/Depot!$B$6),TRUE))) | E25: =Depot!$B$6*((Depot!$B$5*(Depot!$B$7*Depot!$B$8+(1-Depot!$B$7)*Depot!$B$9)/365+INDEX(DepotLoss,6)/Depot!$B$6)*(1-_xlfn.POISSON.DIST(2,(Depot!$B$5*(Depot!$B$7*Depot!$B$8+(1-Depot!$B$7)*Depot!$B$9)/365+INDEX(DepotLoss,6)/Depot!$B$6),TRUE))-3*(1-_xlfn.POISSON.DIST(3,(Depot!$B$5*(Depot!$B$7*Depot!$B$8+(1-Depot!$B$7)*Depot!$B$9)/365+INDEX(DepotLoss,6)/Depot!$B$6),TRUE))) | F25: =Depot!$B$6*((Depot!$B$5*(Depot!$B$7*Depot!$B$8+(1-Depot!$B$7)*Depot!$B$9)/365+INDEX(DepotLoss,2)/Depot!$B$6)*(1-_xlfn.POISSON.DIST(3,(Depot!$B$5*(Depot!$B$7*Depot!$B$8+(1-Depot!$B$7)*Depot!$B$9)/365+INDEX(DepotLoss,2)/Depot!$B$6),TRUE))-4*(1-_xlfn.POISSON.DIST(4,(Depot!$B$5*(Depot!$B$7*Depot!$B$8+(1-Depot!$B$7)*Depot!$B$9)/365+INDEX(DepotLoss,2)/Depot!$B$6),TRUE))) | I25: =MIN(B25:H25) | J25: =MATCH(I25,B25:H25,0)-1 | K25: =A25-Depot!$B$6*J25 | L25: =I24-I25 | M25: =IF(OR(L25="",L26=""),"",IF(L26>L25,"drop","")) | N25: =L25/($B$4/1000)
A26: 18 | B26: =Depot!$B$6*((Depot!$B$5*(Depot!$B$7*Depot!$B$8+(1-Depot!$B$7)*Depot!$B$9)/365+INDEX(DepotLoss,19)/Depot!$B$6)) | C26: =Depot!$B$6*((Depot!$B$5*(Depot!$B$7*Depot!$B$8+(1-Depot!$B$7)*Depot!$B$9)/365+INDEX(DepotLoss,15)/Depot!$B$6)*(1-_xlfn.POISSON.DIST(0,(Depot!$B$5*(Depot!$B$7*Depot!$B$8+(1-Depot!$B$7)*Depot!$B$9)/365+INDEX(DepotLoss,15)/Depot!$B$6),TRUE))-1*(1-_xlfn.POISSON.DIST(1,(Depot!$B$5*(Depot!$B$7*Depot!$B$8+(1-Depot!$B$7)*Depot!$B$9)/365+INDEX(DepotLoss,15)/Depot!$B$6),TRUE))) | D26: =Depot!$B$6*((Depot!$B$5*(Depot!$B$7*Depot!$B$8+(1-Depot!$B$7)*Depot!$B$9)/365+INDEX(DepotLoss,11)/Depot!$B$6)*(1-_xlfn.POISSON.DIST(1,(Depot!$B$5*(Depot!$B$7*Depot!$B$8+(1-Depot!$B$7)*Depot!$B$9)/365+INDEX(DepotLoss,11)/Depot!$B$6),TRUE))-2*(1-_xlfn.POISSON.DIST(2,(Depot!$B$5*(Depot!$B$7*Depot!$B$8+(1-Depot!$B$7)*Depot!$B$9)/365+INDEX(DepotLoss,11)/Depot!$B$6),TRUE))) | E26: =Depot!$B$6*((Depot!$B$5*(Depot!$B$7*Depot!$B$8+(1-Depot!$B$7)*Depot!$B$9)/365+INDEX(DepotLoss,7)/Depot!$B$6)*(1-_xlfn.POISSON.DIST(2,(Depot!$B$5*(Depot!$B$7*Depot!$B$8+(1-Depot!$B$7)*Depot!$B$9)/365+INDEX(DepotLoss,7)/Depot!$B$6),TRUE))-3*(1-_xlfn.POISSON.DIST(3,(Depot!$B$5*(Depot!$B$7*Depot!$B$8+(1-Depot!$B$7)*Depot!$B$9)/365+INDEX(DepotLoss,7)/Depot!$B$6),TRUE))) | F26: =Depot!$B$6*((Depot!$B$5*(Depot!$B$7*Depot!$B$8+(1-Depot!$B$7)*Depot!$B$9)/365+INDEX(DepotLoss,3)/Depot!$B$6)*(1-_xlfn.POISSON.DIST(3,(Depot!$B$5*(Depot!$B$7*Depot!$B$8+(1-Depot!$B$7)*Depot!$B$9)/365+INDEX(DepotLoss,3)/Depot!$B$6),TRUE))-4*(1-_xlfn.POISSON.DIST(4,(Depot!$B$5*(Depot!$B$7*Depot!$B$8+(1-Depot!$B$7)*Depot!$B$9)/365+INDEX(DepotLoss,3)/Depot!$B$6),TRUE))) | I26: =MIN(B26:H26) | J26: =MATCH(I26,B26:H26,0)-1 | K26: =A26-Depot!$B$6*J26 | L26: =I25-I26 | M26: =IF(OR(L26="",L27=""),"",IF(L27>L26,"drop","")) | N26: =L26/($B$4/1000)
A27: 19 | B27: =Depot!$B$6*((Depot!$B$5*(Depot!$B$7*Depot!$B$8+(1-Depot!$B$7)*Depot!$B$9)/365+INDEX(DepotLoss,20)/Depot!$B$6)) | C27: =Depot!$B$6*((Depot!$B$5*(Depot!$B$7*Depot!$B$8+(1-Depot!$B$7)*Depot!$B$9)/365+INDEX(DepotLoss,16)/Depot!$B$6)*(1-_xlfn.POISSON.DIST(0,(Depot!$B$5*(Depot!$B$7*Depot!$B$8+(1-Depot!$B$7)*Depot!$B$9)/365+INDEX(DepotLoss,16)/Depot!$B$6),TRUE))-1*(1-_xlfn.POISSON.DIST(1,(Depot!$B$5*(Depot!$B$7*Depot!$B$8+(1-Depot!$B$7)*Depot!$B$9)/365+INDEX(DepotLoss,16)/Depot!$B$6),TRUE))) | D27: =Depot!$B$6*((Depot!$B$5*(Depot!$B$7*Depot!$B$8+(1-Depot!$B$7)*Depot!$B$9)/365+INDEX(DepotLoss,12)/Depot!$B$6)*(1-_xlfn.POISSON.DIST(1,(Depot!$B$5*(Depot!$B$7*Depot!$B$8+(1-Depot!$B$7)*Depot!$B$9)/365+INDEX(DepotLoss,12)/Depot!$B$6),TRUE))-2*(1-_xlfn.POISSON.DIST(2,(Depot!$B$5*(Depot!$B$7*Depot!$B$8+(1-Depot!$B$7)*Depot!$B$9)/365+INDEX(DepotLoss,12)/Depot!$B$6),TRUE))) | E27: =Depot!$B$6*((Depot!$B$5*(Depot!$B$7*Depot!$B$8+(1-Depot!$B$7)*Depot!$B$9)/365+INDEX(DepotLoss,8)/Depot!$B$6)*(1-_xlfn.POISSON.DIST(2,(Depot!$B$5*(Depot!$B$7*Depot!$B$8+(1-Depot!$B$7)*Depot!$B$9)/365+INDEX(DepotLoss,8)/Depot!$B$6),TRUE))-3*(1-_xlfn.POISSON.DIST(3,(Depot!$B$5*(Depot!$B$7*Depot!$B$8+(1-Depot!$B$7)*Depot!$B$9)/365+INDEX(DepotLoss,8)/Depot!$B$6),TRUE))) | F27: =Depot!$B$6*((Depot!$B$5*(Depot!$B$7*Depot!$B$8+(1-Depot!$B$7)*Depot!$B$9)/365+INDEX(DepotLoss,4)/Depot!$B$6)*(1-_xlfn.POISSON.DIST(3,(Depot!$B$5*(Depot!$B$7*Depot!$B$8+(1-Depot!$B$7)*Depot!$B$9)/365+INDEX(DepotLoss,4)/Depot!$B$6),TRUE))-4*(1-_xlfn.POISSON.DIST(4,(Depot!$B$5*(Depot!$B$7*Depot!$B$8+(1-Depot!$B$7)*Depot!$B$9)/365+INDEX(DepotLoss,4)/Depot!$B$6),TRUE))) | I27: =MIN(B27:H27) | J27: =MATCH(I27,B27:H27,0)-1 | K27: =A27-Depot!$B$6*J27 | L27: =I26-I27 | M27: =IF(OR(L27="",L28=""),"",IF(L28>L27,"drop","")) | N27: =L27/($B$4/1000)
A28: 20 | B28: =Depot!$B$6*((Depot!$B$5*(Depot!$B$7*Depot!$B$8+(1-Depot!$B$7)*Depot!$B$9)/365+INDEX(DepotLoss,21)/Depot!$B$6)) | C28: =Depot!$B$6*((Depot!$B$5*(Depot!$B$7*Depot!$B$8+(1-Depot!$B$7)*Depot!$B$9)/365+INDEX(DepotLoss,17)/Depot!$B$6)*(1-_xlfn.POISSON.DIST(0,(Depot!$B$5*(Depot!$B$7*Depot!$B$8+(1-Depot!$B$7)*Depot!$B$9)/365+INDEX(DepotLoss,17)/Depot!$B$6),TRUE))-1*(1-_xlfn.POISSON.DIST(1,(Depot!$B$5*(Depot!$B$7*Depot!$B$8+(1-Depot!$B$7)*Depot!$B$9)/365+INDEX(DepotLoss,17)/Depot!$B$6),TRUE))) | D28: =Depot!$B$6*((Depot!$B$5*(Depot!$B$7*Depot!$B$8+(1-Depot!$B$7)*Depot!$B$9)/365+INDEX(DepotLoss,13)/Depot!$B$6)*(1-_xlfn.POISSON.DIST(1,(Depot!$B$5*(Depot!$B$7*Depot!$B$8+(1-Depot!$B$7)*Depot!$B$9)/365+INDEX(DepotLoss,13)/Depot!$B$6),TRUE))-2*(1-_xlfn.POISSON.DIST(2,(Depot!$B$5*(Depot!$B$7*Depot!$B$8+(1-Depot!$B$7)*Depot!$B$9)/365+INDEX(DepotLoss,13)/Depot!$B$6),TRUE))) | E28: =Depot!$B$6*((Depot!$B$5*(Depot!$B$7*Depot!$B$8+(1-Depot!$B$7)*Depot!$B$9)/365+INDEX(DepotLoss,9)/Depot!$B$6)*(1-_xlfn.POISSON.DIST(2,(Depot!$B$5*(Depot!$B$7*Depot!$B$8+(1-Depot!$B$7)*Depot!$B$9)/365+INDEX(DepotLoss,9)/Depot!$B$6),TRUE))-3*(1-_xlfn.POISSON.DIST(3,(Depot!$B$5*(Depot!$B$7*Depot!$B$8+(1-Depot!$B$7)*Depot!$B$9)/365+INDEX(DepotLoss,9)/Depot!$B$6),TRUE))) | F28: =Depot!$B$6*((Depot!$B$5*(Depot!$B$7*Depot!$B$8+(1-Depot!$B$7)*Depot!$B$9)/365+INDEX(DepotLoss,5)/Depot!$B$6)*(1-_xlfn.POISSON.DIST(3,(Depot!$B$5*(Depot!$B$7*Depot!$B$8+(1-Depot!$B$7)*Depot!$B$9)/365+INDEX(DepotLoss,5)/Depot!$B$6),TRUE))-4*(1-_xlfn.POISSON.DIST(4,(Depot!$B$5*(Depot!$B$7*Depot!$B$8+(1-Depot!$B$7)*Depot!$B$9)/365+INDEX(DepotLoss,5)/Depot!$B$6),TRUE))) | G28: =Depot!$B$6*((Depot!$B$5*(Depot!$B$7*Depot!$B$8+(1-Depot!$B$7)*Depot!$B$9)/365+INDEX(DepotLoss,1)/Depot!$B$6)*(1-_xlfn.POISSON.DIST(4,(Depot!$B$5*(Depot!$B$7*Depot!$B$8+(1-Depot!$B$7)*Depot!$B$9)/365+INDEX(DepotLoss,1)/Depot!$B$6),TRUE))-5*(1-_xlfn.POISSON.DIST(5,(Depot!$B$5*(Depot!$B$7*Depot!$B$8+(1-Depot!$B$7)*Depot!$B$9)/365+INDEX(DepotLoss,1)/Depot!$B$6),TRUE))) | I28: =MIN(B28:H28) | J28: =MATCH(I28,B28:H28,0)-1 | K28: =A28-Depot!$B$6*J28 | L28: =I27-I28 | M28: =IF(OR(L28="",L29=""),"",IF(L29>L28,"drop","")) | N28: =L28/($B$4/1000)
A29: 21 | B29: =Depot!$B$6*((Depot!$B$5*(Depot!$B$7*Depot!$B$8+(1-Depot!$B$7)*Depot!$B$9)/365+INDEX(DepotLoss,22)/Depot!$B$6)) | C29: =Depot!$B$6*((Depot!$B$5*(Depot!$B$7*Depot!$B$8+(1-Depot!$B$7)*Depot!$B$9)/365+INDEX(DepotLoss,18)/Depot!$B$6)*(1-_xlfn.POISSON.DIST(0,(Depot!$B$5*(Depot!$B$7*Depot!$B$8+(1-Depot!$B$7)*Depot!$B$9)/365+INDEX(DepotLoss,18)/Depot!$B$6),TRUE))-1*(1-_xlfn.POISSON.DIST(1,(Depot!$B$5*(Depot!$B$7*Depot!$B$8+(1-Depot!$B$7)*Depot!$B$9)/365+INDEX(DepotLoss,18)/Depot!$B$6),TRUE))) | D29: =Depot!$B$6*((Depot!$B$5*(Depot!$B$7*Depot!$B$8+(1-Depot!$B$7)*Depot!$B$9)/365+INDEX(DepotLoss,14)/Depot!$B$6)*(1-_xlfn.POISSON.DIST(1,(Depot!$B$5*(Depot!$B$7*Depot!$B$8+(1-Depot!$B$7)*Depot!$B$9)/365+INDEX(DepotLoss,14)/Depot!$B$6),TRUE))-2*(1-_xlfn.POISSON.DIST(2,(Depot!$B$5*(Depot!$B$7*Depot!$B$8+(1-Depot!$B$7)*Depot!$B$9)/365+INDEX(DepotLoss,14)/Depot!$B$6),TRUE))) | E29: =Depot!$B$6*((Depot!$B$5*(Depot!$B$7*Depot!$B$8+(1-Depot!$B$7)*Depot!$B$9)/365+INDEX(DepotLoss,10)/Depot!$B$6)*(1-_xlfn.POISSON.DIST(2,(Depot!$B$5*(Depot!$B$7*Depot!$B$8+(1-Depot!$B$7)*Depot!$B$9)/365+INDEX(DepotLoss,10)/Depot!$B$6),TRUE))-3*(1-_xlfn.POISSON.DIST(3,(Depot!$B$5*(Depot!$B$7*Depot!$B$8+(1-Depot!$B$7)*Depot!$B$9)/365+INDEX(DepotLoss,10)/Depot!$B$6),TRUE))) | F29: =Depot!$B$6*((Depot!$B$5*(Depot!$B$7*Depot!$B$8+(1-Depot!$B$7)*Depot!$B$9)/365+INDEX(DepotLoss,6)/Depot!$B$6)*(1-_xlfn.POISSON.DIST(3,(Depot!$B$5*(Depot!$B$7*Depot!$B$8+(1-Depot!$B$7)*Depot!$B$9)/365+INDEX(DepotLoss,6)/Depot!$B$6),TRUE))-4*(1-_xlfn.POISSON.DIST(4,(Depot!$B$5*(Depot!$B$7*Depot!$B$8+(1-Depot!$B$7)*Depot!$B$9)/365+INDEX(DepotLoss,6)/Depot!$B$6),TRUE))) | G29: =Depot!$B$6*((Depot!$B$5*(Depot!$B$7*Depot!$B$8+(1-Depot!$B$7)*Depot!$B$9)/365+INDEX(DepotLoss,2)/Depot!$B$6)*(1-_xlfn.POISSON.DIST(4,(Depot!$B$5*(Depot!$B$7*Depot!$B$8+(1-Depot!$B$7)*Depot!$B$9)/365+INDEX(DepotLoss,2)/Depot!$B$6),TRUE))-5*(1-_xlfn.POISSON.DIST(5,(Depot!$B$5*(Depot!$B$7*Depot!$B$8+(1-Depot!$B$7)*Depot!$B$9)/365+INDEX(DepotLoss,2)/Depot!$B$6),TRUE))) | I29: =MIN(B29:H29) | J29: =MATCH(I29,B29:H29,0)-1 | K29: =A29-Depot!$B$6*J29 | L29: =I28-I29 | M29: =IF(OR(L29="",L30=""),"",IF(L30>L29,"drop","")) | N29: =L29/($B$4/1000)
A30: 22 | B30: =Depot!$B$6*((Depot!$B$5*(Depot!$B$7*Depot!$B$8+(1-Depot!$B$7)*Depot!$B$9)/365+INDEX(DepotLoss,23)/Depot!$B$6)) | C30: =Depot!$B$6*((Depot!$B$5*(Depot!$B$7*Depot!$B$8+(1-Depot!$B$7)*Depot!$B$9)/365+INDEX(DepotLoss,19)/Depot!$B$6)*(1-_xlfn.POISSON.DIST(0,(Depot!$B$5*(Depot!$B$7*Depot!$B$8+(1-Depot!$B$7)*Depot!$B$9)/365+INDEX(DepotLoss,19)/Depot!$B$6),TRUE))-1*(1-_xlfn.POISSON.DIST(1,(Depot!$B$5*(Depot!$B$7*Depot!$B$8+(1-Depot!$B$7)*Depot!$B$9)/365+INDEX(DepotLoss,19)/Depot!$B$6),TRUE))) | D30: =Depot!$B$6*((Depot!$B$5*(Depot!$B$7*Depot!$B$8+(1-Depot!$B$7)*Depot!$B$9)/365+INDEX(DepotLoss,15)/Depot!$B$6)*(1-_xlfn.POISSON.DIST(1,(Depot!$B$5*(Depot!$B$7*Depot!$B$8+(1-Depot!$B$7)*Depot!$B$9)/365+INDEX(DepotLoss,15)/Depot!$B$6),TRUE))-2*(1-_xlfn.POISSON.DIST(2,(Depot!$B$5*(Depot!$B$7*Depot!$B$8+(1-Depot!$B$7)*Depot!$B$9)/365+INDEX(DepotLoss,15)/Depot!$B$6),TRUE))) | E30: =Depot!$B$6*((Depot!$B$5*(Depot!$B$7*Depot!$B$8+(1-Depot!$B$7)*Depot!$B$9)/365+INDEX(DepotLoss,11)/Depot!$B$6)*(1-_xlfn.POISSON.DIST(2,(Depot!$B$5*(Depot!$B$7*Depot!$B$8+(1-Depot!$B$7)*Depot!$B$9)/365+INDEX(DepotLoss,11)/Depot!$B$6),TRUE))-3*(1-_xlfn.POISSON.DIST(3,(Depot!$B$5*(Depot!$B$7*Depot!$B$8+(1-Depot!$B$7)*Depot!$B$9)/365+INDEX(DepotLoss,11)/Depot!$B$6),TRUE))) | F30: =Depot!$B$6*((Depot!$B$5*(Depot!$B$7*Depot!$B$8+(1-Depot!$B$7)*Depot!$B$9)/365+INDEX(DepotLoss,7)/Depot!$B$6)*(1-_xlfn.POISSON.DIST(3,(Depot!$B$5*(Depot!$B$7*Depot!$B$8+(1-Depot!$B$7)*Depot!$B$9)/365+INDEX(DepotLoss,7)/Depot!$B$6),TRUE))-4*(1-_xlfn.POISSON.DIST(4,(Depot!$B$5*(Depot!$B$7*Depot!$B$8+(1-Depot!$B$7)*Depot!$B$9)/365+INDEX(DepotLoss,7)/Depot!$B$6),TRUE))) | G30: =Depot!$B$6*((Depot!$B$5*(Depot!$B$7*Depot!$B$8+(1-Depot!$B$7)*Depot!$B$9)/365+INDEX(DepotLoss,3)/Depot!$B$6)*(1-_xlfn.POISSON.DIST(4,(Depot!$B$5*(Depot!$B$7*Depot!$B$8+(1-Depot!$B$7)*Depot!$B$9)/365+INDEX(DepotLoss,3)/Depot!$B$6),TRUE))-5*(1-_xlfn.POISSON.DIST(5,(Depot!$B$5*(Depot!$B$7*Depot!$B$8+(1-Depot!$B$7)*Depot!$B$9)/365+INDEX(DepotLoss,3)/Depot!$B$6),TRUE))) | I30: =MIN(B30:H30) | J30: =MATCH(I30,B30:H30,0)-1 | K30: =A30-Depot!$B$6*J30 | L30: =I29-I30 | M30: =IF(OR(L30="",L31=""),"",IF(L31>L30,"drop","")) | N30: =L30/($B$4/1000)
A31: 23 | B31: =Depot!$B$6*((Depot!$B$5*(Depot!$B$7*Depot!$B$8+(1-Depot!$B$7)*Depot!$B$9)/365+INDEX(DepotLoss,24)/Depot!$B$6)) | C31: =Depot!$B$6*((Depot!$B$5*(Depot!$B$7*Depot!$B$8+(1-Depot!$B$7)*Depot!$B$9)/365+INDEX(DepotLoss,20)/Depot!$B$6)*(1-_xlfn.POISSON.DIST(0,(Depot!$B$5*(Depot!$B$7*Depot!$B$8+(1-Depot!$B$7)*Depot!$B$9)/365+INDEX(DepotLoss,20)/Depot!$B$6),TRUE))-1*(1-_xlfn.POISSON.DIST(1,(Depot!$B$5*(Depot!$B$7*Depot!$B$8+(1-Depot!$B$7)*Depot!$B$9)/365+INDEX(DepotLoss,20)/Depot!$B$6),TRUE))) | D31: =Depot!$B$6*((Depot!$B$5*(Depot!$B$7*Depot!$B$8+(1-Depot!$B$7)*Depot!$B$9)/365+INDEX(DepotLoss,16)/Depot!$B$6)*(1-_xlfn.POISSON.DIST(1,(Depot!$B$5*(Depot!$B$7*Depot!$B$8+(1-Depot!$B$7)*Depot!$B$9)/365+INDEX(DepotLoss,16)/Depot!$B$6),TRUE))-2*(1-_xlfn.POISSON.DIST(2,(Depot!$B$5*(Depot!$B$7*Depot!$B$8+(1-Depot!$B$7)*Depot!$B$9)/365+INDEX(DepotLoss,16)/Depot!$B$6),TRUE))) | E31: =Depot!$B$6*((Depot!$B$5*(Depot!$B$7*Depot!$B$8+(1-Depot!$B$7)*Depot!$B$9)/365+INDEX(DepotLoss,12)/Depot!$B$6)*(1-_xlfn.POISSON.DIST(2,(Depot!$B$5*(Depot!$B$7*Depot!$B$8+(1-Depot!$B$7)*Depot!$B$9)/365+INDEX(DepotLoss,12)/Depot!$B$6),TRUE))-3*(1-_xlfn.POISSON.DIST(3,(Depot!$B$5*(Depot!$B$7*Depot!$B$8+(1-Depot!$B$7)*Depot!$B$9)/365+INDEX(DepotLoss,12)/Depot!$B$6),TRUE))) | F31: =Depot!$B$6*((Depot!$B$5*(Depot!$B$7*Depot!$B$8+(1-Depot!$B$7)*Depot!$B$9)/365+INDEX(DepotLoss,8)/Depot!$B$6)*(1-_xlfn.POISSON.DIST(3,(Depot!$B$5*(Depot!$B$7*Depot!$B$8+(1-Depot!$B$7)*Depot!$B$9)/365+INDEX(DepotLoss,8)/Depot!$B$6),TRUE))-4*(1-_xlfn.POISSON.DIST(4,(Depot!$B$5*(Depot!$B$7*Depot!$B$8+(1-Depot!$B$7)*Depot!$B$9)/365+INDEX(DepotLoss,8)/Depot!$B$6),TRUE))) | G31: =Depot!$B$6*((Depot!$B$5*(Depot!$B$7*Depot!$B$8+(1-Depot!$B$7)*Depot!$B$9)/365+INDEX(DepotLoss,4)/Depot!$B$6)*(1-_xlfn.POISSON.DIST(4,(Depot!$B$5*(Depot!$B$7*Depot!$B$8+(1-Depot!$B$7)*Depot!$B$9)/365+INDEX(DepotLoss,4)/Depot!$B$6),TRUE))-5*(1-_xlfn.POISSON.DIST(5,(Depot!$B$5*(Depot!$B$7*Depot!$B$8+(1-Depot!$B$7)*Depot!$B$9)/365+INDEX(DepotLoss,4)/Depot!$B$6),TRUE))) | I31: =MIN(B31:H31) | J31: =MATCH(I31,B31:H31,0)-1 | K31: =A31-Depot!$B$6*J31 | L31: =I30-I31 | M31: =IF(OR(L31="",L32=""),"",IF(L32>L31,"drop","")) | N31: =L31/($B$4/1000)
A32: 24 | B32: =Depot!$B$6*((Depot!$B$5*(Depot!$B$7*Depot!$B$8+(1-Depot!$B$7)*Depot!$B$9)/365+INDEX(DepotLoss,25)/Depot!$B$6)) | C32: =Depot!$B$6*((Depot!$B$5*(Depot!$B$7*Depot!$B$8+(1-Depot!$B$7)*Depot!$B$9)/365+INDEX(DepotLoss,21)/Depot!$B$6)*(1-_xlfn.POISSON.DIST(0,(Depot!$B$5*(Depot!$B$7*Depot!$B$8+(1-Depot!$B$7)*Depot!$B$9)/365+INDEX(DepotLoss,21)/Depot!$B$6),TRUE))-1*(1-_xlfn.POISSON.DIST(1,(Depot!$B$5*(Depot!$B$7*Depot!$B$8+(1-Depot!$B$7)*Depot!$B$9)/365+INDEX(DepotLoss,21)/Depot!$B$6),TRUE))) | D32: =Depot!$B$6*((Depot!$B$5*(Depot!$B$7*Depot!$B$8+(1-Depot!$B$7)*Depot!$B$9)/365+INDEX(DepotLoss,17)/Depot!$B$6)*(1-_xlfn.POISSON.DIST(1,(Depot!$B$5*(Depot!$B$7*Depot!$B$8+(1-Depot!$B$7)*Depot!$B$9)/365+INDEX(DepotLoss,17)/Depot!$B$6),TRUE))-2*(1-_xlfn.POISSON.DIST(2,(Depot!$B$5*(Depot!$B$7*Depot!$B$8+(1-Depot!$B$7)*Depot!$B$9)/365+INDEX(DepotLoss,17)/Depot!$B$6),TRUE))) | E32: =Depot!$B$6*((Depot!$B$5*(Depot!$B$7*Depot!$B$8+(1-Depot!$B$7)*Depot!$B$9)/365+INDEX(DepotLoss,13)/Depot!$B$6)*(1-_xlfn.POISSON.DIST(2,(Depot!$B$5*(Depot!$B$7*Depot!$B$8+(1-Depot!$B$7)*Depot!$B$9)/365+INDEX(DepotLoss,13)/Depot!$B$6),TRUE))-3*(1-_xlfn.POISSON.DIST(3,(Depot!$B$5*(Depot!$B$7*Depot!$B$8+(1-Depot!$B$7)*Depot!$B$9)/365+INDEX(DepotLoss,13)/Depot!$B$6),TRUE))) | F32: =Depot!$B$6*((Depot!$B$5*(Depot!$B$7*Depot!$B$8+(1-Depot!$B$7)*Depot!$B$9)/365+INDEX(DepotLoss,9)/Depot!$B$6)*(1-_xlfn.POISSON.DIST(3,(Depot!$B$5*(Depot!$B$7*Depot!$B$8+(1-Depot!$B$7)*Depot!$B$9)/365+INDEX(DepotLoss,9)/Depot!$B$6),TRUE))-4*(1-_xlfn.POISSON.DIST(4,(Depot!$B$5*(Depot!$B$7*Depot!$B$8+(1-Depot!$B$7)*Depot!$B$9)/365+INDEX(DepotLoss,9)/Depot!$B$6),TRUE))) | G32: =Depot!$B$6*((Depot!$B$5*(Depot!$B$7*Depot!$B$8+(1-Depot!$B$7)*Depot!$B$9)/365+INDEX(DepotLoss,5)/Depot!$B$6)*(1-_xlfn.POISSON.DIST(4,(Depot!$B$5*(Depot!$B$7*Depot!$B$8+(1-Depot!$B$7)*Depot!$B$9)/365+INDEX(DepotLoss,5)/Depot!$B$6),TRUE))-5*(1-_xlfn.POISSON.DIST(5,(Depot!$B$5*(Depot!$B$7*Depot!$B$8+(1-Depot!$B$7)*Depot!$B$9)/365+INDEX(DepotLoss,5)/Depot!$B$6),TRUE))) | H32: =Depot!$B$6*((Depot!$B$5*(Depot!$B$7*Depot!$B$8+(1-Depot!$B$7)*Depot!$B$9)/365+INDEX(DepotLoss,1)/Depot!$B$6)*(1-_xlfn.POISSON.DIST(5,(Depot!$B$5*(Depot!$B$7*Depot!$B$8+(1-Depot!$B$7)*Depot!$B$9)/365+INDEX(DepotLoss,1)/Depot!$B$6),TRUE))-6*(1-_xlfn.POISSON.DIST(6,(Depot!$B$5*(Depot!$B$7*Depot!$B$8+(1-Depot!$B$7)*Depot!$B$9)/365+INDEX(DepotLoss,1)/Depot!$B$6),TRUE))) | I32: =MIN(B32:H32) | J32: =MATCH(I32,B32:H32,0)-1 | K32: =A32-Depot!$B$6*J32 | L32: =I31-I32 | M32: =IF(OR(L32="",L33=""),"",IF(L33>L32,"drop","")) | N32: =L32/($B$4/1000)
A33: 25 | B33: =Depot!$B$6*((Depot!$B$5*(Depot!$B$7*Depot!$B$8+(1-Depot!$B$7)*Depot!$B$9)/365+INDEX(DepotLoss,26)/Depot!$B$6)) | C33: =Depot!$B$6*((Depot!$B$5*(Depot!$B$7*Depot!$B$8+(1-Depot!$B$7)*Depot!$B$9)/365+INDEX(DepotLoss,22)/Depot!$B$6)*(1-_xlfn.POISSON.DIST(0,(Depot!$B$5*(Depot!$B$7*Depot!$B$8+(1-Depot!$B$7)*Depot!$B$9)/365+INDEX(DepotLoss,22)/Depot!$B$6),TRUE))-1*(1-_xlfn.POISSON.DIST(1,(Depot!$B$5*(Depot!$B$7*Depot!$B$8+(1-Depot!$B$7)*Depot!$B$9)/365+INDEX(DepotLoss,22)/Depot!$B$6),TRUE))) | D33: =Depot!$B$6*((Depot!$B$5*(Depot!$B$7*Depot!$B$8+(1-Depot!$B$7)*Depot!$B$9)/365+INDEX(DepotLoss,18)/Depot!$B$6)*(1-_xlfn.POISSON.DIST(1,(Depot!$B$5*(Depot!$B$7*Depot!$B$8+(1-Depot!$B$7)*Depot!$B$9)/365+INDEX(DepotLoss,18)/Depot!$B$6),TRUE))-2*(1-_xlfn.POISSON.DIST(2,(Depot!$B$5*(Depot!$B$7*Depot!$B$8+(1-Depot!$B$7)*Depot!$B$9)/365+INDEX(DepotLoss,18)/Depot!$B$6),TRUE))) | E33: =Depot!$B$6*((Depot!$B$5*(Depot!$B$7*Depot!$B$8+(1-Depot!$B$7)*Depot!$B$9)/365+INDEX(DepotLoss,14)/Depot!$B$6)*(1-_xlfn.POISSON.DIST(2,(Depot!$B$5*(Depot!$B$7*Depot!$B$8+(1-Depot!$B$7)*Depot!$B$9)/365+INDEX(DepotLoss,14)/Depot!$B$6),TRUE))-3*(1-_xlfn.POISSON.DIST(3,(Depot!$B$5*(Depot!$B$7*Depot!$B$8+(1-Depot!$B$7)*Depot!$B$9)/365+INDEX(DepotLoss,14)/Depot!$B$6),TRUE))) | F33: =Depot!$B$6*((Depot!$B$5*(Depot!$B$7*Depot!$B$8+(1-Depot!$B$7)*Depot!$B$9)/365+INDEX(DepotLoss,10)/Depot!$B$6)*(1-_xlfn.POISSON.DIST(3,(Depot!$B$5*(Depot!$B$7*Depot!$B$8+(1-Depot!$B$7)*Depot!$B$9)/365+INDEX(DepotLoss,10)/Depot!$B$6),TRUE))-4*(1-_xlfn.POISSON.DIST(4,(Depot!$B$5*(Depot!$B$7*Depot!$B$8+(1-Depot!$B$7)*Depot!$B$9)/365+INDEX(DepotLoss,10)/Depot!$B$6),TRUE))) | G33: =Depot!$B$6*((Depot!$B$5*(Depot!$B$7*Depot!$B$8+(1-Depot!$B$7)*Depot!$B$9)/365+INDEX(DepotLoss,6)/Depot!$B$6)*(1-_xlfn.POISSON.DIST(4,(Depot!$B$5*(Depot!$B$7*Depot!$B$8+(1-Depot!$B$7)*Depot!$B$9)/365+INDEX(DepotLoss,6)/Depot!$B$6),TRUE))-5*(1-_xlfn.POISSON.DIST(5,(Depot!$B$5*(Depot!$B$7*Depot!$B$8+(1-Depot!$B$7)*Depot!$B$9)/365+INDEX(DepotLoss,6)/Depot!$B$6),TRUE))) | H33: =Depot!$B$6*((Depot!$B$5*(Depot!$B$7*Depot!$B$8+(1-Depot!$B$7)*Depot!$B$9)/365+INDEX(DepotLoss,2)/Depot!$B$6)*(1-_xlfn.POISSON.DIST(5,(Depot!$B$5*(Depot!$B$7*Depot!$B$8+(1-Depot!$B$7)*Depot!$B$9)/365+INDEX(DepotLoss,2)/Depot!$B$6),TRUE))-6*(1-_xlfn.POISSON.DIST(6,(Depot!$B$5*(Depot!$B$7*Depot!$B$8+(1-Depot!$B$7)*Depot!$B$9)/365+INDEX(DepotLoss,2)/Depot!$B$6),TRUE))) | I33: =MIN(B33:H33) | J33: =MATCH(I33,B33:H33,0)-1 | K33: =A33-Depot!$B$6*J33 | L33: =I32-I33 | M33: =IF(OR(L33="",L34=""),"",IF(L34>L33,"drop","")) | N33: =L33/($B$4/1000)
A34: 26 | B34: =Depot!$B$6*((Depot!$B$5*(Depot!$B$7*Depot!$B$8+(1-Depot!$B$7)*Depot!$B$9)/365+INDEX(DepotLoss,27)/Depot!$B$6)) | C34: =Depot!$B$6*((Depot!$B$5*(Depot!$B$7*Depot!$B$8+(1-Depot!$B$7)*Depot!$B$9)/365+INDEX(DepotLoss,23)/Depot!$B$6)*(1-_xlfn.POISSON.DIST(0,(Depot!$B$5*(Depot!$B$7*Depot!$B$8+(1-Depot!$B$7)*Depot!$B$9)/365+INDEX(DepotLoss,23)/Depot!$B$6),TRUE))-1*(1-_xlfn.POISSON.DIST(1,(Depot!$B$5*(Depot!$B$7*Depot!$B$8+(1-Depot!$B$7)*Depot!$B$9)/365+INDEX(DepotLoss,23)/Depot!$B$6),TRUE))) | D34: =Depot!$B$6*((Depot!$B$5*(Depot!$B$7*Depot!$B$8+(1-Depot!$B$7)*Depot!$B$9)/365+INDEX(DepotLoss,19)/Depot!$B$6)*(1-_xlfn.POISSON.DIST(1,(Depot!$B$5*(Depot!$B$7*Depot!$B$8+(1-Depot!$B$7)*Depot!$B$9)/365+INDEX(DepotLoss,19)/Depot!$B$6),TRUE))-2*(1-_xlfn.POISSON.DIST(2,(Depot!$B$5*(Depot!$B$7*Depot!$B$8+(1-Depot!$B$7)*Depot!$B$9)/365+INDEX(DepotLoss,19)/Depot!$B$6),TRUE))) | E34: =Depot!$B$6*((Depot!$B$5*(Depot!$B$7*Depot!$B$8+(1-Depot!$B$7)*Depot!$B$9)/365+INDEX(DepotLoss,15)/Depot!$B$6)*(1-_xlfn.POISSON.DIST(2,(Depot!$B$5*(Depot!$B$7*Depot!$B$8+(1-Depot!$B$7)*Depot!$B$9)/365+INDEX(DepotLoss,15)/Depot!$B$6),TRUE))-3*(1-_xlfn.POISSON.DIST(3,(Depot!$B$5*(Depot!$B$7*Depot!$B$8+(1-Depot!$B$7)*Depot!$B$9)/365+INDEX(DepotLoss,15)/Depot!$B$6),TRUE))) | F34: =Depot!$B$6*((Depot!$B$5*(Depot!$B$7*Depot!$B$8+(1-Depot!$B$7)*Depot!$B$9)/365+INDEX(DepotLoss,11)/Depot!$B$6)*(1-_xlfn.POISSON.DIST(3,(Depot!$B$5*(Depot!$B$7*Depot!$B$8+(1-Depot!$B$7)*Depot!$B$9)/365+INDEX(DepotLoss,11)/Depot!$B$6),TRUE))-4*(1-_xlfn.POISSON.DIST(4,(Depot!$B$5*(Depot!$B$7*Depot!$B$8+(1-Depot!$B$7)*Depot!$B$9)/365+INDEX(DepotLoss,11)/Depot!$B$6),TRUE))) | G34: =Depot!$B$6*((Depot!$B$5*(Depot!$B$7*Depot!$B$8+(1-Depot!$B$7)*Depot!$B$9)/365+INDEX(DepotLoss,7)/Depot!$B$6)*(1-_xlfn.POISSON.DIST(4,(Depot!$B$5*(Depot!$B$7*Depot!$B$8+(1-Depot!$B$7)*Depot!$B$9)/365+INDEX(DepotLoss,7)/Depot!$B$6),TRUE))-5*(1-_xlfn.POISSON.DIST(5,(Depot!$B$5*(Depot!$B$7*Depot!$B$8+(1-Depot!$B$7)*Depot!$B$9)/365+INDEX(DepotLoss,7)/Depot!$B$6),TRUE))) | H34: =Depot!$B$6*((Depot!$B$5*(Depot!$B$7*Depot!$B$8+(1-Depot!$B$7)*Depot!$B$9)/365+INDEX(DepotLoss,3)/Depot!$B$6)*(1-_xlfn.POISSON.DIST(5,(Depot!$B$5*(Depot!$B$7*Depot!$B$8+(1-Depot!$B$7)*Depot!$B$9)/365+INDEX(DepotLoss,3)/Depot!$B$6),TRUE))-6*(1-_xlfn.POISSON.DIST(6,(Depot!$B$5*(Depot!$B$7*Depot!$B$8+(1-Depot!$B$7)*Depot!$B$9)/365+INDEX(DepotLoss,3)/Depot!$B$6),TRUE))) | I34: =MIN(B34:H34) | J34: =MATCH(I34,B34:H34,0)-1 | K34: =A34-Depot!$B$6*J34 | L34: =I33-I34 | M34: =IF(OR(L34="",L35=""),"",IF(L35>L34,"drop","")) | N34: =L34/($B$4/1000)
A35: 27 | C35: =Depot!$B$6*((Depot!$B$5*(Depot!$B$7*Depot!$B$8+(1-Depot!$B$7)*Depot!$B$9)/365+INDEX(DepotLoss,24)/Depot!$B$6)*(1-_xlfn.POISSON.DIST(0,(Depot!$B$5*(Depot!$B$7*Depot!$B$8+(1-Depot!$B$7)*Depot!$B$9)/365+INDEX(DepotLoss,24)/Depot!$B$6),TRUE))-1*(1-_xlfn.POISSON.DIST(1,(Depot!$B$5*(Depot!$B$7*Depot!$B$8+(1-Depot!$B$7)*Depot!$B$9)/365+INDEX(DepotLoss,24)/Depot!$B$6),TRUE))) | D35: =Depot!$B$6*((Depot!$B$5*(Depot!$B$7*Depot!$B$8+(1-Depot!$B$7)*Depot!$B$9)/365+INDEX(DepotLoss,20)/Depot!$B$6)*(1-_xlfn.POISSON.DIST(1,(Depot!$B$5*(Depot!$B$7*Depot!$B$8+(1-Depot!$B$7)*Depot!$B$9)/365+INDEX(DepotLoss,20)/Depot!$B$6),TRUE))-2*(1-_xlfn.POISSON.DIST(2,(Depot!$B$5*(Depot!$B$7*Depot!$B$8+(1-Depot!$B$7)*Depot!$B$9)/365+INDEX(DepotLoss,20)/Depot!$B$6),TRUE))) | E35: =Depot!$B$6*((Depot!$B$5*(Depot!$B$7*Depot!$B$8+(1-Depot!$B$7)*Depot!$B$9)/365+INDEX(DepotLoss,16)/Depot!$B$6)*(1-_xlfn.POISSON.DIST(2,(Depot!$B$5*(Depot!$B$7*Depot!$B$8+(1-Depot!$B$7)*Depot!$B$9)/365+INDEX(DepotLoss,16)/Depot!$B$6),TRUE))-3*(1-_xlfn.POISSON.DIST(3,(Depot!$B$5*(Depot!$B$7*Depot!$B$8+(1-Depot!$B$7)*Depot!$B$9)/365+INDEX(DepotLoss,16)/Depot!$B$6),TRUE))) | F35: =Depot!$B$6*((Depot!$B$5*(Depot!$B$7*Depot!$B$8+(1-Depot!$B$7)*Depot!$B$9)/365+INDEX(DepotLoss,12)/Depot!$B$6)*(1-_xlfn.POISSON.DIST(3,(Depot!$B$5*(Depot!$B$7*Depot!$B$8+(1-Depot!$B$7)*Depot!$B$9)/365+INDEX(DepotLoss,12)/Depot!$B$6),TRUE))-4*(1-_xlfn.POISSON.DIST(4,(Depot!$B$5*(Depot!$B$7*Depot!$B$8+(1-Depot!$B$7)*Depot!$B$9)/365+INDEX(DepotLoss,12)/Depot!$B$6),TRUE))) | G35: =Depot!$B$6*((Depot!$B$5*(Depot!$B$7*Depot!$B$8+(1-Depot!$B$7)*Depot!$B$9)/365+INDEX(DepotLoss,8)/Depot!$B$6)*(1-_xlfn.POISSON.DIST(4,(Depot!$B$5*(Depot!$B$7*Depot!$B$8+(1-Depot!$B$7)*Depot!$B$9)/365+INDEX(DepotLoss,8)/Depot!$B$6),TRUE))-5*(1-_xlfn.POISSON.DIST(5,(Depot!$B$5*(Depot!$B$7*Depot!$B$8+(1-Depot!$B$7)*Depot!$B$9)/365+INDEX(DepotLoss,8)/Depot!$B$6),TRUE))) | H35: =Depot!$B$6*((Depot!$B$5*(Depot!$B$7*Depot!$B$8+(1-Depot!$B$7)*Depot!$B$9)/365+INDEX(DepotLoss,4)/Depot!$B$6)*(1-_xlfn.POISSON.DIST(5,(Depot!$B$5*(Depot!$B$7*Depot!$B$8+(1-Depot!$B$7)*Depot!$B$9)/365+INDEX(DepotLoss,4)/Depot!$B$6),TRUE))-6*(1-_xlfn.POISSON.DIST(6,(Depot!$B$5*(Depot!$B$7*Depot!$B$8+(1-Depot!$B$7)*Depot!$B$9)/365+INDEX(DepotLoss,4)/Depot!$B$6),TRUE))) | I35: =MIN(B35:H35) | J35: =MATCH(I35,B35:H35,0)-1 | K35: =A35-Depot!$B$6*J35 | L35: =I34-I35 | M35: =IF(OR(L35="",L36=""),"",IF(L36>L35,"drop","")) | N35: =L35/($B$4/1000)
A36: 28 | C36: =Depot!$B$6*((Depot!$B$5*(Depot!$B$7*Depot!$B$8+(1-Depot!$B$7)*Depot!$B$9)/365+INDEX(DepotLoss,25)/Depot!$B$6)*(1-_xlfn.POISSON.DIST(0,(Depot!$B$5*(Depot!$B$7*Depot!$B$8+(1-Depot!$B$7)*Depot!$B$9)/365+INDEX(DepotLoss,25)/Depot!$B$6),TRUE))-1*(1-_xlfn.POISSON.DIST(1,(Depot!$B$5*(Depot!$B$7*Depot!$B$8+(1-Depot!$B$7)*Depot!$B$9)/365+INDEX(DepotLoss,25)/Depot!$B$6),TRUE))) | D36: =Depot!$B$6*((Depot!$B$5*(Depot!$B$7*Depot!$B$8+(1-Depot!$B$7)*Depot!$B$9)/365+INDEX(DepotLoss,21)/Depot!$B$6)*(1-_xlfn.POISSON.DIST(1,(Depot!$B$5*(Depot!$B$7*Depot!$B$8+(1-Depot!$B$7)*Depot!$B$9)/365+INDEX(DepotLoss,21)/Depot!$B$6),TRUE))-2*(1-_xlfn.POISSON.DIST(2,(Depot!$B$5*(Depot!$B$7*Depot!$B$8+(1-Depot!$B$7)*Depot!$B$9)/365+INDEX(DepotLoss,21)/Depot!$B$6),TRUE))) | E36: =Depot!$B$6*((Depot!$B$5*(Depot!$B$7*Depot!$B$8+(1-Depot!$B$7)*Depot!$B$9)/365+INDEX(DepotLoss,17)/Depot!$B$6)*(1-_xlfn.POISSON.DIST(2,(Depot!$B$5*(Depot!$B$7*Depot!$B$8+(1-Depot!$B$7)*Depot!$B$9)/365+INDEX(DepotLoss,17)/Depot!$B$6),TRUE))-3*(1-_xlfn.POISSON.DIST(3,(Depot!$B$5*(Depot!$B$7*Depot!$B$8+(1-Depot!$B$7)*Depot!$B$9)/365+INDEX(DepotLoss,17)/Depot!$B$6),TRUE))) | F36: =Depot!$B$6*((Depot!$B$5*(Depot!$B$7*Depot!$B$8+(1-Depot!$B$7)*Depot!$B$9)/365+INDEX(DepotLoss,13)/Depot!$B$6)*(1-_xlfn.POISSON.DIST(3,(Depot!$B$5*(Depot!$B$7*Depot!$B$8+(1-Depot!$B$7)*Depot!$B$9)/365+INDEX(DepotLoss,13)/Depot!$B$6),TRUE))-4*(1-_xlfn.POISSON.DIST(4,(Depot!$B$5*(Depot!$B$7*Depot!$B$8+(1-Depot!$B$7)*Depot!$B$9)/365+INDEX(DepotLoss,13)/Depot!$B$6),TRUE))) | G36: =Depot!$B$6*((Depot!$B$5*(Depot!$B$7*Depot!$B$8+(1-Depot!$B$7)*Depot!$B$9)/365+INDEX(DepotLoss,9)/Depot!$B$6)*(1-_xlfn.POISSON.DIST(4,(Depot!$B$5*(Depot!$B$7*Depot!$B$8+(1-Depot!$B$7)*Depot!$B$9)/365+INDEX(DepotLoss,9)/Depot!$B$6),TRUE))-5*(1-_xlfn.POISSON.DIST(5,(Depot!$B$5*(Depot!$B$7*Depot!$B$8+(1-Depot!$B$7)*Depot!$B$9)/365+INDEX(DepotLoss,9)/Depot!$B$6),TRUE))) | H36: =Depot!$B$6*((Depot!$B$5*(Depot!$B$7*Depot!$B$8+(1-Depot!$B$7)*Depot!$B$9)/365+INDEX(DepotLoss,5)/Depot!$B$6)*(1-_xlfn.POISSON.DIST(5,(Depot!$B$5*(Depot!$B$7*Depot!$B$8+(1-Depot!$B$7)*Depot!$B$9)/365+INDEX(DepotLoss,5)/Depot!$B$6),TRUE))-6*(1-_xlfn.POISSON.DIST(6,(Depot!$B$5*(Depot!$B$7*Depot!$B$8+(1-Depot!$B$7)*Depot!$B$9)/365+INDEX(DepotLoss,5)/Depot!$B$6),TRUE))) | I36: =MIN(B36:H36) | J36: =MATCH(I36,B36:H36,0)-1 | K36: =A36-Depot!$B$6*J36 | L36: =I35-I36 | M36: =IF(OR(L36="",L37=""),"",IF(L37>L36,"drop","")) | N36: =L36/($B$4/1000)
A37: 29 | C37: =Depot!$B$6*((Depot!$B$5*(Depot!$B$7*Depot!$B$8+(1-Depot!$B$7)*Depot!$B$9)/365+INDEX(DepotLoss,26)/Depot!$B$6)*(1-_xlfn.POISSON.DIST(0,(Depot!$B$5*(Depot!$B$7*Depot!$B$8+(1-Depot!$B$7)*Depot!$B$9)/365+INDEX(DepotLoss,26)/Depot!$B$6),TRUE))-1*(1-_xlfn.POISSON.DIST(1,(Depot!$B$5*(Depot!$B$7*Depot!$B$8+(1-Depot!$B$7)*Depot!$B$9)/365+INDEX(DepotLoss,26)/Depot!$B$6),TRUE))) | D37: =Depot!$B$6*((Depot!$B$5*(Depot!$B$7*Depot!$B$8+(1-Depot!$B$7)*Depot!$B$9)/365+INDEX(DepotLoss,22)/Depot!$B$6)*(1-_xlfn.POISSON.DIST(1,(Depot!$B$5*(Depot!$B$7*Depot!$B$8+(1-Depot!$B$7)*Depot!$B$9)/365+INDEX(DepotLoss,22)/Depot!$B$6),TRUE))-2*(1-_xlfn.POISSON.DIST(2,(Depot!$B$5*(Depot!$B$7*Depot!$B$8+(1-Depot!$B$7)*Depot!$B$9)/365+INDEX(DepotLoss,22)/Depot!$B$6),TRUE))) | E37: =Depot!$B$6*((Depot!$B$5*(Depot!$B$7*Depot!$B$8+(1-Depot!$B$7)*Depot!$B$9)/365+INDEX(DepotLoss,18)/Depot!$B$6)*(1-_xlfn.POISSON.DIST(2,(Depot!$B$5*(Depot!$B$7*Depot!$B$8+(1-Depot!$B$7)*Depot!$B$9)/365+INDEX(DepotLoss,18)/Depot!$B$6),TRUE))-3*(1-_xlfn.POISSON.DIST(3,(Depot!$B$5*(Depot!$B$7*Depot!$B$8+(1-Depot!$B$7)*Depot!$B$9)/365+INDEX(DepotLoss,18)/Depot!$B$6),TRUE))) | F37: =Depot!$B$6*((Depot!$B$5*(Depot!$B$7*Depot!$B$8+(1-Depot!$B$7)*Depot!$B$9)/365+INDEX(DepotLoss,14)/Depot!$B$6)*(1-_xlfn.POISSON.DIST(3,(Depot!$B$5*(Depot!$B$7*Depot!$B$8+(1-Depot!$B$7)*Depot!$B$9)/365+INDEX(DepotLoss,14)/Depot!$B$6),TRUE))-4*(1-_xlfn.POISSON.DIST(4,(Depot!$B$5*(Depot!$B$7*Depot!$B$8+(1-Depot!$B$7)*Depot!$B$9)/365+INDEX(DepotLoss,14)/Depot!$B$6),TRUE))) | G37: =Depot!$B$6*((Depot!$B$5*(Depot!$B$7*Depot!$B$8+(1-Depot!$B$7)*Depot!$B$9)/365+INDEX(DepotLoss,10)/Depot!$B$6)*(1-_xlfn.POISSON.DIST(4,(Depot!$B$5*(Depot!$B$7*Depot!$B$8+(1-Depot!$B$7)*Depot!$B$9)/365+INDEX(DepotLoss,10)/Depot!$B$6),TRUE))-5*(1-_xlfn.POISSON.DIST(5,(Depot!$B$5*(Depot!$B$7*Depot!$B$8+(1-Depot!$B$7)*Depot!$B$9)/365+INDEX(DepotLoss,10)/Depot!$B$6),TRUE))) | H37: =Depot!$B$6*((Depot!$B$5*(Depot!$B$7*Depot!$B$8+(1-Depot!$B$7)*Depot!$B$9)/365+INDEX(DepotLoss,6)/Depot!$B$6)*(1-_xlfn.POISSON.DIST(5,(Depot!$B$5*(Depot!$B$7*Depot!$B$8+(1-Depot!$B$7)*Depot!$B$9)/365+INDEX(DepotLoss,6)/Depot!$B$6),TRUE))-6*(1-_xlfn.POISSON.DIST(6,(Depot!$B$5*(Depot!$B$7*Depot!$B$8+(1-Depot!$B$7)*Depot!$B$9)/365+INDEX(DepotLoss,6)/Depot!$B$6),TRUE))) | I37: =MIN(B37:H37) | J37: =MATCH(I37,B37:H37,0)-1 | K37: =A37-Depot!$B$6*J37 | L37: =I36-I37 | M37: =IF(OR(L37="",L38=""),"",IF(L38>L37,"drop","")) | N37: =L37/($B$4/1000)
A38: 30 | C38: =Depot!$B$6*((Depot!$B$5*(Depot!$B$7*Depot!$B$8+(1-Depot!$B$7)*Depot!$B$9)/365+INDEX(DepotLoss,27)/Depot!$B$6)*(1-_xlfn.POISSON.DIST(0,(Depot!$B$5*(Depot!$B$7*Depot!$B$8+(1-Depot!$B$7)*Depot!$B$9)/365+INDEX(DepotLoss,27)/Depot!$B$6),TRUE))-1*(1-_xlfn.POISSON.DIST(1,(Depot!$B$5*(Depot!$B$7*Depot!$B$8+(1-Depot!$B$7)*Depot!$B$9)/365+INDEX(DepotLoss,27)/Depot!$B$6),TRUE))) | D38: =Depot!$B$6*((Depot!$B$5*(Depot!$B$7*Depot!$B$8+(1-Depot!$B$7)*Depot!$B$9)/365+INDEX(DepotLoss,23)/Depot!$B$6)*(1-_xlfn.POISSON.DIST(1,(Depot!$B$5*(Depot!$B$7*Depot!$B$8+(1-Depot!$B$7)*Depot!$B$9)/365+INDEX(DepotLoss,23)/Depot!$B$6),TRUE))-2*(1-_xlfn.POISSON.DIST(2,(Depot!$B$5*(Depot!$B$7*Depot!$B$8+(1-Depot!$B$7)*Depot!$B$9)/365+INDEX(DepotLoss,23)/Depot!$B$6),TRUE))) | E38: =Depot!$B$6*((Depot!$B$5*(Depot!$B$7*Depot!$B$8+(1-Depot!$B$7)*Depot!$B$9)/365+INDEX(DepotLoss,19)/Depot!$B$6)*(1-_xlfn.POISSON.DIST(2,(Depot!$B$5*(Depot!$B$7*Depot!$B$8+(1-Depot!$B$7)*Depot!$B$9)/365+INDEX(DepotLoss,19)/Depot!$B$6),TRUE))-3*(1-_xlfn.POISSON.DIST(3,(Depot!$B$5*(Depot!$B$7*Depot!$B$8+(1-Depot!$B$7)*Depot!$B$9)/365+INDEX(DepotLoss,19)/Depot!$B$6),TRUE))) | F38: =Depot!$B$6*((Depot!$B$5*(Depot!$B$7*Depot!$B$8+(1-Depot!$B$7)*Depot!$B$9)/365+INDEX(DepotLoss,15)/Depot!$B$6)*(1-_xlfn.POISSON.DIST(3,(Depot!$B$5*(Depot!$B$7*Depot!$B$8+(1-Depot!$B$7)*Depot!$B$9)/365+INDEX(DepotLoss,15)/Depot!$B$6),TRUE))-4*(1-_xlfn.POISSON.DIST(4,(Depot!$B$5*(Depot!$B$7*Depot!$B$8+(1-Depot!$B$7)*Depot!$B$9)/365+INDEX(DepotLoss,15)/Depot!$B$6),TRUE))) | G38: =Depot!$B$6*((Depot!$B$5*(Depot!$B$7*Depot!$B$8+(1-Depot!$B$7)*Depot!$B$9)/365+INDEX(DepotLoss,11)/Depot!$B$6)*(1-_xlfn.POISSON.DIST(4,(Depot!$B$5*(Depot!$B$7*Depot!$B$8+(1-Depot!$B$7)*Depot!$B$9)/365+INDEX(DepotLoss,11)/Depot!$B$6),TRUE))-5*(1-_xlfn.POISSON.DIST(5,(Depot!$B$5*(Depot!$B$7*Depot!$B$8+(1-Depot!$B$7)*Depot!$B$9)/365+INDEX(DepotLoss,11)/Depot!$B$6),TRUE))) | H38: =Depot!$B$6*((Depot!$B$5*(Depot!$B$7*Depot!$B$8+(1-Depot!$B$7)*Depot!$B$9)/365+INDEX(DepotLoss,7)/Depot!$B$6)*(1-_xlfn.POISSON.DIST(5,(Depot!$B$5*(Depot!$B$7*Depot!$B$8+(1-Depot!$B$7)*Depot!$B$9)/365+INDEX(DepotLoss,7)/Depot!$B$6),TRUE))-6*(1-_xlfn.POISSON.DIST(6,(Depot!$B$5*(Depot!$B$7*Depot!$B$8+(1-Depot!$B$7)*Depot!$B$9)/365+INDEX(DepotLoss,7)/Depot!$B$6),TRUE))) | I38: =MIN(B38:H38) | J38: =MATCH(I38,B38:H38,0)-1 | K38: =A38-Depot!$B$6*J38 | L38: =I37-I38 | M38: =IF(OR(L38="",L39=""),"",IF(L39>L38,"drop","")) | N38: =L38/($B$4/1000)
A39: 31 | D39: =Depot!$B$6*((Depot!$B$5*(Depot!$B$7*Depot!$B$8+(1-Depot!$B$7)*Depot!$B$9)/365+INDEX(DepotLoss,24)/Depot!$B$6)*(1-_xlfn.POISSON.DIST(1,(Depot!$B$5*(Depot!$B$7*Depot!$B$8+(1-Depot!$B$7)*Depot!$B$9)/365+INDEX(DepotLoss,24)/Depot!$B$6),TRUE))-2*(1-_xlfn.POISSON.DIST(2,(Depot!$B$5*(Depot!$B$7*Depot!$B$8+(1-Depot!$B$7)*Depot!$B$9)/365+INDEX(DepotLoss,24)/Depot!$B$6),TRUE))) | E39: =Depot!$B$6*((Depot!$B$5*(Depot!$B$7*Depot!$B$8+(1-Depot!$B$7)*Depot!$B$9)/365+INDEX(DepotLoss,20)/Depot!$B$6)*(1-_xlfn.POISSON.DIST(2,(Depot!$B$5*(Depot!$B$7*Depot!$B$8+(1-Depot!$B$7)*Depot!$B$9)/365+INDEX(DepotLoss,20)/Depot!$B$6),TRUE))-3*(1-_xlfn.POISSON.DIST(3,(Depot!$B$5*(Depot!$B$7*Depot!$B$8+(1-Depot!$B$7)*Depot!$B$9)/365+INDEX(DepotLoss,20)/Depot!$B$6),TRUE))) | F39: =Depot!$B$6*((Depot!$B$5*(Depot!$B$7*Depot!$B$8+(1-Depot!$B$7)*Depot!$B$9)/365+INDEX(DepotLoss,16)/Depot!$B$6)*(1-_xlfn.POISSON.DIST(3,(Depot!$B$5*(Depot!$B$7*Depot!$B$8+(1-Depot!$B$7)*Depot!$B$9)/365+INDEX(DepotLoss,16)/Depot!$B$6),TRUE))-4*(1-_xlfn.POISSON.DIST(4,(Depot!$B$5*(Depot!$B$7*Depot!$B$8+(1-Depot!$B$7)*Depot!$B$9)/365+INDEX(DepotLoss,16)/Depot!$B$6),TRUE))) | G39: =Depot!$B$6*((Depot!$B$5*(Depot!$B$7*Depot!$B$8+(1-Depot!$B$7)*Depot!$B$9)/365+INDEX(DepotLoss,12)/Depot!$B$6)*(1-_xlfn.POISSON.DIST(4,(Depot!$B$5*(Depot!$B$7*Depot!$B$8+(1-Depot!$B$7)*Depot!$B$9)/365+INDEX(DepotLoss,12)/Depot!$B$6),TRUE))-5*(1-_xlfn.POISSON.DIST(5,(Depot!$B$5*(Depot!$B$7*Depot!$B$8+(1-Depot!$B$7)*Depot!$B$9)/365+INDEX(DepotLoss,12)/Depot!$B$6),TRUE))) | H39: =Depot!$B$6*((Depot!$B$5*(Depot!$B$7*Depot!$B$8+(1-Depot!$B$7)*Depot!$B$9)/365+INDEX(DepotLoss,8)/Depot!$B$6)*(1-_xlfn.POISSON.DIST(5,(Depot!$B$5*(Depot!$B$7*Depot!$B$8+(1-Depot!$B$7)*Depot!$B$9)/365+INDEX(DepotLoss,8)/Depot!$B$6),TRUE))-6*(1-_xlfn.POISSON.DIST(6,(Depot!$B$5*(Depot!$B$7*Depot!$B$8+(1-Depot!$B$7)*Depot!$B$9)/365+INDEX(DepotLoss,8)/Depot!$B$6),TRUE))) | I39: =MIN(B39:H39) | J39: =MATCH(I39,B39:H39,0)-1 | K39: =A39-Depot!$B$6*J39 | L39: =I38-I39 | M39: =IF(OR(L39="",L40=""),"",IF(L40>L39,"drop","")) | N39: =L39/($B$4/1000)
A40: 32 | D40: =Depot!$B$6*((Depot!$B$5*(Depot!$B$7*Depot!$B$8+(1-Depot!$B$7)*Depot!$B$9)/365+INDEX(DepotLoss,25)/Depot!$B$6)*(1-_xlfn.POISSON.DIST(1,(Depot!$B$5*(Depot!$B$7*Depot!$B$8+(1-Depot!$B$7)*Depot!$B$9)/365+INDEX(DepotLoss,25)/Depot!$B$6),TRUE))-2*(1-_xlfn.POISSON.DIST(2,(Depot!$B$5*(Depot!$B$7*Depot!$B$8+(1-Depot!$B$7)*Depot!$B$9)/365+INDEX(DepotLoss,25)/Depot!$B$6),TRUE))) | E40: =Depot!$B$6*((Depot!$B$5*(Depot!$B$7*Depot!$B$8+(1-Depot!$B$7)*Depot!$B$9)/365+INDEX(DepotLoss,21)/Depot!$B$6)*(1-_xlfn.POISSON.DIST(2,(Depot!$B$5*(Depot!$B$7*Depot!$B$8+(1-Depot!$B$7)*Depot!$B$9)/365+INDEX(DepotLoss,21)/Depot!$B$6),TRUE))-3*(1-_xlfn.POISSON.DIST(3,(Depot!$B$5*(Depot!$B$7*Depot!$B$8+(1-Depot!$B$7)*Depot!$B$9)/365+INDEX(DepotLoss,21)/Depot!$B$6),TRUE))) | F40: =Depot!$B$6*((Depot!$B$5*(Depot!$B$7*Depot!$B$8+(1-Depot!$B$7)*Depot!$B$9)/365+INDEX(DepotLoss,17)/Depot!$B$6)*(1-_xlfn.POISSON.DIST(3,(Depot!$B$5*(Depot!$B$7*Depot!$B$8+(1-Depot!$B$7)*Depot!$B$9)/365+INDEX(DepotLoss,17)/Depot!$B$6),TRUE))-4*(1-_xlfn.POISSON.DIST(4,(Depot!$B$5*(Depot!$B$7*Depot!$B$8+(1-Depot!$B$7)*Depot!$B$9)/365+INDEX(DepotLoss,17)/Depot!$B$6),TRUE))) | G40: =Depot!$B$6*((Depot!$B$5*(Depot!$B$7*Depot!$B$8+(1-Depot!$B$7)*Depot!$B$9)/365+INDEX(DepotLoss,13)/Depot!$B$6)*(1-_xlfn.POISSON.DIST(4,(Depot!$B$5*(Depot!$B$7*Depot!$B$8+(1-Depot!$B$7)*Depot!$B$9)/365+INDEX(DepotLoss,13)/Depot!$B$6),TRUE))-5*(1-_xlfn.POISSON.DIST(5,(Depot!$B$5*(Depot!$B$7*Depot!$B$8+(1-Depot!$B$7)*Depot!$B$9)/365+INDEX(DepotLoss,13)/Depot!$B$6),TRUE))) | H40: =Depot!$B$6*((Depot!$B$5*(Depot!$B$7*Depot!$B$8+(1-Depot!$B$7)*Depot!$B$9)/365+INDEX(DepotLoss,9)/Depot!$B$6)*(1-_xlfn.POISSON.DIST(5,(Depot!$B$5*(Depot!$B$7*Depot!$B$8+(1-Depot!$B$7)*Depot!$B$9)/365+INDEX(DepotLoss,9)/Depot!$B$6),TRUE))-6*(1-_xlfn.POISSON.DIST(6,(Depot!$B$5*(Depot!$B$7*Depot!$B$8+(1-Depot!$B$7)*Depot!$B$9)/365+INDEX(DepotLoss,9)/Depot!$B$6),TRUE))) | I40: =MIN(B40:H40) | J40: =MATCH(I40,B40:H40,0)-1 | K40: =A40-Depot!$B$6*J40 | L40: =I39-I40 | M40: =IF(OR(L40="",L41=""),"",IF(L41>L40,"drop","")) | N40: =L40/($B$4/1000)
A41: 33 | D41: =Depot!$B$6*((Depot!$B$5*(Depot!$B$7*Depot!$B$8+(1-Depot!$B$7)*Depot!$B$9)/365+INDEX(DepotLoss,26)/Depot!$B$6)*(1-_xlfn.POISSON.DIST(1,(Depot!$B$5*(Depot!$B$7*Depot!$B$8+(1-Depot!$B$7)*Depot!$B$9)/365+INDEX(DepotLoss,26)/Depot!$B$6),TRUE))-2*(1-_xlfn.POISSON.DIST(2,(Depot!$B$5*(Depot!$B$7*Depot!$B$8+(1-Depot!$B$7)*Depot!$B$9)/365+INDEX(DepotLoss,26)/Depot!$B$6),TRUE))) | E41: =Depot!$B$6*((Depot!$B$5*(Depot!$B$7*Depot!$B$8+(1-Depot!$B$7)*Depot!$B$9)/365+INDEX(DepotLoss,22)/Depot!$B$6)*(1-_xlfn.POISSON.DIST(2,(Depot!$B$5*(Depot!$B$7*Depot!$B$8+(1-Depot!$B$7)*Depot!$B$9)/365+INDEX(DepotLoss,22)/Depot!$B$6),TRUE))-3*(1-_xlfn.POISSON.DIST(3,(Depot!$B$5*(Depot!$B$7*Depot!$B$8+(1-Depot!$B$7)*Depot!$B$9)/365+INDEX(DepotLoss,22)/Depot!$B$6),TRUE))) | F41: =Depot!$B$6*((Depot!$B$5*(Depot!$B$7*Depot!$B$8+(1-Depot!$B$7)*Depot!$B$9)/365+INDEX(DepotLoss,18)/Depot!$B$6)*(1-_xlfn.POISSON.DIST(3,(Depot!$B$5*(Depot!$B$7*Depot!$B$8+(1-Depot!$B$7)*Depot!$B$9)/365+INDEX(DepotLoss,18)/Depot!$B$6),TRUE))-4*(1-_xlfn.POISSON.DIST(4,(Depot!$B$5*(Depot!$B$7*Depot!$B$8+(1-Depot!$B$7)*Depot!$B$9)/365+INDEX(DepotLoss,18)/Depot!$B$6),TRUE))) | G41: =Depot!$B$6*((Depot!$B$5*(Depot!$B$7*Depot!$B$8+(1-Depot!$B$7)*Depot!$B$9)/365+INDEX(DepotLoss,14)/Depot!$B$6)*(1-_xlfn.POISSON.DIST(4,(Depot!$B$5*(Depot!$B$7*Depot!$B$8+(1-Depot!$B$7)*Depot!$B$9)/365+INDEX(DepotLoss,14)/Depot!$B$6),TRUE))-5*(1-_xlfn.POISSON.DIST(5,(Depot!$B$5*(Depot!$B$7*Depot!$B$8+(1-Depot!$B$7)*Depot!$B$9)/365+INDEX(DepotLoss,14)/Depot!$B$6),TRUE))) | H41: =Depot!$B$6*((Depot!$B$5*(Depot!$B$7*Depot!$B$8+(1-Depot!$B$7)*Depot!$B$9)/365+INDEX(DepotLoss,10)/Depot!$B$6)*(1-_xlfn.POISSON.DIST(5,(Depot!$B$5*(Depot!$B$7*Depot!$B$8+(1-Depot!$B$7)*Depot!$B$9)/365+INDEX(DepotLoss,10)/Depot!$B$6),TRUE))-6*(1-_xlfn.POISSON.DIST(6,(Depot!$B$5*(Depot!$B$7*Depot!$B$8+(1-Depot!$B$7)*Depot!$B$9)/365+INDEX(DepotLoss,10)/Depot!$B$6),TRUE))) | I41: =MIN(B41:H41) | J41: =MATCH(I41,B41:H41,0)-1 | K41: =A41-Depot!$B$6*J41 | L41: =I40-I41 | M41: =IF(OR(L41="",L42=""),"",IF(L42>L41,"drop","")) | N41: =L41/($B$4/1000)
...

Sheet Ledger
A1: Two levels, one row per event
A2: @sec-multiechelon-ledger. Review is continuous, so there are no periods. Blue columns are typed.
A4: week | B4: event | C4: I_j | D4: B_j | E4: X_j | F4: I_0 | G4: B_0 | H4: X_0 | I4: residual j | J4: residual 0 | K4: weeks held
