Workbook
Name HubLossOne: 'Hub'!$D$33:$D$93
Name HubLossTwo: 'Hub'!$E$33:$E$93
Name DelayMass: 'Delay'!$G$14:$G$35
Name DelayMid: 'Delay'!$H$14:$H$35
Name HubTail: 'Exact'!$B$33:$B$84
Name OrdersTail: 'Orders'!$B$20:$B$64
Name OrdersCount: 'Orders'!$D$20:$D$34
Name GenExactDist: 'HubGeneral'!$C$32:$C$92
Name GenExactLossOne: 'HubGeneral'!$D$32:$D$92
Name GenExactLossTwo: 'HubGeneral'!$E$32:$E$92
Name GenRecipeDist: 'HubGeneral'!$G$32:$G$92
Name GenRecipeLossOne: 'HubGeneral'!$H$32:$H$92
Name GenRecipeLossTwo: 'HubGeneral'!$I$32:$I$92
Name GenShortcutDist: 'HubGeneral'!$K$32:$K$92
Name GenShortcutLossOne: 'HubGeneral'!$L$32:$L$92
Name GenShortcutLossTwo: 'HubGeneral'!$M$32:$M$92
Name PassOneStoreDist: 'Iterate'!$C$49:$C$144
Name PassOneStoreLossOne: 'Iterate'!$D$49:$D$144
Name PassOneStoreLossTwo: 'Iterate'!$E$49:$E$144
Name PassOneHubDist: 'Iterate'!$G$49:$G$214
Name PassOneHubLossOne: 'Iterate'!$H$49:$H$214
Name PassOneHubLossTwo: 'Iterate'!$I$49:$I$214
Name PassTwoStoreDist: 'Iterate'!$C$245:$C$340
Name PassTwoStoreLossOne: 'Iterate'!$D$245:$D$340
Name PassTwoStoreLossTwo: 'Iterate'!$E$245:$E$340
Name PassTwoHubDist: 'Iterate'!$G$245:$G$410
Name PassTwoHubLossOne: 'Iterate'!$H$245:$H$410
Name PassTwoHubLossTwo: 'Iterate'!$I$245:$I$410
Name PassThreeStoreDist: 'Iterate'!$C$441:$C$536
Name PassThreeStoreLossOne: 'Iterate'!$D$441:$D$536
Name PassThreeStoreLossTwo: 'Iterate'!$E$441:$E$536
Name PassThreeHubDist: 'Iterate'!$G$441:$G$606
Name PassThreeHubLossOne: 'Iterate'!$H$441:$H$606
Name PassThreeHubLossTwo: 'Iterate'!$I$441:$I$606

Sheet Hub
A1: The hub, when the storerooms order one at a time
A2: @sec-batchedmultiechelon. Every storeroom demand becomes one request at the hub, so the hub is chapter 8's location.
A4: The item and the network
A5: demand per storeroom | B5: 1 | C5: units a week
A6: storerooms N | B6: 4 | C6: locations
A7: hub lead time L_0 | B7: 3 | C7: weeks
A8: transit O_j | B8: 1 | C8: weeks
A9: holding cost h | B9: 28.75 | C9: dollars a unit a year
A10: backorder cost b | B10: 287.5 | C10: dollars a unit a year
A11: weeks a year | B11: 52 | C11: weeks
A12: lambda_0 | B12: =B5*B6 | C12: units a week reaching the hub
A13: mean lead time demand | B13: =B12*B7 | C13: Poisson, lambda_0 L_0
A14: h per week | B14: =B9/B11 | C14: $/unit/yr x 1 yr/52 wk
A15: b per week | B15: =B10/B11
A17: The hub's policy
A18: reorder point r_0 | B18: 9 | C18: units
A19: order quantity Q_0 | B19: 8 | C19: units
A21: Its measures, averaged over the positions r_0+1 .. r_0+Q_0
A22: expected backorders | B22: =(INDEX(HubLossTwo,B18+1)-INDEX(HubLossTwo,B18+B19+1))/B19
A23: ready rate | B23: =1-(INDEX(HubLossOne,B18+1)-INDEX(HubLossOne,B18+B19+1))/B19
A24: expected on-hand | B24: =(B19+1)/2+B18-B13+B22
A25: E[B(B-1)] | B25: =2/B19*SUM(INDEX(HubLossTwo,B18+1+1):INDEX(HubLossTwo,B18+B19+1))
A26: Var[B] | B26: =B25+B22-B22^2
A27: mean wait, weeks | B27: =B22/B12 | C27: Little's law, over every request
A28: Var[W], weeks squared | B28: =(B26-B22)/B12^2 | C28: the distributional Little's law, in factorial moments
A31: Poisson at the mean lead time demand. G1 is closed form; G2 walks down from mu^2/2.
A32: x | B32: P(X = x) | C32: F(x) | D32: G1(x) | E32: G2(x)
A33: 0 | B33: =_xlfn.POISSON.DIST(A33,$B$13,FALSE) | C33: =_xlfn.POISSON.DIST(A33,$B$13,TRUE) | D33: =($B$13*(1-IF(A33<1,0,_xlfn.POISSON.DIST(A33-1,$B$13,TRUE)))-A33*(1-_xlfn.POISSON.DIST(A33,$B$13,TRUE))) | E33: =$B$13^2/2
A34: 1 | B34: =_xlfn.POISSON.DIST(A34,$B$13,FALSE) | C34: =_xlfn.POISSON.DIST(A34,$B$13,TRUE) | D34: =($B$13*(1-IF(A34<1,0,_xlfn.POISSON.DIST(A34-1,$B$13,TRUE)))-A34*(1-_xlfn.POISSON.DIST(A34,$B$13,TRUE))) | E34: =E33-D34
A35: 2 | B35: =_xlfn.POISSON.DIST(A35,$B$13,FALSE) | C35: =_xlfn.POISSON.DIST(A35,$B$13,TRUE) | D35: =($B$13*(1-IF(A35<1,0,_xlfn.POISSON.DIST(A35-1,$B$13,TRUE)))-A35*(1-_xlfn.POISSON.DIST(A35,$B$13,TRUE))) | E35: =E34-D35
A36: 3 | B36: =_xlfn.POISSON.DIST(A36,$B$13,FALSE) | C36: =_xlfn.POISSON.DIST(A36,$B$13,TRUE) | D36: =($B$13*(1-IF(A36<1,0,_xlfn.POISSON.DIST(A36-1,$B$13,TRUE)))-A36*(1-_xlfn.POISSON.DIST(A36,$B$13,TRUE))) | E36: =E35-D36
A37: 4 | B37: =_xlfn.POISSON.DIST(A37,$B$13,FALSE) | C37: =_xlfn.POISSON.DIST(A37,$B$13,TRUE) | D37: =($B$13*(1-IF(A37<1,0,_xlfn.POISSON.DIST(A37-1,$B$13,TRUE)))-A37*(1-_xlfn.POISSON.DIST(A37,$B$13,TRUE))) | E37: =E36-D37
A38: 5 | B38: =_xlfn.POISSON.DIST(A38,$B$13,FALSE) | C38: =_xlfn.POISSON.DIST(A38,$B$13,TRUE) | D38: =($B$13*(1-IF(A38<1,0,_xlfn.POISSON.DIST(A38-1,$B$13,TRUE)))-A38*(1-_xlfn.POISSON.DIST(A38,$B$13,TRUE))) | E38: =E37-D38
A39: 6 | B39: =_xlfn.POISSON.DIST(A39,$B$13,FALSE) | C39: =_xlfn.POISSON.DIST(A39,$B$13,TRUE) | D39: =($B$13*(1-IF(A39<1,0,_xlfn.POISSON.DIST(A39-1,$B$13,TRUE)))-A39*(1-_xlfn.POISSON.DIST(A39,$B$13,TRUE))) | E39: =E38-D39
A40: 7 | B40: =_xlfn.POISSON.DIST(A40,$B$13,FALSE) | C40: =_xlfn.POISSON.DIST(A40,$B$13,TRUE) | D40: =($B$13*(1-IF(A40<1,0,_xlfn.POISSON.DIST(A40-1,$B$13,TRUE)))-A40*(1-_xlfn.POISSON.DIST(A40,$B$13,TRUE))) | E40: =E39-D40
A41: 8 | B41: =_xlfn.POISSON.DIST(A41,$B$13,FALSE) | C41: =_xlfn.POISSON.DIST(A41,$B$13,TRUE) | D41: =($B$13*(1-IF(A41<1,0,_xlfn.POISSON.DIST(A41-1,$B$13,TRUE)))-A41*(1-_xlfn.POISSON.DIST(A41,$B$13,TRUE))) | E41: =E40-D41
A42: 9 | B42: =_xlfn.POISSON.DIST(A42,$B$13,FALSE) | C42: =_xlfn.POISSON.DIST(A42,$B$13,TRUE) | D42: =($B$13*(1-IF(A42<1,0,_xlfn.POISSON.DIST(A42-1,$B$13,TRUE)))-A42*(1-_xlfn.POISSON.DIST(A42,$B$13,TRUE))) | E42: =E41-D42
A43: 10 | B43: =_xlfn.POISSON.DIST(A43,$B$13,FALSE) | C43: =_xlfn.POISSON.DIST(A43,$B$13,TRUE) | D43: =($B$13*(1-IF(A43<1,0,_xlfn.POISSON.DIST(A43-1,$B$13,TRUE)))-A43*(1-_xlfn.POISSON.DIST(A43,$B$13,TRUE))) | E43: =E42-D43
A44: 11 | B44: =_xlfn.POISSON.DIST(A44,$B$13,FALSE) | C44: =_xlfn.POISSON.DIST(A44,$B$13,TRUE) | D44: =($B$13*(1-IF(A44<1,0,_xlfn.POISSON.DIST(A44-1,$B$13,TRUE)))-A44*(1-_xlfn.POISSON.DIST(A44,$B$13,TRUE))) | E44: =E43-D44
A45: 12 | B45: =_xlfn.POISSON.DIST(A45,$B$13,FALSE) | C45: =_xlfn.POISSON.DIST(A45,$B$13,TRUE) | D45: =($B$13*(1-IF(A45<1,0,_xlfn.POISSON.DIST(A45-1,$B$13,TRUE)))-A45*(1-_xlfn.POISSON.DIST(A45,$B$13,TRUE))) | E45: =E44-D45
...

Sheet Delay
A1: The wait a request suffers at the hub
A2: @sec-batchedmultiechelon. Waiting at most w is having stock at once with a lead time w shorter.
A4: Read from the Hub sheet
A5: lambda_0 | B5: =Hub!B12
A6: L_0 | B6: =Hub!B7
A7: r_0 | B7: =Hub!B18
A8: Q_0 | B8: =Hub!B19
A10: What the grid gives
A11: P(W = 0), the ready rate | B11: =F14
A12: mean wait, the grid | B12: =SUMPRODUCT(G14:G35,H14:H35)
A13: day k | B13: w, weeks | C13: mean over L_0 - w | D13: G1(r_0) | E13: G1(r_0+Q_0) | F13: P(W <= w) | G13: P(k-1 < W <= k) | H13: midpoint | I13: P(W > w)
A14: 0 | B14: =A14/7 | C14: =IF(B14<$B$6,$B$5*($B$6-B14),0) | D14: =IF(C14>0,(C14*(1-IF($B$7<1,0,_xlfn.POISSON.DIST($B$7-1,C14,TRUE)))-$B$7*(1-_xlfn.POISSON.DIST($B$7,C14,TRUE))),0) | E14: =IF(C14>0,(C14*(1-IF(($B$7+$B$8)<1,0,_xlfn.POISSON.DIST(($B$7+$B$8)-1,C14,TRUE)))-($B$7+$B$8)*(1-_xlfn.POISSON.DIST(($B$7+$B$8),C14,TRUE))),0) | F14: =IF(B14>=$B$6,1,1-(D14-E14)/$B$8) | G14: =F14 | H14: 0 | I14: =1-F14
A15: 1 | B15: =A15/7 | C15: =IF(B15<$B$6,$B$5*($B$6-B15),0) | D15: =IF(C15>0,(C15*(1-IF($B$7<1,0,_xlfn.POISSON.DIST($B$7-1,C15,TRUE)))-$B$7*(1-_xlfn.POISSON.DIST($B$7,C15,TRUE))),0) | E15: =IF(C15>0,(C15*(1-IF(($B$7+$B$8)<1,0,_xlfn.POISSON.DIST(($B$7+$B$8)-1,C15,TRUE)))-($B$7+$B$8)*(1-_xlfn.POISSON.DIST(($B$7+$B$8),C15,TRUE))),0) | F15: =IF(B15>=$B$6,1,1-(D15-E15)/$B$8) | G15: =F15-F14 | H15: =(B14+B15)/2 | I15: =1-F15
A16: 2 | B16: =A16/7 | C16: =IF(B16<$B$6,$B$5*($B$6-B16),0) | D16: =IF(C16>0,(C16*(1-IF($B$7<1,0,_xlfn.POISSON.DIST($B$7-1,C16,TRUE)))-$B$7*(1-_xlfn.POISSON.DIST($B$7,C16,TRUE))),0) | E16: =IF(C16>0,(C16*(1-IF(($B$7+$B$8)<1,0,_xlfn.POISSON.DIST(($B$7+$B$8)-1,C16,TRUE)))-($B$7+$B$8)*(1-_xlfn.POISSON.DIST(($B$7+$B$8),C16,TRUE))),0) | F16: =IF(B16>=$B$6,1,1-(D16-E16)/$B$8) | G16: =F16-F15 | H16: =(B15+B16)/2 | I16: =1-F16
A17: 3 | B17: =A17/7 | C17: =IF(B17<$B$6,$B$5*($B$6-B17),0) | D17: =IF(C17>0,(C17*(1-IF($B$7<1,0,_xlfn.POISSON.DIST($B$7-1,C17,TRUE)))-$B$7*(1-_xlfn.POISSON.DIST($B$7,C17,TRUE))),0) | E17: =IF(C17>0,(C17*(1-IF(($B$7+$B$8)<1,0,_xlfn.POISSON.DIST(($B$7+$B$8)-1,C17,TRUE)))-($B$7+$B$8)*(1-_xlfn.POISSON.DIST(($B$7+$B$8),C17,TRUE))),0) | F17: =IF(B17>=$B$6,1,1-(D17-E17)/$B$8) | G17: =F17-F16 | H17: =(B16+B17)/2 | I17: =1-F17
A18: 4 | B18: =A18/7 | C18: =IF(B18<$B$6,$B$5*($B$6-B18),0) | D18: =IF(C18>0,(C18*(1-IF($B$7<1,0,_xlfn.POISSON.DIST($B$7-1,C18,TRUE)))-$B$7*(1-_xlfn.POISSON.DIST($B$7,C18,TRUE))),0) | E18: =IF(C18>0,(C18*(1-IF(($B$7+$B$8)<1,0,_xlfn.POISSON.DIST(($B$7+$B$8)-1,C18,TRUE)))-($B$7+$B$8)*(1-_xlfn.POISSON.DIST(($B$7+$B$8),C18,TRUE))),0) | F18: =IF(B18>=$B$6,1,1-(D18-E18)/$B$8) | G18: =F18-F17 | H18: =(B17+B18)/2 | I18: =1-F18
A19: 5 | B19: =A19/7 | C19: =IF(B19<$B$6,$B$5*($B$6-B19),0) | D19: =IF(C19>0,(C19*(1-IF($B$7<1,0,_xlfn.POISSON.DIST($B$7-1,C19,TRUE)))-$B$7*(1-_xlfn.POISSON.DIST($B$7,C19,TRUE))),0) | E19: =IF(C19>0,(C19*(1-IF(($B$7+$B$8)<1,0,_xlfn.POISSON.DIST(($B$7+$B$8)-1,C19,TRUE)))-($B$7+$B$8)*(1-_xlfn.POISSON.DIST(($B$7+$B$8),C19,TRUE))),0) | F19: =IF(B19>=$B$6,1,1-(D19-E19)/$B$8) | G19: =F19-F18 | H19: =(B18+B19)/2 | I19: =1-F19
A20: 6 | B20: =A20/7 | C20: =IF(B20<$B$6,$B$5*($B$6-B20),0) | D20: =IF(C20>0,(C20*(1-IF($B$7<1,0,_xlfn.POISSON.DIST($B$7-1,C20,TRUE)))-$B$7*(1-_xlfn.POISSON.DIST($B$7,C20,TRUE))),0) | E20: =IF(C20>0,(C20*(1-IF(($B$7+$B$8)<1,0,_xlfn.POISSON.DIST(($B$7+$B$8)-1,C20,TRUE)))-($B$7+$B$8)*(1-_xlfn.POISSON.DIST(($B$7+$B$8),C20,TRUE))),0) | F20: =IF(B20>=$B$6,1,1-(D20-E20)/$B$8) | G20: =F20-F19 | H20: =(B19+B20)/2 | I20: =1-F20
A21: 7 | B21: =A21/7 | C21: =IF(B21<$B$6,$B$5*($B$6-B21),0) | D21: =IF(C21>0,(C21*(1-IF($B$7<1,0,_xlfn.POISSON.DIST($B$7-1,C21,TRUE)))-$B$7*(1-_xlfn.POISSON.DIST($B$7,C21,TRUE))),0) | E21: =IF(C21>0,(C21*(1-IF(($B$7+$B$8)<1,0,_xlfn.POISSON.DIST(($B$7+$B$8)-1,C21,TRUE)))-($B$7+$B$8)*(1-_xlfn.POISSON.DIST(($B$7+$B$8),C21,TRUE))),0) | F21: =IF(B21>=$B$6,1,1-(D21-E21)/$B$8) | G21: =F21-F20 | H21: =(B20+B21)/2 | I21: =1-F21
A22: 8 | B22: =A22/7 | C22: =IF(B22<$B$6,$B$5*($B$6-B22),0) | D22: =IF(C22>0,(C22*(1-IF($B$7<1,0,_xlfn.POISSON.DIST($B$7-1,C22,TRUE)))-$B$7*(1-_xlfn.POISSON.DIST($B$7,C22,TRUE))),0) | E22: =IF(C22>0,(C22*(1-IF(($B$7+$B$8)<1,0,_xlfn.POISSON.DIST(($B$7+$B$8)-1,C22,TRUE)))-($B$7+$B$8)*(1-_xlfn.POISSON.DIST(($B$7+$B$8),C22,TRUE))),0) | F22: =IF(B22>=$B$6,1,1-(D22-E22)/$B$8) | G22: =F22-F21 | H22: =(B21+B22)/2 | I22: =1-F22
A23: 9 | B23: =A23/7 | C23: =IF(B23<$B$6,$B$5*($B$6-B23),0) | D23: =IF(C23>0,(C23*(1-IF($B$7<1,0,_xlfn.POISSON.DIST($B$7-1,C23,TRUE)))-$B$7*(1-_xlfn.POISSON.DIST($B$7,C23,TRUE))),0) | E23: =IF(C23>0,(C23*(1-IF(($B$7+$B$8)<1,0,_xlfn.POISSON.DIST(($B$7+$B$8)-1,C23,TRUE)))-($B$7+$B$8)*(1-_xlfn.POISSON.DIST(($B$7+$B$8),C23,TRUE))),0) | F23: =IF(B23>=$B$6,1,1-(D23-E23)/$B$8) | G23: =F23-F22 | H23: =(B22+B23)/2 | I23: =1-F23
A24: 10 | B24: =A24/7 | C24: =IF(B24<$B$6,$B$5*($B$6-B24),0) | D24: =IF(C24>0,(C24*(1-IF($B$7<1,0,_xlfn.POISSON.DIST($B$7-1,C24,TRUE)))-$B$7*(1-_xlfn.POISSON.DIST($B$7,C24,TRUE))),0) | E24: =IF(C24>0,(C24*(1-IF(($B$7+$B$8)<1,0,_xlfn.POISSON.DIST(($B$7+$B$8)-1,C24,TRUE)))-($B$7+$B$8)*(1-_xlfn.POISSON.DIST(($B$7+$B$8),C24,TRUE))),0) | F24: =IF(B24>=$B$6,1,1-(D24-E24)/$B$8) | G24: =F24-F23 | H24: =(B23+B24)/2 | I24: =1-F24
A25: 11 | B25: =A25/7 | C25: =IF(B25<$B$6,$B$5*($B$6-B25),0) | D25: =IF(C25>0,(C25*(1-IF($B$7<1,0,_xlfn.POISSON.DIST($B$7-1,C25,TRUE)))-$B$7*(1-_xlfn.POISSON.DIST($B$7,C25,TRUE))),0) | E25: =IF(C25>0,(C25*(1-IF(($B$7+$B$8)<1,0,_xlfn.POISSON.DIST(($B$7+$B$8)-1,C25,TRUE)))-($B$7+$B$8)*(1-_xlfn.POISSON.DIST(($B$7+$B$8),C25,TRUE))),0) | F25: =IF(B25>=$B$6,1,1-(D25-E25)/$B$8) | G25: =F25-F24 | H25: =(B24+B25)/2 | I25: =1-F25
A26: 12 | B26: =A26/7 | C26: =IF(B26<$B$6,$B$5*($B$6-B26),0) | D26: =IF(C26>0,(C26*(1-IF($B$7<1,0,_xlfn.POISSON.DIST($B$7-1,C26,TRUE)))-$B$7*(1-_xlfn.POISSON.DIST($B$7,C26,TRUE))),0) | E26: =IF(C26>0,(C26*(1-IF(($B$7+$B$8)<1,0,_xlfn.POISSON.DIST(($B$7+$B$8)-1,C26,TRUE)))-($B$7+$B$8)*(1-_xlfn.POISSON.DIST(($B$7+$B$8),C26,TRUE))),0) | F26: =IF(B26>=$B$6,1,1-(D26-E26)/$B$8) | G26: =F26-F25 | H26: =(B25+B26)/2 | I26: =1-F26
... A35: 21 | B35: =A35/7 | C35: =IF(B35<$B$6,$B$5*($B$6-B35),0) | D35: =IF(C35>0,(C35*(1-IF($B$7<1,0,_xlfn.POISSON.DIST($B$7-1,C35,TRUE)))-$B$7*(1-_xlfn.POISSON.DIST($B$7,C35,TRUE))),0) | E35: =IF(C35>0,(C35*(1-IF(($B$7+$B$8)<1,0,_xlfn.POISSON.DIST(($B$7+$B$8)-1,C35,TRUE)))-($B$7+$B$8)*(1-_xlfn.POISSON.DIST(($B$7+$B$8),C35,TRUE))),0) | F35: =IF(B35>=$B$6,1,1-(D35-E35)/$B$8) | G35: =F35-F34 | H35: =(B34+B35)/2 | I35: =1-F35
A37: integral of P(W > w) | B37: =((I14+I15)/2+(I15+I16)/2+(I16+I17)/2+(I17+I18)/2+(I18+I19)/2+(I19+I20)/2+(I20+I21)/2+(I21+I22)/2+(I22+I23)/2+(I23+I24)/2+(I24+I25)/2+(I25+I26)/2+(I26+I27)/2+(I27+I28)/2+(I28+I29)/2+(I29+I30)/2+(I30+I31)/2+(I31+I32)/2+(I32+I33)/2+(I33+I34)/2+(I34+I35)/2)/7 | C37: trapezoids, a day wide
A38: Little's law, B_0/lambda_0 | B38: =Hub!B27
A39: difference | B39: =B37-B38
A40: The midpoint column places each day's probability in the middle of the day. At the end of the day it would overstate the mean wait by half a day.

Sheet Exact
A1: Exact costs, Axsater's recursion
A2: @sec-batchedmultiechelon. One-for-one costs C(S_0, S_j) by Axsater (1993), equations (A.1) to (A.13), averaged over the hub's positions by his equation (1).
A4: Read from the Hub sheet
A5: lambda_j | B5: =Hub!B5
A6: lambda_0 | B6: =Hub!B12
A7: L_0 | B7: =Hub!B7
A8: O_j | B8: =Hub!B8
A9: N | B9: =Hub!B6
A10: r_0 | B10: =Hub!B18
A11: Q_0 | B11: =Hub!B19
A12: storeroom stock S_j | B12: 3 | C12: units
A14: Two sets of cost rates, per week
B15: costs | C15: backorders only
A16: h_j | B16: =Hub!B14 | C16: 0
A17: h_0 | B17: =Hub!B14 | C17: 0
A18: beta | B18: =Hub!B15 | C18: 1
A19: Every term is linear in the three rates, so the right-hand column prices only the storerooms' backorders and returns their expected number.
A21: Equation (1): the cost at each S_j, averaged over S_0 = r_0+1 .. r_0+Q_0
A22: S_j | B22: 0 | C22: 1 | D22: 2 | E22: 3 | F22: 4 | G22: 5 | H22: 6
A23: cost per week | B23: =$B$6*(SUM(INDEX(F33:F83,51-($B$10+$B$11)):INDEX(F33:F83,51-($B$10+1)))+SUM(INDEX(E33:E83,51-($B$10+$B$11)):INDEX(E33:E83,51-($B$10+1))))/$B$11 | C23: =$B$6*(SUM(INDEX(G33:G83,51-($B$10+$B$11)):INDEX(G33:G83,51-($B$10+1)))+SUM(INDEX(E33:E83,51-($B$10+$B$11)):INDEX(E33:E83,51-($B$10+1))))/$B$11 | D23: =$B$6*(SUM(INDEX(H33:H83,51-($B$10+$B$11)):INDEX(H33:H83,51-($B$10+1)))+SUM(INDEX(E33:E83,51-($B$10+$B$11)):INDEX(E33:E83,51-($B$10+1))))/$B$11 | E23: =$B$6*(SUM(INDEX(I33:I83,51-($B$10+$B$11)):INDEX(I33:I83,51-($B$10+1)))+SUM(INDEX(E33:E83,51-($B$10+$B$11)):INDEX(E33:E83,51-($B$10+1))))/$B$11 | F23: =$B$6*(SUM(INDEX(J33:J83,51-($B$10+$B$11)):INDEX(J33:J83,51-($B$10+1)))+SUM(INDEX(E33:E83,51-($B$10+$B$11)):INDEX(E33:E83,51-($B$10+1))))/$B$11 | G23: =$B$6*(SUM(INDEX(K33:K83,51-($B$10+$B$11)):INDEX(K33:K83,51-($B$10+1)))+SUM(INDEX(E33:E83,51-($B$10+$B$11)):INDEX(E33:E83,51-($B$10+1))))/$B$11 | H23: =$B$6*(SUM(INDEX(L33:L83,51-($B$10+$B$11)):INDEX(L33:L83,51-($B$10+1)))+SUM(INDEX(E33:E83,51-($B$10+$B$11)):INDEX(E33:E83,51-($B$10+1))))/$B$11
A24: storeroom backorders | B24: =$B$6*(SUM(INDEX(O33:O83,51-($B$10+$B$11)):INDEX(O33:O83,51-($B$10+1)))+SUM(INDEX(N33:N83,51-($B$10+$B$11)):INDEX(N33:N83,51-($B$10+1))))/$B$11 | C24: =$B$6*(SUM(INDEX(P33:P83,51-($B$10+$B$11)):INDEX(P33:P83,51-($B$10+1)))+SUM(INDEX(N33:N83,51-($B$10+$B$11)):INDEX(N33:N83,51-($B$10+1))))/$B$11 | D24: =$B$6*(SUM(INDEX(Q33:Q83,51-($B$10+$B$11)):INDEX(Q33:Q83,51-($B$10+1)))+SUM(INDEX(N33:N83,51-($B$10+$B$11)):INDEX(N33:N83,51-($B$10+1))))/$B$11 | E24: =$B$6*(SUM(INDEX(R33:R83,51-($B$10+$B$11)):INDEX(R33:R83,51-($B$10+1)))+SUM(INDEX(N33:N83,51-($B$10+$B$11)):INDEX(N33:N83,51-($B$10+1))))/$B$11 | F24: =$B$6*(SUM(INDEX(S33:S83,51-($B$10+$B$11)):INDEX(S33:S83,51-($B$10+1)))+SUM(INDEX(N33:N83,51-($B$10+$B$11)):INDEX(N33:N83,51-($B$10+1))))/$B$11 | G24: =$B$6*(SUM(INDEX(T33:T83,51-($B$10+$B$11)):INDEX(T33:T83,51-($B$10+1)))+SUM(INDEX(N33:N83,51-($B$10+$B$11)):INDEX(N33:N83,51-($B$10+1))))/$B$11 | H24: =$B$6*(SUM(INDEX(U33:U83,51-($B$10+$B$11)):INDEX(U33:U83,51-($B$10+1)))+SUM(INDEX(N33:N83,51-($B$10+$B$11)):INDEX(N33:N83,51-($B$10+1))))/$B$11
A25: per storeroom | B25: =B24/$B$9 | C25: =C24/$B$9 | D25: =D24/$B$9 | E25: =E24/$B$9 | F25: =F24/$B$9 | G25: =G24/$B$9 | H25: =H24/$B$9
A27: At the storeroom stock above
A28: system cost per week | B28: =INDEX(B23:H23,B12+1)
A29: backorders per storeroom | B29: =INDEX(B25:H25,B12+1)
A31: G^n, the chance of n or more hub demands in L_0, (A.4). | D31: costs | M31: backorders only
A32: n | B32: G^n | D32: S_0 | E32: gamma(S_0) | F32: S_j=0 | G32: S_j=1 | H32: S_j=2 | I32: S_j=3 | J32: S_j=4 | K32: S_j=5 | L32: S_j=6 | M32: S_0 | N32: gamma(S_0) | O32: S_j=0 | P32: S_j=1 | Q32: S_j=2 | R32: S_j=3 | S32: S_j=4 | T32: S_j=5 | U32: S_j=6
A33: 0 | B33: 1 | D33: 50 | E33: =$B$17*50/$B$6*(1-INDEX(HubTail,52))-$B$17*$B$7*(1-INDEX(HubTail,51)) | F33: =INDEX(HubTail,51)*$B$18*$B$7-INDEX(HubTail,52)*$B$18*50/$B$6+$B$18*$B$8 | G33: =G85 | H33: =H85 | I33: =I85 | J33: =J85 | K33: =K85 | L33: =L85 | M33: 50 | N33: =$C$17*50/$B$6*(1-INDEX(HubTail,52))-$C$17*$B$7*(1-INDEX(HubTail,51)) | O33: =INDEX(HubTail,51)*$C$18*$B$7-INDEX(HubTail,52)*$C$18*50/$B$6+$C$18*$B$8 | P33: =P85 | Q33: =Q85 | R33: =R85 | S33: =S85 | T33: =T85 | U33: =U85
A34: 1 | B34: =1-_xlfn.POISSON.DIST(0,$B$6*$B$7,TRUE) | D34: 49 | E34: =$B$17*49/$B$6*(1-INDEX(HubTail,51))-$B$17*$B$7*(1-INDEX(HubTail,50)) | F34: =INDEX(HubTail,50)*$B$18*$B$7-INDEX(HubTail,51)*$B$18*49/$B$6+$B$18*$B$8 | G34: =$B$5/$B$6*F33+(1-$B$5/$B$6)*G33+$B$5/$B$6*(1-INDEX(HubTail,51))*($G$85-$F$85) | H34: =$B$5/$B$6*G33+(1-$B$5/$B$6)*H33+$B$5/$B$6*(1-INDEX(HubTail,51))*($H$85-$G$85) | I34: =$B$5/$B$6*H33+(1-$B$5/$B$6)*I33+$B$5/$B$6*(1-INDEX(HubTail,51))*($I$85-$H$85) | J34: =$B$5/$B$6*I33+(1-$B$5/$B$6)*J33+$B$5/$B$6*(1-INDEX(HubTail,51))*($J$85-$I$85) | K34: =$B$5/$B$6*J33+(1-$B$5/$B$6)*K33+$B$5/$B$6*(1-INDEX(HubTail,51))*($K$85-$J$85) | L34: =$B$5/$B$6*K33+(1-$B$5/$B$6)*L33+$B$5/$B$6*(1-INDEX(HubTail,51))*($L$85-$K$85) | M34: 49 | N34: =$C$17*49/$B$6*(1-INDEX(HubTail,51))-$C$17*$B$7*(1-INDEX(HubTail,50)) | O34: =INDEX(HubTail,50)*$C$18*$B$7-INDEX(HubTail,51)*$C$18*49/$B$6+$C$18*$B$8 | P34: =$B$5/$B$6*O33+(1-$B$5/$B$6)*P33+$B$5/$B$6*(1-INDEX(HubTail,51))*($P$85-$O$85) | Q34: =$B$5/$B$6*P33+(1-$B$5/$B$6)*Q33+$B$5/$B$6*(1-INDEX(HubTail,51))*($Q$85-$P$85) | R34: =$B$5/$B$6*Q33+(1-$B$5/$B$6)*R33+$B$5/$B$6*(1-INDEX(HubTail,51))*($R$85-$Q$85) | S34: =$B$5/$B$6*R33+(1-$B$5/$B$6)*S33+$B$5/$B$6*(1-INDEX(HubTail,51))*($S$85-$R$85) | T34: =$B$5/$B$6*S33+(1-$B$5/$B$6)*T33+$B$5/$B$6*(1-INDEX(HubTail,51))*($T$85-$S$85) | U34: =$B$5/$B$6*T33+(1-$B$5/$B$6)*U33+$B$5/$B$6*(1-INDEX(HubTail,51))*($U$85-$T$85)
A35: 2 | B35: =1-_xlfn.POISSON.DIST(1,$B$6*$B$7,TRUE) | D35: 48 | E35: =$B$17*48/$B$6*(1-INDEX(HubTail,50))-$B$17*$B$7*(1-INDEX(HubTail,49)) | F35: =INDEX(HubTail,49)*$B$18*$B$7-INDEX(HubTail,50)*$B$18*48/$B$6+$B$18*$B$8 | G35: =$B$5/$B$6*F34+(1-$B$5/$B$6)*G34+$B$5/$B$6*(1-INDEX(HubTail,50))*($G$85-$F$85) | H35: =$B$5/$B$6*G34+(1-$B$5/$B$6)*H34+$B$5/$B$6*(1-INDEX(HubTail,50))*($H$85-$G$85) | I35: =$B$5/$B$6*H34+(1-$B$5/$B$6)*I34+$B$5/$B$6*(1-INDEX(HubTail,50))*($I$85-$H$85) | J35: =$B$5/$B$6*I34+(1-$B$5/$B$6)*J34+$B$5/$B$6*(1-INDEX(HubTail,50))*($J$85-$I$85) | K35: =$B$5/$B$6*J34+(1-$B$5/$B$6)*K34+$B$5/$B$6*(1-INDEX(HubTail,50))*($K$85-$J$85) | L35: =$B$5/$B$6*K34+(1-$B$5/$B$6)*L34+$B$5/$B$6*(1-INDEX(HubTail,50))*($L$85-$K$85) | M35: 48 | N35: =$C$17*48/$B$6*(1-INDEX(HubTail,50))-$C$17*$B$7*(1-INDEX(HubTail,49)) | O35: =INDEX(HubTail,49)*$C$18*$B$7-INDEX(HubTail,50)*$C$18*48/$B$6+$C$18*$B$8 | P35: =$B$5/$B$6*O34+(1-$B$5/$B$6)*P34+$B$5/$B$6*(1-INDEX(HubTail,50))*($P$85-$O$85) | Q35: =$B$5/$B$6*P34+(1-$B$5/$B$6)*Q34+$B$5/$B$6*(1-INDEX(HubTail,50))*($Q$85-$P$85) | R35: =$B$5/$B$6*Q34+(1-$B$5/$B$6)*R34+$B$5/$B$6*(1-INDEX(HubTail,50))*($R$85-$Q$85) | S35: =$B$5/$B$6*R34+(1-$B$5/$B$6)*S34+$B$5/$B$6*(1-INDEX(HubTail,50))*($S$85-$R$85) | T35: =$B$5/$B$6*S34+(1-$B$5/$B$6)*T34+$B$5/$B$6*(1-INDEX(HubTail,50))*($T$85-$S$85) | U35: =$B$5/$B$6*T34+(1-$B$5/$B$6)*U34+$B$5/$B$6*(1-INDEX(HubTail,50))*($U$85-$T$85)
A36: 3 | B36: =1-_xlfn.POISSON.DIST(2,$B$6*$B$7,TRUE) | D36: 47 | E36: =$B$17*47/$B$6*(1-INDEX(HubTail,49))-$B$17*$B$7*(1-INDEX(HubTail,48)) | F36: =INDEX(HubTail,48)*$B$18*$B$7-INDEX(HubTail,49)*$B$18*47/$B$6+$B$18*$B$8 | G36: =$B$5/$B$6*F35+(1-$B$5/$B$6)*G35+$B$5/$B$6*(1-INDEX(HubTail,49))*($G$85-$F$85) | H36: =$B$5/$B$6*G35+(1-$B$5/$B$6)*H35+$B$5/$B$6*(1-INDEX(HubTail,49))*($H$85-$G$85) | I36: =$B$5/$B$6*H35+(1-$B$5/$B$6)*I35+$B$5/$B$6*(1-INDEX(HubTail,49))*($I$85-$H$85) | J36: =$B$5/$B$6*I35+(1-$B$5/$B$6)*J35+$B$5/$B$6*(1-INDEX(HubTail,49))*($J$85-$I$85) | K36: =$B$5/$B$6*J35+(1-$B$5/$B$6)*K35+$B$5/$B$6*(1-INDEX(HubTail,49))*($K$85-$J$85) | L36: =$B$5/$B$6*K35+(1-$B$5/$B$6)*L35+$B$5/$B$6*(1-INDEX(HubTail,49))*($L$85-$K$85) | M36: 47 | N36: =$C$17*47/$B$6*(1-INDEX(HubTail,49))-$C$17*$B$7*(1-INDEX(HubTail,48)) | O36: =INDEX(HubTail,48)*$C$18*$B$7-INDEX(HubTail,49)*$C$18*47/$B$6+$C$18*$B$8 | P36: =$B$5/$B$6*O35+(1-$B$5/$B$6)*P35+$B$5/$B$6*(1-INDEX(HubTail,49))*($P$85-$O$85) | Q36: =$B$5/$B$6*P35+(1-$B$5/$B$6)*Q35+$B$5/$B$6*(1-INDEX(HubTail,49))*($Q$85-$P$85) | R36: =$B$5/$B$6*Q35+(1-$B$5/$B$6)*R35+$B$5/$B$6*(1-INDEX(HubTail,49))*($R$85-$Q$85) | S36: =$B$5/$B$6*R35+(1-$B$5/$B$6)*S35+$B$5/$B$6*(1-INDEX(HubTail,49))*($S$85-$R$85) | T36: =$B$5/$B$6*S35+(1-$B$5/$B$6)*T35+$B$5/$B$6*(1-INDEX(HubTail,49))*($T$85-$S$85) | U36: =$B$5/$B$6*T35+(1-$B$5/$B$6)*U35+$B$5/$B$6*(1-INDEX(HubTail,49))*($U$85-$T$85)
A37: 4 | B37: =1-_xlfn.POISSON.DIST(3,$B$6*$B$7,TRUE) | D37: 46 | E37: =$B$17*46/$B$6*(1-INDEX(HubTail,48))-$B$17*$B$7*(1-INDEX(HubTail,47)) | F37: =INDEX(HubTail,47)*$B$18*$B$7-INDEX(HubTail,48)*$B$18*46/$B$6+$B$18*$B$8 | G37: =$B$5/$B$6*F36+(1-$B$5/$B$6)*G36+$B$5/$B$6*(1-INDEX(HubTail,48))*($G$85-$F$85) | H37: =$B$5/$B$6*G36+(1-$B$5/$B$6)*H36+$B$5/$B$6*(1-INDEX(HubTail,48))*($H$85-$G$85) | I37: =$B$5/$B$6*H36+(1-$B$5/$B$6)*I36+$B$5/$B$6*(1-INDEX(HubTail,48))*($I$85-$H$85) | J37: =$B$5/$B$6*I36+(1-$B$5/$B$6)*J36+$B$5/$B$6*(1-INDEX(HubTail,48))*($J$85-$I$85) | K37: =$B$5/$B$6*J36+(1-$B$5/$B$6)*K36+$B$5/$B$6*(1-INDEX(HubTail,48))*($K$85-$J$85) | L37: =$B$5/$B$6*K36+(1-$B$5/$B$6)*L36+$B$5/$B$6*(1-INDEX(HubTail,48))*($L$85-$K$85) | M37: 46 | N37: =$C$17*46/$B$6*(1-INDEX(HubTail,48))-$C$17*$B$7*(1-INDEX(HubTail,47)) | O37: =INDEX(HubTail,47)*$C$18*$B$7-INDEX(HubTail,48)*$C$18*46/$B$6+$C$18*$B$8 | P37: =$B$5/$B$6*O36+(1-$B$5/$B$6)*P36+$B$5/$B$6*(1-INDEX(HubTail,48))*($P$85-$O$85) | Q37: =$B$5/$B$6*P36+(1-$B$5/$B$6)*Q36+$B$5/$B$6*(1-INDEX(HubTail,48))*($Q$85-$P$85) | R37: =$B$5/$B$6*Q36+(1-$B$5/$B$6)*R36+$B$5/$B$6*(1-INDEX(HubTail,48))*($R$85-$Q$85) | S37: =$B$5/$B$6*R36+(1-$B$5/$B$6)*S36+$B$5/$B$6*(1-INDEX(HubTail,48))*($S$85-$R$85) | T37: =$B$5/$B$6*S36+(1-$B$5/$B$6)*T36+$B$5/$B$6*(1-INDEX(HubTail,48))*($T$85-$S$85) | U37: =$B$5/$B$6*T36+(1-$B$5/$B$6)*U36+$B$5/$B$6*(1-INDEX(HubTail,48))*($U$85-$T$85)
A38: 5 | B38: =1-_xlfn.POISSON.DIST(4,$B$6*$B$7,TRUE) | D38: 45 | E38: =$B$17*45/$B$6*(1-INDEX(HubTail,47))-$B$17*$B$7*(1-INDEX(HubTail,46)) | F38: =INDEX(HubTail,46)*$B$18*$B$7-INDEX(HubTail,47)*$B$18*45/$B$6+$B$18*$B$8 | G38: =$B$5/$B$6*F37+(1-$B$5/$B$6)*G37+$B$5/$B$6*(1-INDEX(HubTail,47))*($G$85-$F$85) | H38: =$B$5/$B$6*G37+(1-$B$5/$B$6)*H37+$B$5/$B$6*(1-INDEX(HubTail,47))*($H$85-$G$85) | I38: =$B$5/$B$6*H37+(1-$B$5/$B$6)*I37+$B$5/$B$6*(1-INDEX(HubTail,47))*($I$85-$H$85) | J38: =$B$5/$B$6*I37+(1-$B$5/$B$6)*J37+$B$5/$B$6*(1-INDEX(HubTail,47))*($J$85-$I$85) | K38: =$B$5/$B$6*J37+(1-$B$5/$B$6)*K37+$B$5/$B$6*(1-INDEX(HubTail,47))*($K$85-$J$85) | L38: =$B$5/$B$6*K37+(1-$B$5/$B$6)*L37+$B$5/$B$6*(1-INDEX(HubTail,47))*($L$85-$K$85) | M38: 45 | N38: =$C$17*45/$B$6*(1-INDEX(HubTail,47))-$C$17*$B$7*(1-INDEX(HubTail,46)) | O38: =INDEX(HubTail,46)*$C$18*$B$7-INDEX(HubTail,47)*$C$18*45/$B$6+$C$18*$B$8 | P38: =$B$5/$B$6*O37+(1-$B$5/$B$6)*P37+$B$5/$B$6*(1-INDEX(HubTail,47))*($P$85-$O$85) | Q38: =$B$5/$B$6*P37+(1-$B$5/$B$6)*Q37+$B$5/$B$6*(1-INDEX(HubTail,47))*($Q$85-$P$85) | R38: =$B$5/$B$6*Q37+(1-$B$5/$B$6)*R37+$B$5/$B$6*(1-INDEX(HubTail,47))*($R$85-$Q$85) | S38: =$B$5/$B$6*R37+(1-$B$5/$B$6)*S37+$B$5/$B$6*(1-INDEX(HubTail,47))*($S$85-$R$85) | T38: =$B$5/$B$6*S37+(1-$B$5/$B$6)*T37+$B$5/$B$6*(1-INDEX(HubTail,47))*($T$85-$S$85) | U38: =$B$5/$B$6*T37+(1-$B$5/$B$6)*U37+$B$5/$B$6*(1-INDEX(HubTail,47))*($U$85-$T$85)
A39: 6 | B39: =1-_xlfn.POISSON.DIST(5,$B$6*$B$7,TRUE) | D39: 44 | E39: =$B$17*44/$B$6*(1-INDEX(HubTail,46))-$B$17*$B$7*(1-INDEX(HubTail,45)) | F39: =INDEX(HubTail,45)*$B$18*$B$7-INDEX(HubTail,46)*$B$18*44/$B$6+$B$18*$B$8 | G39: =$B$5/$B$6*F38+(1-$B$5/$B$6)*G38+$B$5/$B$6*(1-INDEX(HubTail,46))*($G$85-$F$85) | H39: =$B$5/$B$6*G38+(1-$B$5/$B$6)*H38+$B$5/$B$6*(1-INDEX(HubTail,46))*($H$85-$G$85) | I39: =$B$5/$B$6*H38+(1-$B$5/$B$6)*I38+$B$5/$B$6*(1-INDEX(HubTail,46))*($I$85-$H$85) | J39: =$B$5/$B$6*I38+(1-$B$5/$B$6)*J38+$B$5/$B$6*(1-INDEX(HubTail,46))*($J$85-$I$85) | K39: =$B$5/$B$6*J38+(1-$B$5/$B$6)*K38+$B$5/$B$6*(1-INDEX(HubTail,46))*($K$85-$J$85) | L39: =$B$5/$B$6*K38+(1-$B$5/$B$6)*L38+$B$5/$B$6*(1-INDEX(HubTail,46))*($L$85-$K$85) | M39: 44 | N39: =$C$17*44/$B$6*(1-INDEX(HubTail,46))-$C$17*$B$7*(1-INDEX(HubTail,45)) | O39: =INDEX(HubTail,45)*$C$18*$B$7-INDEX(HubTail,46)*$C$18*44/$B$6+$C$18*$B$8 | P39: =$B$5/$B$6*O38+(1-$B$5/$B$6)*P38+$B$5/$B$6*(1-INDEX(HubTail,46))*($P$85-$O$85) | Q39: =$B$5/$B$6*P38+(1-$B$5/$B$6)*Q38+$B$5/$B$6*(1-INDEX(HubTail,46))*($Q$85-$P$85) | R39: =$B$5/$B$6*Q38+(1-$B$5/$B$6)*R38+$B$5/$B$6*(1-INDEX(HubTail,46))*($R$85-$Q$85) | S39: =$B$5/$B$6*R38+(1-$B$5/$B$6)*S38+$B$5/$B$6*(1-INDEX(HubTail,46))*($S$85-$R$85) | T39: =$B$5/$B$6*S38+(1-$B$5/$B$6)*T38+$B$5/$B$6*(1-INDEX(HubTail,46))*($T$85-$S$85) | U39: =$B$5/$B$6*T38+(1-$B$5/$B$6)*U38+$B$5/$B$6*(1-INDEX(HubTail,46))*($U$85-$T$85)
A40: 7 | B40: =1-_xlfn.POISSON.DIST(6,$B$6*$B$7,TRUE) | D40: 43 | E40: =$B$17*43/$B$6*(1-INDEX(HubTail,45))-$B$17*$B$7*(1-INDEX(HubTail,44)) | F40: =INDEX(HubTail,44)*$B$18*$B$7-INDEX(HubTail,45)*$B$18*43/$B$6+$B$18*$B$8 | G40: =$B$5/$B$6*F39+(1-$B$5/$B$6)*G39+$B$5/$B$6*(1-INDEX(HubTail,45))*($G$85-$F$85) | H40: =$B$5/$B$6*G39+(1-$B$5/$B$6)*H39+$B$5/$B$6*(1-INDEX(HubTail,45))*($H$85-$G$85) | I40: =$B$5/$B$6*H39+(1-$B$5/$B$6)*I39+$B$5/$B$6*(1-INDEX(HubTail,45))*($I$85-$H$85) | J40: =$B$5/$B$6*I39+(1-$B$5/$B$6)*J39+$B$5/$B$6*(1-INDEX(HubTail,45))*($J$85-$I$85) | K40: =$B$5/$B$6*J39+(1-$B$5/$B$6)*K39+$B$5/$B$6*(1-INDEX(HubTail,45))*($K$85-$J$85) | L40: =$B$5/$B$6*K39+(1-$B$5/$B$6)*L39+$B$5/$B$6*(1-INDEX(HubTail,45))*($L$85-$K$85) | M40: 43 | N40: =$C$17*43/$B$6*(1-INDEX(HubTail,45))-$C$17*$B$7*(1-INDEX(HubTail,44)) | O40: =INDEX(HubTail,44)*$C$18*$B$7-INDEX(HubTail,45)*$C$18*43/$B$6+$C$18*$B$8 | P40: =$B$5/$B$6*O39+(1-$B$5/$B$6)*P39+$B$5/$B$6*(1-INDEX(HubTail,45))*($P$85-$O$85) | Q40: =$B$5/$B$6*P39+(1-$B$5/$B$6)*Q39+$B$5/$B$6*(1-INDEX(HubTail,45))*($Q$85-$P$85) | R40: =$B$5/$B$6*Q39+(1-$B$5/$B$6)*R39+$B$5/$B$6*(1-INDEX(HubTail,45))*($R$85-$Q$85) | S40: =$B$5/$B$6*R39+(1-$B$5/$B$6)*S39+$B$5/$B$6*(1-INDEX(HubTail,45))*($S$85-$R$85) | T40: =$B$5/$B$6*S39+(1-$B$5/$B$6)*T39+$B$5/$B$6*(1-INDEX(HubTail,45))*($T$85-$S$85) | U40: =$B$5/$B$6*T39+(1-$B$5/$B$6)*U39+$B$5/$B$6*(1-INDEX(HubTail,45))*($U$85-$T$85)
A41: 8 | B41: =1-_xlfn.POISSON.DIST(7,$B$6*$B$7,TRUE) | D41: 42 | E41: =$B$17*42/$B$6*(1-INDEX(HubTail,44))-$B$17*$B$7*(1-INDEX(HubTail,43)) | F41: =INDEX(HubTail,43)*$B$18*$B$7-INDEX(HubTail,44)*$B$18*42/$B$6+$B$18*$B$8 | G41: =$B$5/$B$6*F40+(1-$B$5/$B$6)*G40+$B$5/$B$6*(1-INDEX(HubTail,44))*($G$85-$F$85) | H41: =$B$5/$B$6*G40+(1-$B$5/$B$6)*H40+$B$5/$B$6*(1-INDEX(HubTail,44))*($H$85-$G$85) | I41: =$B$5/$B$6*H40+(1-$B$5/$B$6)*I40+$B$5/$B$6*(1-INDEX(HubTail,44))*($I$85-$H$85) | J41: =$B$5/$B$6*I40+(1-$B$5/$B$6)*J40+$B$5/$B$6*(1-INDEX(HubTail,44))*($J$85-$I$85) | K41: =$B$5/$B$6*J40+(1-$B$5/$B$6)*K40+$B$5/$B$6*(1-INDEX(HubTail,44))*($K$85-$J$85) | L41: =$B$5/$B$6*K40+(1-$B$5/$B$6)*L40+$B$5/$B$6*(1-INDEX(HubTail,44))*($L$85-$K$85) | M41: 42 | N41: =$C$17*42/$B$6*(1-INDEX(HubTail,44))-$C$17*$B$7*(1-INDEX(HubTail,43)) | O41: =INDEX(HubTail,43)*$C$18*$B$7-INDEX(HubTail,44)*$C$18*42/$B$6+$C$18*$B$8 | P41: =$B$5/$B$6*O40+(1-$B$5/$B$6)*P40+$B$5/$B$6*(1-INDEX(HubTail,44))*($P$85-$O$85) | Q41: =$B$5/$B$6*P40+(1-$B$5/$B$6)*Q40+$B$5/$B$6*(1-INDEX(HubTail,44))*($Q$85-$P$85) | R41: =$B$5/$B$6*Q40+(1-$B$5/$B$6)*R40+$B$5/$B$6*(1-INDEX(HubTail,44))*($R$85-$Q$85) | S41: =$B$5/$B$6*R40+(1-$B$5/$B$6)*S40+$B$5/$B$6*(1-INDEX(HubTail,44))*($S$85-$R$85) | T41: =$B$5/$B$6*S40+(1-$B$5/$B$6)*T40+$B$5/$B$6*(1-INDEX(HubTail,44))*($T$85-$S$85) | U41: =$B$5/$B$6*T40+(1-$B$5/$B$6)*U40+$B$5/$B$6*(1-INDEX(HubTail,44))*($U$85-$T$85)
A42: 9 | B42: =1-_xlfn.POISSON.DIST(8,$B$6*$B$7,TRUE) | D42: 41 | E42: =$B$17*41/$B$6*(1-INDEX(HubTail,43))-$B$17*$B$7*(1-INDEX(HubTail,42)) | F42: =INDEX(HubTail,42)*$B$18*$B$7-INDEX(HubTail,43)*$B$18*41/$B$6+$B$18*$B$8 | G42: =$B$5/$B$6*F41+(1-$B$5/$B$6)*G41+$B$5/$B$6*(1-INDEX(HubTail,43))*($G$85-$F$85) | H42: =$B$5/$B$6*G41+(1-$B$5/$B$6)*H41+$B$5/$B$6*(1-INDEX(HubTail,43))*($H$85-$G$85) | I42: =$B$5/$B$6*H41+(1-$B$5/$B$6)*I41+$B$5/$B$6*(1-INDEX(HubTail,43))*($I$85-$H$85) | J42: =$B$5/$B$6*I41+(1-$B$5/$B$6)*J41+$B$5/$B$6*(1-INDEX(HubTail,43))*($J$85-$I$85) | K42: =$B$5/$B$6*J41+(1-$B$5/$B$6)*K41+$B$5/$B$6*(1-INDEX(HubTail,43))*($K$85-$J$85) | L42: =$B$5/$B$6*K41+(1-$B$5/$B$6)*L41+$B$5/$B$6*(1-INDEX(HubTail,43))*($L$85-$K$85) | M42: 41 | N42: =$C$17*41/$B$6*(1-INDEX(HubTail,43))-$C$17*$B$7*(1-INDEX(HubTail,42)) | O42: =INDEX(HubTail,42)*$C$18*$B$7-INDEX(HubTail,43)*$C$18*41/$B$6+$C$18*$B$8 | P42: =$B$5/$B$6*O41+(1-$B$5/$B$6)*P41+$B$5/$B$6*(1-INDEX(HubTail,43))*($P$85-$O$85) | Q42: =$B$5/$B$6*P41+(1-$B$5/$B$6)*Q41+$B$5/$B$6*(1-INDEX(HubTail,43))*($Q$85-$P$85) | R42: =$B$5/$B$6*Q41+(1-$B$5/$B$6)*R41+$B$5/$B$6*(1-INDEX(HubTail,43))*($R$85-$Q$85) | S42: =$B$5/$B$6*R41+(1-$B$5/$B$6)*S41+$B$5/$B$6*(1-INDEX(HubTail,43))*($S$85-$R$85) | T42: =$B$5/$B$6*S41+(1-$B$5/$B$6)*T41+$B$5/$B$6*(1-INDEX(HubTail,43))*($T$85-$S$85) | U42: =$B$5/$B$6*T41+(1-$B$5/$B$6)*U41+$B$5/$B$6*(1-INDEX(HubTail,43))*($U$85-$T$85)
A43: 10 | B43: =1-_xlfn.POISSON.DIST(9,$B$6*$B$7,TRUE) | D43: 40 | E43: =$B$17*40/$B$6*(1-INDEX(HubTail,42))-$B$17*$B$7*(1-INDEX(HubTail,41)) | F43: =INDEX(HubTail,41)*$B$18*$B$7-INDEX(HubTail,42)*$B$18*40/$B$6+$B$18*$B$8 | G43: =$B$5/$B$6*F42+(1-$B$5/$B$6)*G42+$B$5/$B$6*(1-INDEX(HubTail,42))*($G$85-$F$85) | H43: =$B$5/$B$6*G42+(1-$B$5/$B$6)*H42+$B$5/$B$6*(1-INDEX(HubTail,42))*($H$85-$G$85) | I43: =$B$5/$B$6*H42+(1-$B$5/$B$6)*I42+$B$5/$B$6*(1-INDEX(HubTail,42))*($I$85-$H$85) | J43: =$B$5/$B$6*I42+(1-$B$5/$B$6)*J42+$B$5/$B$6*(1-INDEX(HubTail,42))*($J$85-$I$85) | K43: =$B$5/$B$6*J42+(1-$B$5/$B$6)*K42+$B$5/$B$6*(1-INDEX(HubTail,42))*($K$85-$J$85) | L43: =$B$5/$B$6*K42+(1-$B$5/$B$6)*L42+$B$5/$B$6*(1-INDEX(HubTail,42))*($L$85-$K$85) | M43: 40 | N43: =$C$17*40/$B$6*(1-INDEX(HubTail,42))-$C$17*$B$7*(1-INDEX(HubTail,41)) | O43: =INDEX(HubTail,41)*$C$18*$B$7-INDEX(HubTail,42)*$C$18*40/$B$6+$C$18*$B$8 | P43: =$B$5/$B$6*O42+(1-$B$5/$B$6)*P42+$B$5/$B$6*(1-INDEX(HubTail,42))*($P$85-$O$85) | Q43: =$B$5/$B$6*P42+(1-$B$5/$B$6)*Q42+$B$5/$B$6*(1-INDEX(HubTail,42))*($Q$85-$P$85) | R43: =$B$5/$B$6*Q42+(1-$B$5/$B$6)*R42+$B$5/$B$6*(1-INDEX(HubTail,42))*($R$85-$Q$85) | S43: =$B$5/$B$6*R42+(1-$B$5/$B$6)*S42+$B$5/$B$6*(1-INDEX(HubTail,42))*($S$85-$R$85) | T43: =$B$5/$B$6*S42+(1-$B$5/$B$6)*T42+$B$5/$B$6*(1-INDEX(HubTail,42))*($T$85-$S$85) | U43: =$B$5/$B$6*T42+(1-$B$5/$B$6)*U42+$B$5/$B$6*(1-INDEX(HubTail,42))*($U$85-$T$85)
A44: 11 | B44: =1-_xlfn.POISSON.DIST(10,$B$6*$B$7,TRUE) | D44: 39 | E44: =$B$17*39/$B$6*(1-INDEX(HubTail,41))-$B$17*$B$7*(1-INDEX(HubTail,40)) | F44: =INDEX(HubTail,40)*$B$18*$B$7-INDEX(HubTail,41)*$B$18*39/$B$6+$B$18*$B$8 | G44: =$B$5/$B$6*F43+(1-$B$5/$B$6)*G43+$B$5/$B$6*(1-INDEX(HubTail,41))*($G$85-$F$85) | H44: =$B$5/$B$6*G43+(1-$B$5/$B$6)*H43+$B$5/$B$6*(1-INDEX(HubTail,41))*($H$85-$G$85) | I44: =$B$5/$B$6*H43+(1-$B$5/$B$6)*I43+$B$5/$B$6*(1-INDEX(HubTail,41))*($I$85-$H$85) | J44: =$B$5/$B$6*I43+(1-$B$5/$B$6)*J43+$B$5/$B$6*(1-INDEX(HubTail,41))*($J$85-$I$85) | K44: =$B$5/$B$6*J43+(1-$B$5/$B$6)*K43+$B$5/$B$6*(1-INDEX(HubTail,41))*($K$85-$J$85) | L44: =$B$5/$B$6*K43+(1-$B$5/$B$6)*L43+$B$5/$B$6*(1-INDEX(HubTail,41))*($L$85-$K$85) | M44: 39 | N44: =$C$17*39/$B$6*(1-INDEX(HubTail,41))-$C$17*$B$7*(1-INDEX(HubTail,40)) | O44: =INDEX(HubTail,40)*$C$18*$B$7-INDEX(HubTail,41)*$C$18*39/$B$6+$C$18*$B$8 | P44: =$B$5/$B$6*O43+(1-$B$5/$B$6)*P43+$B$5/$B$6*(1-INDEX(HubTail,41))*($P$85-$O$85) | Q44: =$B$5/$B$6*P43+(1-$B$5/$B$6)*Q43+$B$5/$B$6*(1-INDEX(HubTail,41))*($Q$85-$P$85) | R44: =$B$5/$B$6*Q43+(1-$B$5/$B$6)*R43+$B$5/$B$6*(1-INDEX(HubTail,41))*($R$85-$Q$85) | S44: =$B$5/$B$6*R43+(1-$B$5/$B$6)*S43+$B$5/$B$6*(1-INDEX(HubTail,41))*($S$85-$R$85) | T44: =$B$5/$B$6*S43+(1-$B$5/$B$6)*T43+$B$5/$B$6*(1-INDEX(HubTail,41))*($T$85-$S$85) | U44: =$B$5/$B$6*T43+(1-$B$5/$B$6)*U43+$B$5/$B$6*(1-INDEX(HubTail,41))*($U$85-$T$85)
A45: 12 | B45: =1-_xlfn.POISSON.DIST(11,$B$6*$B$7,TRUE) | D45: 38 | E45: =$B$17*38/$B$6*(1-INDEX(HubTail,40))-$B$17*$B$7*(1-INDEX(HubTail,39)) | F45: =INDEX(HubTail,39)*$B$18*$B$7-INDEX(HubTail,40)*$B$18*38/$B$6+$B$18*$B$8 | G45: =$B$5/$B$6*F44+(1-$B$5/$B$6)*G44+$B$5/$B$6*(1-INDEX(HubTail,40))*($G$85-$F$85) | H45: =$B$5/$B$6*G44+(1-$B$5/$B$6)*H44+$B$5/$B$6*(1-INDEX(HubTail,40))*($H$85-$G$85) | I45: =$B$5/$B$6*H44+(1-$B$5/$B$6)*I44+$B$5/$B$6*(1-INDEX(HubTail,40))*($I$85-$H$85) | J45: =$B$5/$B$6*I44+(1-$B$5/$B$6)*J44+$B$5/$B$6*(1-INDEX(HubTail,40))*($J$85-$I$85) | K45: =$B$5/$B$6*J44+(1-$B$5/$B$6)*K44+$B$5/$B$6*(1-INDEX(HubTail,40))*($K$85-$J$85) | L45: =$B$5/$B$6*K44+(1-$B$5/$B$6)*L44+$B$5/$B$6*(1-INDEX(HubTail,40))*($L$85-$K$85) | M45: 38 | N45: =$C$17*38/$B$6*(1-INDEX(HubTail,40))-$C$17*$B$7*(1-INDEX(HubTail,39)) | O45: =INDEX(HubTail,39)*$C$18*$B$7-INDEX(HubTail,40)*$C$18*38/$B$6+$C$18*$B$8 | P45: =$B$5/$B$6*O44+(1-$B$5/$B$6)*P44+$B$5/$B$6*(1-INDEX(HubTail,40))*($P$85-$O$85) | Q45: =$B$5/$B$6*P44+(1-$B$5/$B$6)*Q44+$B$5/$B$6*(1-INDEX(HubTail,40))*($Q$85-$P$85) | R45: =$B$5/$B$6*Q44+(1-$B$5/$B$6)*R44+$B$5/$B$6*(1-INDEX(HubTail,40))*($R$85-$Q$85) | S45: =$B$5/$B$6*R44+(1-$B$5/$B$6)*S44+$B$5/$B$6*(1-INDEX(HubTail,40))*($S$85-$R$85) | T45: =$B$5/$B$6*S44+(1-$B$5/$B$6)*T44+$B$5/$B$6*(1-INDEX(HubTail,40))*($T$85-$S$85) | U45: =$B$5/$B$6*T44+(1-$B$5/$B$6)*U44+$B$5/$B$6*(1-INDEX(HubTail,40))*($U$85-$T$85)
...

Sheet Storeroom
A1: One storeroom behind the hub, three routes
A2: @sec-batchedmultiechelon. The wait at the hub makes the storeroom's lead time random.
A4: Read from the other sheets
A5: lambda_j | B5: =Hub!B5
A6: O_j | B6: =Hub!B8
A7: mean wait | B7: =Hub!B27
A8: Var[W] | B8: =Hub!B28
A9: S_j | B9: =Exact!B12
A11: The two moment routes' parameters
A12: mean lead time demand | B12: =B5*(B6+B7)
A13: its variance | B13: =B12+B5^2*B8
A14: negative binomial p | B14: =B12/B13
A15: negative binomial r | B15: =B12^2/(B13-B12)
A17: Backorders and on-hand per storeroom
B18: mean only | C18: two moments | D18: conditioned | E18: exact
A19: expected backorders | B19: =SUMPRODUCT(B26:B56,$E$26:$E$56) | C19: =SUMPRODUCT(C26:C56,$E$26:$E$56) | D19: =SUMPRODUCT(D26:D56,$E$26:$E$56) | E19: =Exact!B29
A20: expected on-hand | B20: =$B$9-SUMPRODUCT(B26:B56,$A$26:$A$56)+B19 | C20: =$B$9-SUMPRODUCT(C26:C56,$A$26:$A$56)+C19 | D20: =$B$9-SUMPRODUCT(D26:D56,$A$26:$A$56)+D19 | E20: =B9-B5*(B6+B7)+E19
A21: On-hand less backorders is S_j - lambda_j (O_j + E[W]) in every route with the exact mean wait.
A22: The wait's grid from the Delay sheet, one column per day: probability, then midpoint.
F23: =INDEX(DelayMass,1) | G23: =INDEX(DelayMass,2) | H23: =INDEX(DelayMass,3) | I23: =INDEX(DelayMass,4) | J23: =INDEX(DelayMass,5) | K23: =INDEX(DelayMass,6) | L23: =INDEX(DelayMass,7) | M23: =INDEX(DelayMass,8) | N23: =INDEX(DelayMass,9) | O23: =INDEX(DelayMass,10) | P23: =INDEX(DelayMass,11) | Q23: =INDEX(DelayMass,12) | R23: =INDEX(DelayMass,13) | S23: =INDEX(DelayMass,14) | T23: =INDEX(DelayMass,15) | U23: =INDEX(DelayMass,16) | V23: =INDEX(DelayMass,17) | W23: =INDEX(DelayMass,18) | X23: =INDEX(DelayMass,19) | Y23: =INDEX(DelayMass,20) | Z23: =INDEX(DelayMass,21) | AA23: =INDEX(DelayMass,22)
F24: =INDEX(DelayMid,1) | G24: =INDEX(DelayMid,2) | H24: =INDEX(DelayMid,3) | I24: =INDEX(DelayMid,4) | J24: =INDEX(DelayMid,5) | K24: =INDEX(DelayMid,6) | L24: =INDEX(DelayMid,7) | M24: =INDEX(DelayMid,8) | N24: =INDEX(DelayMid,9) | O24: =INDEX(DelayMid,10) | P24: =INDEX(DelayMid,11) | Q24: =INDEX(DelayMid,12) | R24: =INDEX(DelayMid,13) | S24: =INDEX(DelayMid,14) | T24: =INDEX(DelayMid,15) | U24: =INDEX(DelayMid,16) | V24: =INDEX(DelayMid,17) | W24: =INDEX(DelayMid,18) | X24: =INDEX(DelayMid,19) | Y24: =INDEX(DelayMid,20) | Z24: =INDEX(DelayMid,21) | AA24: =INDEX(DelayMid,22)
A25: x | B25: mean only | C25: two moments | D25: conditioned | E25: (x - S_j)+ | F25: day 0 | G25: day 1 | H25: day 2 | I25: day 3 | J25: day 4 | K25: day 5 | L25: day 6 | M25: day 7 | N25: day 8 | O25: day 9 | P25: day 10 | Q25: day 11 | R25: day 12 | S25: day 13 | T25: day 14 | U25: day 15 | V25: day 16 | W25: day 17 | X25: day 18 | Y25: day 19 | Z25: day 20 | AA25: day 21
A26: 0 | B26: =_xlfn.POISSON.DIST(A26,$B$12,FALSE) | C26: =$B$14^$B$15 | D26: =SUMPRODUCT(F26:AA26,$F$23:$AA$23) | E26: =MAX(0,A26-$B$9) | F26: =_xlfn.POISSON.DIST($A26,$B$5*($B$6+F$24),FALSE) | G26: =_xlfn.POISSON.DIST($A26,$B$5*($B$6+G$24),FALSE) | H26: =_xlfn.POISSON.DIST($A26,$B$5*($B$6+H$24),FALSE) | I26: =_xlfn.POISSON.DIST($A26,$B$5*($B$6+I$24),FALSE) | J26: =_xlfn.POISSON.DIST($A26,$B$5*($B$6+J$24),FALSE) | K26: =_xlfn.POISSON.DIST($A26,$B$5*($B$6+K$24),FALSE) | L26: =_xlfn.POISSON.DIST($A26,$B$5*($B$6+L$24),FALSE) | M26: =_xlfn.POISSON.DIST($A26,$B$5*($B$6+M$24),FALSE) | ... AA26: =_xlfn.POISSON.DIST($A26,$B$5*($B$6+AA$24),FALSE)
A27: 1 | B27: =_xlfn.POISSON.DIST(A27,$B$12,FALSE) | C27: =C26*($B$15+A27-1)*(1-$B$14)/A27 | D27: =SUMPRODUCT(F27:AA27,$F$23:$AA$23) | E27: =MAX(0,A27-$B$9) | F27: =_xlfn.POISSON.DIST($A27,$B$5*($B$6+F$24),FALSE) | G27: =_xlfn.POISSON.DIST($A27,$B$5*($B$6+G$24),FALSE) | H27: =_xlfn.POISSON.DIST($A27,$B$5*($B$6+H$24),FALSE) | I27: =_xlfn.POISSON.DIST($A27,$B$5*($B$6+I$24),FALSE) | J27: =_xlfn.POISSON.DIST($A27,$B$5*($B$6+J$24),FALSE) | K27: =_xlfn.POISSON.DIST($A27,$B$5*($B$6+K$24),FALSE) | L27: =_xlfn.POISSON.DIST($A27,$B$5*($B$6+L$24),FALSE) | M27: =_xlfn.POISSON.DIST($A27,$B$5*($B$6+M$24),FALSE) | ... AA27: =_xlfn.POISSON.DIST($A27,$B$5*($B$6+AA$24),FALSE)
A28: 2 | B28: =_xlfn.POISSON.DIST(A28,$B$12,FALSE) | C28: =C27*($B$15+A28-1)*(1-$B$14)/A28 | D28: =SUMPRODUCT(F28:AA28,$F$23:$AA$23) | E28: =MAX(0,A28-$B$9) | F28: =_xlfn.POISSON.DIST($A28,$B$5*($B$6+F$24),FALSE) | G28: =_xlfn.POISSON.DIST($A28,$B$5*($B$6+G$24),FALSE) | H28: =_xlfn.POISSON.DIST($A28,$B$5*($B$6+H$24),FALSE) | I28: =_xlfn.POISSON.DIST($A28,$B$5*($B$6+I$24),FALSE) | J28: =_xlfn.POISSON.DIST($A28,$B$5*($B$6+J$24),FALSE) | K28: =_xlfn.POISSON.DIST($A28,$B$5*($B$6+K$24),FALSE) | L28: =_xlfn.POISSON.DIST($A28,$B$5*($B$6+L$24),FALSE) | M28: =_xlfn.POISSON.DIST($A28,$B$5*($B$6+M$24),FALSE) | ... AA28: =_xlfn.POISSON.DIST($A28,$B$5*($B$6+AA$24),FALSE)
A29: 3 | B29: =_xlfn.POISSON.DIST(A29,$B$12,FALSE) | C29: =C28*($B$15+A29-1)*(1-$B$14)/A29 | D29: =SUMPRODUCT(F29:AA29,$F$23:$AA$23) | E29: =MAX(0,A29-$B$9) | F29: =_xlfn.POISSON.DIST($A29,$B$5*($B$6+F$24),FALSE) | G29: =_xlfn.POISSON.DIST($A29,$B$5*($B$6+G$24),FALSE) | H29: =_xlfn.POISSON.DIST($A29,$B$5*($B$6+H$24),FALSE) | I29: =_xlfn.POISSON.DIST($A29,$B$5*($B$6+I$24),FALSE) | J29: =_xlfn.POISSON.DIST($A29,$B$5*($B$6+J$24),FALSE) | K29: =_xlfn.POISSON.DIST($A29,$B$5*($B$6+K$24),FALSE) | L29: =_xlfn.POISSON.DIST($A29,$B$5*($B$6+L$24),FALSE) | M29: =_xlfn.POISSON.DIST($A29,$B$5*($B$6+M$24),FALSE) | ... AA29: =_xlfn.POISSON.DIST($A29,$B$5*($B$6+AA$24),FALSE)
A30: 4 | B30: =_xlfn.POISSON.DIST(A30,$B$12,FALSE) | C30: =C29*($B$15+A30-1)*(1-$B$14)/A30 | D30: =SUMPRODUCT(F30:AA30,$F$23:$AA$23) | E30: =MAX(0,A30-$B$9) | F30: =_xlfn.POISSON.DIST($A30,$B$5*($B$6+F$24),FALSE) | G30: =_xlfn.POISSON.DIST($A30,$B$5*($B$6+G$24),FALSE) | H30: =_xlfn.POISSON.DIST($A30,$B$5*($B$6+H$24),FALSE) | I30: =_xlfn.POISSON.DIST($A30,$B$5*($B$6+I$24),FALSE) | J30: =_xlfn.POISSON.DIST($A30,$B$5*($B$6+J$24),FALSE) | K30: =_xlfn.POISSON.DIST($A30,$B$5*($B$6+K$24),FALSE) | L30: =_xlfn.POISSON.DIST($A30,$B$5*($B$6+L$24),FALSE) | M30: =_xlfn.POISSON.DIST($A30,$B$5*($B$6+M$24),FALSE) | ... AA30: =_xlfn.POISSON.DIST($A30,$B$5*($B$6+AA$24),FALSE)
A31: 5 | B31: =_xlfn.POISSON.DIST(A31,$B$12,FALSE) | C31: =C30*($B$15+A31-1)*(1-$B$14)/A31 | D31: =SUMPRODUCT(F31:AA31,$F$23:$AA$23) | E31: =MAX(0,A31-$B$9) | F31: =_xlfn.POISSON.DIST($A31,$B$5*($B$6+F$24),FALSE) | G31: =_xlfn.POISSON.DIST($A31,$B$5*($B$6+G$24),FALSE) | H31: =_xlfn.POISSON.DIST($A31,$B$5*($B$6+H$24),FALSE) | I31: =_xlfn.POISSON.DIST($A31,$B$5*($B$6+I$24),FALSE) | J31: =_xlfn.POISSON.DIST($A31,$B$5*($B$6+J$24),FALSE) | K31: =_xlfn.POISSON.DIST($A31,$B$5*($B$6+K$24),FALSE) | L31: =_xlfn.POISSON.DIST($A31,$B$5*($B$6+L$24),FALSE) | M31: =_xlfn.POISSON.DIST($A31,$B$5*($B$6+M$24),FALSE) | ... AA31: =_xlfn.POISSON.DIST($A31,$B$5*($B$6+AA$24),FALSE)
A32: 6 | B32: =_xlfn.POISSON.DIST(A32,$B$12,FALSE) | C32: =C31*($B$15+A32-1)*(1-$B$14)/A32 | D32: =SUMPRODUCT(F32:AA32,$F$23:$AA$23) | E32: =MAX(0,A32-$B$9) | F32: =_xlfn.POISSON.DIST($A32,$B$5*($B$6+F$24),FALSE) | G32: =_xlfn.POISSON.DIST($A32,$B$5*($B$6+G$24),FALSE) | H32: =_xlfn.POISSON.DIST($A32,$B$5*($B$6+H$24),FALSE) | I32: =_xlfn.POISSON.DIST($A32,$B$5*($B$6+I$24),FALSE) | J32: =_xlfn.POISSON.DIST($A32,$B$5*($B$6+J$24),FALSE) | K32: =_xlfn.POISSON.DIST($A32,$B$5*($B$6+K$24),FALSE) | L32: =_xlfn.POISSON.DIST($A32,$B$5*($B$6+L$24),FALSE) | M32: =_xlfn.POISSON.DIST($A32,$B$5*($B$6+M$24),FALSE) | ... AA32: =_xlfn.POISSON.DIST($A32,$B$5*($B$6+AA$24),FALSE)
A33: 7 | B33: =_xlfn.POISSON.DIST(A33,$B$12,FALSE) | C33: =C32*($B$15+A33-1)*(1-$B$14)/A33 | D33: =SUMPRODUCT(F33:AA33,$F$23:$AA$23) | E33: =MAX(0,A33-$B$9) | F33: =_xlfn.POISSON.DIST($A33,$B$5*($B$6+F$24),FALSE) | G33: =_xlfn.POISSON.DIST($A33,$B$5*($B$6+G$24),FALSE) | H33: =_xlfn.POISSON.DIST($A33,$B$5*($B$6+H$24),FALSE) | I33: =_xlfn.POISSON.DIST($A33,$B$5*($B$6+I$24),FALSE) | J33: =_xlfn.POISSON.DIST($A33,$B$5*($B$6+J$24),FALSE) | K33: =_xlfn.POISSON.DIST($A33,$B$5*($B$6+K$24),FALSE) | L33: =_xlfn.POISSON.DIST($A33,$B$5*($B$6+L$24),FALSE) | M33: =_xlfn.POISSON.DIST($A33,$B$5*($B$6+M$24),FALSE) | ... AA33: =_xlfn.POISSON.DIST($A33,$B$5*($B$6+AA$24),FALSE)
A34: 8 | B34: =_xlfn.POISSON.DIST(A34,$B$12,FALSE) | C34: =C33*($B$15+A34-1)*(1-$B$14)/A34 | D34: =SUMPRODUCT(F34:AA34,$F$23:$AA$23) | E34: =MAX(0,A34-$B$9) | F34: =_xlfn.POISSON.DIST($A34,$B$5*($B$6+F$24),FALSE) | G34: =_xlfn.POISSON.DIST($A34,$B$5*($B$6+G$24),FALSE) | H34: =_xlfn.POISSON.DIST($A34,$B$5*($B$6+H$24),FALSE) | I34: =_xlfn.POISSON.DIST($A34,$B$5*($B$6+I$24),FALSE) | J34: =_xlfn.POISSON.DIST($A34,$B$5*($B$6+J$24),FALSE) | K34: =_xlfn.POISSON.DIST($A34,$B$5*($B$6+K$24),FALSE) | L34: =_xlfn.POISSON.DIST($A34,$B$5*($B$6+L$24),FALSE) | M34: =_xlfn.POISSON.DIST($A34,$B$5*($B$6+M$24),FALSE) | ... AA34: =_xlfn.POISSON.DIST($A34,$B$5*($B$6+AA$24),FALSE)
A35: 9 | B35: =_xlfn.POISSON.DIST(A35,$B$12,FALSE) | C35: =C34*($B$15+A35-1)*(1-$B$14)/A35 | D35: =SUMPRODUCT(F35:AA35,$F$23:$AA$23) | E35: =MAX(0,A35-$B$9) | F35: =_xlfn.POISSON.DIST($A35,$B$5*($B$6+F$24),FALSE) | G35: =_xlfn.POISSON.DIST($A35,$B$5*($B$6+G$24),FALSE) | H35: =_xlfn.POISSON.DIST($A35,$B$5*($B$6+H$24),FALSE) | I35: =_xlfn.POISSON.DIST($A35,$B$5*($B$6+I$24),FALSE) | J35: =_xlfn.POISSON.DIST($A35,$B$5*($B$6+J$24),FALSE) | K35: =_xlfn.POISSON.DIST($A35,$B$5*($B$6+K$24),FALSE) | L35: =_xlfn.POISSON.DIST($A35,$B$5*($B$6+L$24),FALSE) | M35: =_xlfn.POISSON.DIST($A35,$B$5*($B$6+M$24),FALSE) | ... AA35: =_xlfn.POISSON.DIST($A35,$B$5*($B$6+AA$24),FALSE)
A36: 10 | B36: =_xlfn.POISSON.DIST(A36,$B$12,FALSE) | C36: =C35*($B$15+A36-1)*(1-$B$14)/A36 | D36: =SUMPRODUCT(F36:AA36,$F$23:$AA$23) | E36: =MAX(0,A36-$B$9) | F36: =_xlfn.POISSON.DIST($A36,$B$5*($B$6+F$24),FALSE) | G36: =_xlfn.POISSON.DIST($A36,$B$5*($B$6+G$24),FALSE) | H36: =_xlfn.POISSON.DIST($A36,$B$5*($B$6+H$24),FALSE) | I36: =_xlfn.POISSON.DIST($A36,$B$5*($B$6+I$24),FALSE) | J36: =_xlfn.POISSON.DIST($A36,$B$5*($B$6+J$24),FALSE) | K36: =_xlfn.POISSON.DIST($A36,$B$5*($B$6+K$24),FALSE) | L36: =_xlfn.POISSON.DIST($A36,$B$5*($B$6+L$24),FALSE) | M36: =_xlfn.POISSON.DIST($A36,$B$5*($B$6+M$24),FALSE) | ... AA36: =_xlfn.POISSON.DIST($A36,$B$5*($B$6+AA$24),FALSE)
A37: 11 | B37: =_xlfn.POISSON.DIST(A37,$B$12,FALSE) | C37: =C36*($B$15+A37-1)*(1-$B$14)/A37 | D37: =SUMPRODUCT(F37:AA37,$F$23:$AA$23) | E37: =MAX(0,A37-$B$9) | F37: =_xlfn.POISSON.DIST($A37,$B$5*($B$6+F$24),FALSE) | G37: =_xlfn.POISSON.DIST($A37,$B$5*($B$6+G$24),FALSE) | H37: =_xlfn.POISSON.DIST($A37,$B$5*($B$6+H$24),FALSE) | I37: =_xlfn.POISSON.DIST($A37,$B$5*($B$6+I$24),FALSE) | J37: =_xlfn.POISSON.DIST($A37,$B$5*($B$6+J$24),FALSE) | K37: =_xlfn.POISSON.DIST($A37,$B$5*($B$6+K$24),FALSE) | L37: =_xlfn.POISSON.DIST($A37,$B$5*($B$6+L$24),FALSE) | M37: =_xlfn.POISSON.DIST($A37,$B$5*($B$6+M$24),FALSE) | ... AA37: =_xlfn.POISSON.DIST($A37,$B$5*($B$6+AA$24),FALSE)
A38: 12 | B38: =_xlfn.POISSON.DIST(A38,$B$12,FALSE) | C38: =C37*($B$15+A38-1)*(1-$B$14)/A38 | D38: =SUMPRODUCT(F38:AA38,$F$23:$AA$23) | E38: =MAX(0,A38-$B$9) | F38: =_xlfn.POISSON.DIST($A38,$B$5*($B$6+F$24),FALSE) | G38: =_xlfn.POISSON.DIST($A38,$B$5*($B$6+G$24),FALSE) | H38: =_xlfn.POISSON.DIST($A38,$B$5*($B$6+H$24),FALSE) | I38: =_xlfn.POISSON.DIST($A38,$B$5*($B$6+I$24),FALSE) | J38: =_xlfn.POISSON.DIST($A38,$B$5*($B$6+J$24),FALSE) | K38: =_xlfn.POISSON.DIST($A38,$B$5*($B$6+K$24),FALSE) | L38: =_xlfn.POISSON.DIST($A38,$B$5*($B$6+L$24),FALSE) | M38: =_xlfn.POISSON.DIST($A38,$B$5*($B$6+M$24),FALSE) | ... AA38: =_xlfn.POISSON.DIST($A38,$B$5*($B$6+AA$24),FALSE)
... A56: 30 | B56: =_xlfn.POISSON.DIST(A56,$B$12,FALSE) | C56: =C55*($B$15+A56-1)*(1-$B$14)/A56 | D56: =SUMPRODUCT(F56:AA56,$F$23:$AA$23) | E56: =MAX(0,A56-$B$9) | F56: =_xlfn.POISSON.DIST($A56,$B$5*($B$6+F$24),FALSE) | G56: =_xlfn.POISSON.DIST($A56,$B$5*($B$6+G$24),FALSE) | H56: =_xlfn.POISSON.DIST($A56,$B$5*($B$6+H$24),FALSE) | I56: =_xlfn.POISSON.DIST($A56,$B$5*($B$6+I$24),FALSE) | J56: =_xlfn.POISSON.DIST($A56,$B$5*($B$6+J$24),FALSE) | K56: =_xlfn.POISSON.DIST($A56,$B$5*($B$6+K$24),FALSE) | L56: =_xlfn.POISSON.DIST($A56,$B$5*($B$6+L$24),FALSE) | M56: =_xlfn.POISSON.DIST($A56,$B$5*($B$6+M$24),FALSE) | ... AA56: =_xlfn.POISSON.DIST($A56,$B$5*($B$6+AA$24),FALSE)

Sheet Orders
A1: Orders in a window
A2: @sec-batchedmultiechelon. The storeroom orders each time its customers carry its position down through r_j.
A4: Part II's network
A5: storeroom demand lambda_j | B5: 2 | C5: units a week
A6: storeroom order Q_j | B6: 3 | C6: units
A7: other demand lambda_o | B7: 2 | C7: units a week
A8: hub lead time L_0 | B8: 3 | C8: weeks, and the window
A9: hub reorder point r_0 | B9: 12 | C9: units
A10: hub order quantity Q_0 | B10: 8 | C10: units
A11: storeroom reorder point r_j | B11: 3 | C11: units
A12: storeroom demand in the window | B12: =B5*B8
A14: Checks
A15: sum of P(N = n) | B15: =SUM(D20:D34)
A16: Q_j E[N] | B16: =$B$6*SUMPRODUCT(C20:C34,D20:D34) | C16: must equal the demand in the window
A17: sum of P(floor(D'/Q_j) = n) | B17: =SUM(E20:E34)
A19: y | B19: P(D >= y) | C19: n | D19: P(N = n) | E19: seen from an order | F19: P(N >= n)
A20: 1 | B20: =1-_xlfn.POISSON.DIST(A20-1,$B$12,TRUE) | C20: 0 | D20: =F20-F21 | E20: =_xlfn.POISSON.DIST(0*$B$6+$B$6-1,$B$12,TRUE)-0 | F20: =1
A21: 2 | B21: =1-_xlfn.POISSON.DIST(A21-1,$B$12,TRUE) | C21: 1 | D21: =F21-F22 | E21: =_xlfn.POISSON.DIST(1*$B$6+$B$6-1,$B$12,TRUE)-_xlfn.POISSON.DIST(1*$B$6-1,$B$12,TRUE) | F21: =AVERAGE(INDEX(OrdersTail,(1-1)*$B$6+1):INDEX(OrdersTail,1*$B$6))
A22: 3 | B22: =1-_xlfn.POISSON.DIST(A22-1,$B$12,TRUE) | C22: 2 | D22: =F22-F23 | E22: =_xlfn.POISSON.DIST(2*$B$6+$B$6-1,$B$12,TRUE)-_xlfn.POISSON.DIST(2*$B$6-1,$B$12,TRUE) | F22: =AVERAGE(INDEX(OrdersTail,(2-1)*$B$6+1):INDEX(OrdersTail,2*$B$6))
A23: 4 | B23: =1-_xlfn.POISSON.DIST(A23-1,$B$12,TRUE) | C23: 3 | D23: =F23-F24 | E23: =_xlfn.POISSON.DIST(3*$B$6+$B$6-1,$B$12,TRUE)-_xlfn.POISSON.DIST(3*$B$6-1,$B$12,TRUE) | F23: =AVERAGE(INDEX(OrdersTail,(3-1)*$B$6+1):INDEX(OrdersTail,3*$B$6))
A24: 5 | B24: =1-_xlfn.POISSON.DIST(A24-1,$B$12,TRUE) | C24: 4 | D24: =F24-F25 | E24: =_xlfn.POISSON.DIST(4*$B$6+$B$6-1,$B$12,TRUE)-_xlfn.POISSON.DIST(4*$B$6-1,$B$12,TRUE) | F24: =AVERAGE(INDEX(OrdersTail,(4-1)*$B$6+1):INDEX(OrdersTail,4*$B$6))
A25: 6 | B25: =1-_xlfn.POISSON.DIST(A25-1,$B$12,TRUE) | C25: 5 | D25: =F25-F26 | E25: =_xlfn.POISSON.DIST(5*$B$6+$B$6-1,$B$12,TRUE)-_xlfn.POISSON.DIST(5*$B$6-1,$B$12,TRUE) | F25: =AVERAGE(INDEX(OrdersTail,(5-1)*$B$6+1):INDEX(OrdersTail,5*$B$6))
A26: 7 | B26: =1-_xlfn.POISSON.DIST(A26-1,$B$12,TRUE) | C26: 6 | D26: =F26-F27 | E26: =_xlfn.POISSON.DIST(6*$B$6+$B$6-1,$B$12,TRUE)-_xlfn.POISSON.DIST(6*$B$6-1,$B$12,TRUE) | F26: =AVERAGE(INDEX(OrdersTail,(6-1)*$B$6+1):INDEX(OrdersTail,6*$B$6))
A27: 8 | B27: =1-_xlfn.POISSON.DIST(A27-1,$B$12,TRUE) | C27: 7 | D27: =F27-F28 | E27: =_xlfn.POISSON.DIST(7*$B$6+$B$6-1,$B$12,TRUE)-_xlfn.POISSON.DIST(7*$B$6-1,$B$12,TRUE) | F27: =AVERAGE(INDEX(OrdersTail,(7-1)*$B$6+1):INDEX(OrdersTail,7*$B$6))
A28: 9 | B28: =1-_xlfn.POISSON.DIST(A28-1,$B$12,TRUE) | C28: 8 | D28: =F28-F29 | E28: =_xlfn.POISSON.DIST(8*$B$6+$B$6-1,$B$12,TRUE)-_xlfn.POISSON.DIST(8*$B$6-1,$B$12,TRUE) | F28: =AVERAGE(INDEX(OrdersTail,(8-1)*$B$6+1):INDEX(OrdersTail,8*$B$6))
A29: 10 | B29: =1-_xlfn.POISSON.DIST(A29-1,$B$12,TRUE) | C29: 9 | D29: =F29-F30 | E29: =_xlfn.POISSON.DIST(9*$B$6+$B$6-1,$B$12,TRUE)-_xlfn.POISSON.DIST(9*$B$6-1,$B$12,TRUE) | F29: =AVERAGE(INDEX(OrdersTail,(9-1)*$B$6+1):INDEX(OrdersTail,9*$B$6))
A30: 11 | B30: =1-_xlfn.POISSON.DIST(A30-1,$B$12,TRUE) | C30: 10 | D30: =F30-F31 | E30: =_xlfn.POISSON.DIST(10*$B$6+$B$6-1,$B$12,TRUE)-_xlfn.POISSON.DIST(10*$B$6-1,$B$12,TRUE) | F30: =AVERAGE(INDEX(OrdersTail,(10-1)*$B$6+1):INDEX(OrdersTail,10*$B$6))
A31: 12 | B31: =1-_xlfn.POISSON.DIST(A31-1,$B$12,TRUE) | C31: 11 | D31: =F31-F32 | E31: =_xlfn.POISSON.DIST(11*$B$6+$B$6-1,$B$12,TRUE)-_xlfn.POISSON.DIST(11*$B$6-1,$B$12,TRUE) | F31: =AVERAGE(INDEX(OrdersTail,(11-1)*$B$6+1):INDEX(OrdersTail,11*$B$6))
A32: 13 | B32: =1-_xlfn.POISSON.DIST(A32-1,$B$12,TRUE) | C32: 12 | D32: =F32-F33 | E32: =_xlfn.POISSON.DIST(12*$B$6+$B$6-1,$B$12,TRUE)-_xlfn.POISSON.DIST(12*$B$6-1,$B$12,TRUE) | F32: =AVERAGE(INDEX(OrdersTail,(12-1)*$B$6+1):INDEX(OrdersTail,12*$B$6))
A33: 14 | B33: =1-_xlfn.POISSON.DIST(A33-1,$B$12,TRUE) | C33: 13 | D33: =F33-F34 | E33: =_xlfn.POISSON.DIST(13*$B$6+$B$6-1,$B$12,TRUE)-_xlfn.POISSON.DIST(13*$B$6-1,$B$12,TRUE) | F33: =AVERAGE(INDEX(OrdersTail,(13-1)*$B$6+1):INDEX(OrdersTail,13*$B$6))
A34: 15 | B34: =1-_xlfn.POISSON.DIST(A34-1,$B$12,TRUE) | C34: 14 | D34: =F34-F35 | E34: =_xlfn.POISSON.DIST(14*$B$6+$B$6-1,$B$12,TRUE)-_xlfn.POISSON.DIST(14*$B$6-1,$B$12,TRUE) | F34: =AVERAGE(INDEX(OrdersTail,(14-1)*$B$6+1):INDEX(OrdersTail,14*$B$6))
A35: 16 | B35: =1-_xlfn.POISSON.DIST(A35-1,$B$12,TRUE) | F35: =AVERAGE(INDEX(OrdersTail,(15-1)*$B$6+1):INDEX(OrdersTail,15*$B$6))
A36: 17 | B36: =1-_xlfn.POISSON.DIST(A36-1,$B$12,TRUE)
A37: 18 | B37: =1-_xlfn.POISSON.DIST(A37-1,$B$12,TRUE)
A38: 19 | B38: =1-_xlfn.POISSON.DIST(A38-1,$B$12,TRUE)
A39: 20 | B39: =1-_xlfn.POISSON.DIST(A39-1,$B$12,TRUE)
A40: 21 | B40: =1-_xlfn.POISSON.DIST(A40-1,$B$12,TRUE)
A41: 22 | B41: =1-_xlfn.POISSON.DIST(A41-1,$B$12,TRUE)
A42: 23 | B42: =1-_xlfn.POISSON.DIST(A42-1,$B$12,TRUE)
A43: 24 | B43: =1-_xlfn.POISSON.DIST(A43-1,$B$12,TRUE)
...

Sheet HubGeneral
A1: The hub with other demand, exactly and by two shortcuts
A2: @sec-batchedmultiechelon. The hub's demand is the other demand plus the storeroom's orders counted in batches.
A4: Read from the Orders sheet, and the costs
A5: lambda_o L_0 | B5: =Orders!B7*Orders!B8
A6: Q_j | B6: =Orders!B6
A7: Q_0 | B7: =Orders!B10
A8: h per week | B8: =Hub!B14
A9: b per week | B9: =Hub!B15
A10: lambda_0 L_0 | B10: =(Orders!B5+Orders!B7)*Orders!B8
A12: Three lead time demands
B13: exact | C13: recipe | D13: shortcut
A14: mean | B14: =SUMPRODUCT($A$32:$A$92,B32:B92) | C14: =B10 | D14: =B10
A15: variance | B15: =B18-B14^2 | C15: =Orders!B7*Orders!B8+Orders!B5*Orders!B8+B6^2/6 | D15: =Orders!B7*Orders!B8+Orders!B5*Orders!B6*Orders!B8
A16: negative binomial p | C16: =C14/C15 | D16: =D14/D15
A17: negative binomial r | C17: =C14^2/(C15-C14) | D17: =D14^2/(D15-D14)
A18: second moment E[X^2] | B18: =SUMPRODUCT($A$32:$A$92,$A$32:$A$92,B32:B92) | C18: =C15+C14^2 | D18: =D15+D14^2
A19: r_0 it would choose | B19: =MATCH(B20,O32:O62,0)-1 | C19: =MATCH(C20,P32:P62,0)-1 | D19: =MATCH(D20,Q32:Q62,0)-1
A20: cost it believes | B20: =MIN(O32:O62) | C20: =MIN(P32:P62) | D20: =MIN(Q32:Q62)
A21: true cost of that r_0 | B21: =INDEX($O$32:$O$62,B19+1) | C21: =INDEX($O$32:$O$62,C19+1) | D21: =INDEX($O$32:$O$62,D19+1)
A23: The hub at r_0 from the Orders sheet, exactly
A24: expected backorders | B24: =(INDEX(GenExactLossTwo,Orders!B9+1)-INDEX(GenExactLossTwo,Orders!B9+B7+1))/B7
A25: ready rate | B25: =1-(INDEX(GenExactLossOne,Orders!B9+1)-INDEX(GenExactLossOne,Orders!B9+B7+1))/B7
A26: expected on-hand | B26: =(B7+1)/2+Orders!B9-B14+B24
A27: The recipe adds Q_j^2/6 for the rounding to whole batches. The shortcut treats the storeroom's orders as Poisson arrivals of Q_j units, which is Q_j times the customers' variance.
A29: Columns R onward: the other demand's Poisson mass shifted by n batches, weighted by P(N = n). | Q29: P(N = n) | R29: =INDEX(OrdersCount,1) | S29: =INDEX(OrdersCount,2) | T29: =INDEX(OrdersCount,3) | U29: =INDEX(OrdersCount,4) | V29: =INDEX(OrdersCount,5) | W29: =INDEX(OrdersCount,6) | X29: =INDEX(OrdersCount,7) | Y29: =INDEX(OrdersCount,8) | Z29: =INDEX(OrdersCount,9) | AA29: =INDEX(OrdersCount,10) | AB29: =INDEX(OrdersCount,11) | AC29: =INDEX(OrdersCount,12) | AD29: =INDEX(OrdersCount,13) | AE29: =INDEX(OrdersCount,14) | AF29: =INDEX(OrdersCount,15)
R30: 0 | S30: 1 | T30: 2 | U30: 3 | V30: 4 | W30: 5 | X30: 6 | Y30: 7 | Z30: 8 | AA30: 9 | AB30: 10 | AC30: 11 | AD30: 12 | AE30: 13 | AF30: 14
A31: x | B31: exact | C31: F | D31: LossOne | E31: LossTwo | F31: recipe | G31: F | H31: LossOne | I31: LossTwo | J31: shortcut | K31: F | L31: LossOne | M31: LossTwo | N31: r | O31: exact cost | P31: recipe cost | Q31: shortcut cost
A32: 0 | B32: =SUMPRODUCT(R32:AF32,$R$29:$AF$29) | C32: =B32 | D32: =$B$14 | E32: =0.5*($B$18-$B$14) | F32: =$C$16^$C$17 | G32: =F32 | H32: =$C$14 | I32: =0.5*($C$18-$C$14) | J32: =$D$16^$D$17 | K32: =J32 | L32: =$D$14 | M32: =0.5*($D$18-$D$14) | N32: 0 | O32: =$B$8*(($B$7+1)/2+N32-$B$14+(INDEX(GenExactLossTwo,N32+1)-INDEX(GenExactLossTwo,N32+$B$7+1))/$B$7)+$B$9*(INDEX(GenExactLossTwo,N32+1)-INDEX(GenExactLossTwo,N32+$B$7+1))/$B$7 | P32: =$B$8*(($B$7+1)/2+N32-$C$14+(INDEX(GenRecipeLossTwo,N32+1)-INDEX(GenRecipeLossTwo,N32+$B$7+1))/$B$7)+$B$9*(INDEX(GenRecipeLossTwo,N32+1)-INDEX(GenRecipeLossTwo,N32+$B$7+1))/$B$7 | Q32: =$B$8*(($B$7+1)/2+N32-$D$14+(INDEX(GenShortcutLossTwo,N32+1)-INDEX(GenShortcutLossTwo,N32+$B$7+1))/$B$7)+$B$9*(INDEX(GenShortcutLossTwo,N32+1)-INDEX(GenShortcutLossTwo,N32+$B$7+1))/$B$7 | R32: =IF($A32-0*$B$6>=0,_xlfn.POISSON.DIST($A32-0*$B$6,$B$5,FALSE),0) | S32: =IF($A32-1*$B$6>=0,_xlfn.POISSON.DIST($A32-1*$B$6,$B$5,FALSE),0) | T32: =IF($A32-2*$B$6>=0,_xlfn.POISSON.DIST($A32-2*$B$6,$B$5,FALSE),0) | U32: =IF($A32-3*$B$6>=0,_xlfn.POISSON.DIST($A32-3*$B$6,$B$5,FALSE),0) | V32: =IF($A32-4*$B$6>=0,_xlfn.POISSON.DIST($A32-4*$B$6,$B$5,FALSE),0) | W32: =IF($A32-5*$B$6>=0,_xlfn.POISSON.DIST($A32-5*$B$6,$B$5,FALSE),0) | X32: =IF($A32-6*$B$6>=0,_xlfn.POISSON.DIST($A32-6*$B$6,$B$5,FALSE),0) | Y32: =IF($A32-7*$B$6>=0,_xlfn.POISSON.DIST($A32-7*$B$6,$B$5,FALSE),0) | Z32: =IF($A32-8*$B$6>=0,_xlfn.POISSON.DIST($A32-8*$B$6,$B$5,FALSE),0) | AA32: =IF($A32-9*$B$6>=0,_xlfn.POISSON.DIST($A32-9*$B$6,$B$5,FALSE),0) | AB32: =IF($A32-10*$B$6>=0,_xlfn.POISSON.DIST($A32-10*$B$6,$B$5,FALSE),0) | AC32: =IF($A32-11*$B$6>=0,_xlfn.POISSON.DIST($A32-11*$B$6,$B$5,FALSE),0) | AD32: =IF($A32-12*$B$6>=0,_xlfn.POISSON.DIST($A32-12*$B$6,$B$5,FALSE),0) | AE32: =IF($A32-13*$B$6>=0,_xlfn.POISSON.DIST($A32-13*$B$6,$B$5,FALSE),0) | AF32: =IF($A32-14*$B$6>=0,_xlfn.POISSON.DIST($A32-14*$B$6,$B$5,FALSE),0)
A33: 1 | B33: =SUMPRODUCT(R33:AF33,$R$29:$AF$29) | C33: =C32+B33 | D33: =D32-(1-C32) | E33: =E32-D33 | F33: =F32*($C$17+1-1)*(1-$C$16)/1 | G33: =G32+F33 | H33: =H32-(1-G32) | I33: =I32-H33 | J33: =J32*($D$17+1-1)*(1-$D$16)/1 | K33: =K32+J33 | L33: =L32-(1-K32) | M33: =M32-L33 | N33: 1 | O33: =$B$8*(($B$7+1)/2+N33-$B$14+(INDEX(GenExactLossTwo,N33+1)-INDEX(GenExactLossTwo,N33+$B$7+1))/$B$7)+$B$9*(INDEX(GenExactLossTwo,N33+1)-INDEX(GenExactLossTwo,N33+$B$7+1))/$B$7 | P33: =$B$8*(($B$7+1)/2+N33-$C$14+(INDEX(GenRecipeLossTwo,N33+1)-INDEX(GenRecipeLossTwo,N33+$B$7+1))/$B$7)+$B$9*(INDEX(GenRecipeLossTwo,N33+1)-INDEX(GenRecipeLossTwo,N33+$B$7+1))/$B$7 | Q33: =$B$8*(($B$7+1)/2+N33-$D$14+(INDEX(GenShortcutLossTwo,N33+1)-INDEX(GenShortcutLossTwo,N33+$B$7+1))/$B$7)+$B$9*(INDEX(GenShortcutLossTwo,N33+1)-INDEX(GenShortcutLossTwo,N33+$B$7+1))/$B$7 | R33: =IF($A33-0*$B$6>=0,_xlfn.POISSON.DIST($A33-0*$B$6,$B$5,FALSE),0) | S33: =IF($A33-1*$B$6>=0,_xlfn.POISSON.DIST($A33-1*$B$6,$B$5,FALSE),0) | T33: =IF($A33-2*$B$6>=0,_xlfn.POISSON.DIST($A33-2*$B$6,$B$5,FALSE),0) | U33: =IF($A33-3*$B$6>=0,_xlfn.POISSON.DIST($A33-3*$B$6,$B$5,FALSE),0) | V33: =IF($A33-4*$B$6>=0,_xlfn.POISSON.DIST($A33-4*$B$6,$B$5,FALSE),0) | W33: =IF($A33-5*$B$6>=0,_xlfn.POISSON.DIST($A33-5*$B$6,$B$5,FALSE),0) | X33: =IF($A33-6*$B$6>=0,_xlfn.POISSON.DIST($A33-6*$B$6,$B$5,FALSE),0) | Y33: =IF($A33-7*$B$6>=0,_xlfn.POISSON.DIST($A33-7*$B$6,$B$5,FALSE),0) | Z33: =IF($A33-8*$B$6>=0,_xlfn.POISSON.DIST($A33-8*$B$6,$B$5,FALSE),0) | AA33: =IF($A33-9*$B$6>=0,_xlfn.POISSON.DIST($A33-9*$B$6,$B$5,FALSE),0) | AB33: =IF($A33-10*$B$6>=0,_xlfn.POISSON.DIST($A33-10*$B$6,$B$5,FALSE),0) | AC33: =IF($A33-11*$B$6>=0,_xlfn.POISSON.DIST($A33-11*$B$6,$B$5,FALSE),0) | AD33: =IF($A33-12*$B$6>=0,_xlfn.POISSON.DIST($A33-12*$B$6,$B$5,FALSE),0) | AE33: =IF($A33-13*$B$6>=0,_xlfn.POISSON.DIST($A33-13*$B$6,$B$5,FALSE),0) | AF33: =IF($A33-14*$B$6>=0,_xlfn.POISSON.DIST($A33-14*$B$6,$B$5,FALSE),0)
