Workbook
Name Dls_t: 'Data'!$A$31:$A$42
Name Dls_d: 'Data'!$B$31:$B$42
Name Dls_k: 'Data'!$C$31:$C$42
Name Dls_c: 'Data'!$D$31:$D$42
Name Dls_h: 'Data'!$E$31:$E$42
Name Dls_N: 'Data'!$B$9

Sheet Notes
A1: Chapter 5, Dynamic Lot Sizing
A3: One item, twelve months of known but time-varying requirements, and several ways to plan them.
A5: Sheets, in the order to read them:
A6: Data the requirements and the costs. The only cells anyone types into.
A7: Plans four plans side by side. Type over a plan's order column and read what it costs.
A8: WagnerWhitin the window costs, the recursion, and the traceback that reads the optimal plan off it.
A9: Heuristics Silver-Meal, least unit cost and part-period balancing against the same windows.
A10: Solver the same problem as a mixed integer program, for Solver to run.
A12: Conventions:
A13: Blue cells are inputs. Grey cells are computed and should not be typed over.
A14: Every sheet ends with a check block giving what the shipped data should produce.
A15: A sub-range of the requirements is written INDEX(Dls_d,a):INDEX(Dls_d,b), which is the
... A20: Rebuild this file with scripts/build-ch5-workbook.py and check it with scripts/check-ch5-workbook.py.

Sheet Data
A1: The item and its requirements
A2: Chapter 5, section 5.1.
A4: INPUTS
A5: Order cost, k | B5: 300 | C5: dollars per order
A6: Unit cost, c | B6: 50 | C6: dollars per belt
A7: Carrying charge, i | B7: 0.02 | C7: per dollar per month
A8: Holding rate, h = ic | B8: =B6*B7
A9: Periods in the horizon, N | B9: =COUNT(Dls_d)
A11: WHAT THE PATTERN LOOKS LIKE
A12: Total requirement | B12: =SUM(Dls_d)
A13: Average requirement per month | B13: =B12/B9
A14: Variability coefficient | B14: =SUM(F31:F42)/B9/B13^2
A15: Use a heuristic? | B15: =IF(B14>=0.2,"yes, the pattern varies enough","no, an ordinary EOQ will serve")
A16: k / h, the carrying a single order buys | B16: =B5/B8
A17: First month whose requirement forces an order | B17: =IF(COUNT(G31:G42)=0,"none",MIN(G31:G42))
A18: Section 5.3: a requirement larger than k/h cannot be carried in from any earlier month.
A20: THE ECONOMIC ORDER QUANTITY, FOR COMPARISON
A21: EOQ on the average requirement | B21: =SQRT(2*B5*B13/B8)
A22: As a time supply, months | B22: =B21/B13
A23: Rounded to whole months | B23: =MAX(1,ROUND(B22,0))
A25: CHECK with the data as shipped
A26: Total 1,840 belts; average 153.3333; variability coefficient 0.6191; k/h = 300;
A27: the first forced month is 5; EOQ 303.3 belts, 1.98 months, rounding to 2.
A29: REQUIREMENTS type over column B to change the pattern
A30: Month t | B30: Requirement d(t) | C30: Order cost k(t) | D30: Unit cost c(t) | E30: Holding rate h(t) | F30: (d(t) - mean)^2 | G30: Forced?
A31: 1 | B31: 40 | C31: =$B$5 | D31: =$B$6 | E31: =$B$8 | F31: =(B31-$B$13)^2 | G31: =IF(B31*$B$8>$B$5,A31,"")
A32: 2 | B32: 60 | C32: =$B$5 | D32: =$B$6 | E32: =$B$8 | F32: =(B32-$B$13)^2 | G32: =IF(B32*$B$8>$B$5,A32,"")
A33: 3 | B33: 120 | C33: =$B$5 | D33: =$B$6 | E33: =$B$8 | F33: =(B33-$B$13)^2 | G33: =IF(B33*$B$8>$B$5,A33,"")
A34: 4 | B34: 300 | C34: =$B$5 | D34: =$B$6 | E34: =$B$8 | F34: =(B34-$B$13)^2 | G34: =IF(B34*$B$8>$B$5,A34,"")
A35: 5 | B35: 420 | C35: =$B$5 | D35: =$B$6 | E35: =$B$8 | F35: =(B35-$B$13)^2 | G35: =IF(B35*$B$8>$B$5,A35,"")
A36: 6 | B36: 260 | C36: =$B$5 | D36: =$B$6 | E36: =$B$8 | F36: =(B36-$B$13)^2 | G36: =IF(B36*$B$8>$B$5,A36,"")
A37: 7 | B37: 120 | C37: =$B$5 | D37: =$B$6 | E37: =$B$8 | F37: =(B37-$B$13)^2 | G37: =IF(B37*$B$8>$B$5,A37,"")
A38: 8 | B38: 40 | C38: =$B$5 | D38: =$B$6 | E38: =$B$8 | F38: =(B38-$B$13)^2 | G38: =IF(B38*$B$8>$B$5,A38,"")
A39: 9 | B39: 0 | C39: =$B$5 | D39: =$B$6 | E39: =$B$8 | F39: =(B39-$B$13)^2 | G39: =IF(B39*$B$8>$B$5,A39,"")
A40: 10 | B40: 80 | C40: =$B$5 | D40: =$B$6 | E40: =$B$8 | F40: =(B40-$B$13)^2 | G40: =IF(B40*$B$8>$B$5,A40,"")
A41: 11 | B41: 180 | C41: =$B$5 | D41: =$B$6 | E41: =$B$8 | F41: =(B41-$B$13)^2 | G41: =IF(B41*$B$8>$B$5,A41,"")
A42: 12 | B42: 220 | C42: =$B$5 | D42: =$B$6 | E42: =$B$8 | F42: =(B42-$B$13)^2 | G42: =IF(B42*$B$8>$B$5,A42,"")
A44: The cost columns point at the inputs above, so a constant-cost problem is typed once.
A45: Type a number over one of them to make that month's cost differ, which is the case of Section 5.2.
A46: Columns F and G feed the variability coefficient and the forced month. They are not data.

Sheet Plans
A1: What a plan costs
A2: Chapter 5, section 5.2. Each plan owns an order column. Type over one and the results above it move.
A4: RESULTS
C5: Lot-for-lot | E5: Adjusted EOQ | G5: Periodic, T = 2 | I5: Your plan
A6: Orders placed | C6: =COUNTIF(C19:C30,">0") | E6: =COUNTIF(E19:E30,">0") | G6: =COUNTIF(G19:G30,">0") | I6: =COUNTIF(I19:I30,">0")
A7: Setup cost | C7: =Data!$B$5*COUNTIF(C19:C30,">0") | E7: =Data!$B$5*COUNTIF(E19:E30,">0") | G7: =Data!$B$5*COUNTIF(G19:G30,">0") | I7: =Data!$B$5*COUNTIF(I19:I30,">0")
A8: Carrying cost | C8: =SUMPRODUCT(Dls_h,D19:D30) | E8: =SUMPRODUCT(Dls_h,F19:F30) | G8: =SUMPRODUCT(Dls_h,H19:H30) | I8: =SUMPRODUCT(Dls_h,J19:J30)
A9: Purchase cost | C9: =SUMPRODUCT(Dls_c,C19:C30) | E9: =SUMPRODUCT(Dls_c,E19:E30) | G9: =SUMPRODUCT(Dls_c,G19:G30) | I9: =SUMPRODUCT(Dls_c,I19:I30)
A10: Relevant cost | C10: =C7+C8 | E10: =E7+E8 | G10: =G7+G8 | I10: =I7+I8
A11: Total cost | C11: =C10+C9 | E11: =E10+E9 | G11: =G10+G9 | I11: =I10+I9
A12: Penalty against the optimum | C12: =C10/WagnerWhitin!$B$5-1 | E12: =E10/WagnerWhitin!$B$5-1 | G12: =G10/WagnerWhitin!$B$5-1 | I12: =I10/WagnerWhitin!$B$5-1
A14: CHECK with the data as shipped
A15: Lot-for-lot: eleven orders, $3,300 of setup, nothing carried, 33.06% above the optimum.
A16: Adjusted EOQ: six orders, $1,800 and $800, for $2,600 and 4.84%. Periodic: $1,800 and $960, for $2,760 and 11.29%.
A17: THE LEDGER one row per month
A18: Month | B18: Requirement | C18: Order | D18: End | E18: Order | F18: End | G18: Order | H18: End | I18: Order | J18: End
A19: =INDEX(Dls_t,1) | B19: =INDEX(Dls_d,1) | C19: 40 | D19: =0+C19-$B19 | E19: 220 | F19: =0+E19-$B19 | G19: 100 | H19: =0+G19-$B19 | I19: 40 | J19: =0+I19-$B19
A20: =INDEX(Dls_t,2) | B20: =INDEX(Dls_d,2) | C20: 60 | D20: =D19+C20-$B20 | E20: 0 | F20: =F19+E20-$B20 | G20: 0 | H20: =H19+G20-$B20 | I20: 60 | J20: =J19+I20-$B20
A21: =INDEX(Dls_t,3) | B21: =INDEX(Dls_d,3) | C21: 120 | D21: =D20+C21-$B21 | E21: 0 | F21: =F20+E21-$B21 | G21: 420 | H21: =H20+G21-$B21 | I21: 120 | J21: =J20+I21-$B21
A22: =INDEX(Dls_t,4) | B22: =INDEX(Dls_d,4) | C22: 300 | D22: =D21+C22-$B22 | E22: 300 | F22: =F21+E22-$B22 | G22: 0 | H22: =H21+G22-$B22 | I22: 300 | J22: =J21+I22-$B22
A23: =INDEX(Dls_t,5) | B23: =INDEX(Dls_d,5) | C23: 420 | D23: =D22+C23-$B23 | E23: 420 | F23: =F22+E23-$B23 | G23: 680 | H23: =H22+G23-$B23 | I23: 420 | J23: =J22+I23-$B23
A24: =INDEX(Dls_t,6) | B24: =INDEX(Dls_d,6) | C24: 260 | D24: =D23+C24-$B24 | E24: 260 | F24: =F23+E24-$B24 | G24: 0 | H24: =H23+G24-$B24 | I24: 260 | J24: =J23+I24-$B24
A25: =INDEX(Dls_t,7) | B25: =INDEX(Dls_d,7) | C25: 120 | D25: =D24+C25-$B25 | E25: 240 | F25: =F24+E25-$B25 | G25: 160 | H25: =H24+G25-$B25 | I25: 120 | J25: =J24+I25-$B25
A26: =INDEX(Dls_t,8) | B26: =INDEX(Dls_d,8) | C26: 40 | D26: =D25+C26-$B26 | E26: 0 | F26: =F25+E26-$B26 | G26: 0 | H26: =H25+G26-$B26 | I26: 40 | J26: =J25+I26-$B26
A27: =INDEX(Dls_t,9) | B27: =INDEX(Dls_d,9) | C27: 0 | D27: =D26+C27-$B27 | E27: 0 | F27: =F26+E27-$B27 | G27: 80 | H27: =H26+G27-$B27 | I27: 0 | J27: =J26+I27-$B27
A28: =INDEX(Dls_t,10) | B28: =INDEX(Dls_d,10) | C28: 80 | D28: =D27+C28-$B28 | E28: 0 | F28: =F27+E28-$B28 | G28: 0 | H28: =H27+G28-$B28 | I28: 80 | J28: =J27+I28-$B28
A29: =INDEX(Dls_t,11) | B29: =INDEX(Dls_d,11) | C29: 180 | D29: =D28+C29-$B29 | E29: 400 | F29: =F28+E29-$B29 | G29: 400 | H29: =H28+G29-$B29 | I29: 180 | J29: =J28+I29-$B29
A30: =INDEX(Dls_t,12) | B30: =INDEX(Dls_d,12) | C30: 220 | D30: =D29+C30-$B30 | E30: 0 | F30: =F29+E30-$B30 | G30: 0 | H30: =H29+G30-$B30 | I30: 220 | J30: =J29+I30-$B30
A31: End = previous end + order - requirement. A negative end is a shortage, which section 5.1 forbids.
A32: Carrying cost charges the end-of-month balance, so a plan that orders only when empty carries nothing.

Sheet WagnerWhitin
A1: The optimal plan
A2: Chapter 5, section 5.4. Nothing here is typed; everything reads the Data sheet.
A4: RESULTS
A5: Optimal relevant cost, V(N) | B5: =M32
A6: Orders placed | B6: =COUNTIF(C58:C69,">0")
A7: Setup cost | B7: =E70
A8: Carrying cost | B8: =F70
A9: Setup plus carrying, which must equal V(N) | B9: =B7+B8
A11: CHECK with the data as shipped
A12: V(12) = $2,480 in six orders: $1,800 of setup and $680 of carrying.
A13: The orders fall in months 1, 4, 5, 6, 10 and 12, for 220, 300, 420, 420, 260 and 220 belts.
A14: WINDOW COSTS w(t,u) order in month t, cover through month u
A15: t \ u | B15: 1 | C15: 2 | D15: 3 | E15: 4 | F15: 5 | G15: 6 | H15: 7 | I15: 8 | J15: 9 | K15: 10 | L15: 11 | M15: 12
A16: 1 | B16: =INDEX(Dls_k,1) | C16: =B16+INDEX(Dls_d,2)*SUM(INDEX(Dls_h,2):INDEX(Dls_h,2)) | D16: =C16+INDEX(Dls_d,3)*SUM(INDEX(Dls_h,2):INDEX(Dls_h,3)) | E16: =D16+INDEX(Dls_d,4)*SUM(INDEX(Dls_h,2):INDEX(Dls_h,4)) | F16: =E16+INDEX(Dls_d,5)*SUM(INDEX(Dls_h,2):INDEX(Dls_h,5)) | G16: =F16+INDEX(Dls_d,6)*SUM(INDEX(Dls_h,2):INDEX(Dls_h,6)) | H16: =G16+INDEX(Dls_d,7)*SUM(INDEX(Dls_h,2):INDEX(Dls_h,7)) | I16: =H16+INDEX(Dls_d,8)*SUM(INDEX(Dls_h,2):INDEX(Dls_h,8)) | J16: =I16+INDEX(Dls_d,9)*SUM(INDEX(Dls_h,2):INDEX(Dls_h,9)) | K16: =J16+INDEX(Dls_d,10)*SUM(INDEX(Dls_h,2):INDEX(Dls_h,10)) | L16: =K16+INDEX(Dls_d,11)*SUM(INDEX(Dls_h,2):INDEX(Dls_h,11)) | M16: =L16+INDEX(Dls_d,12)*SUM(INDEX(Dls_h,2):INDEX(Dls_h,12))
A17: 2 | C17: =INDEX(Dls_k,2) | D17: =C17+INDEX(Dls_d,3)*SUM(INDEX(Dls_h,3):INDEX(Dls_h,3)) | E17: =D17+INDEX(Dls_d,4)*SUM(INDEX(Dls_h,3):INDEX(Dls_h,4)) | F17: =E17+INDEX(Dls_d,5)*SUM(INDEX(Dls_h,3):INDEX(Dls_h,5)) | G17: =F17+INDEX(Dls_d,6)*SUM(INDEX(Dls_h,3):INDEX(Dls_h,6)) | H17: =G17+INDEX(Dls_d,7)*SUM(INDEX(Dls_h,3):INDEX(Dls_h,7)) | I17: =H17+INDEX(Dls_d,8)*SUM(INDEX(Dls_h,3):INDEX(Dls_h,8)) | J17: =I17+INDEX(Dls_d,9)*SUM(INDEX(Dls_h,3):INDEX(Dls_h,9)) | K17: =J17+INDEX(Dls_d,10)*SUM(INDEX(Dls_h,3):INDEX(Dls_h,10)) | L17: =K17+INDEX(Dls_d,11)*SUM(INDEX(Dls_h,3):INDEX(Dls_h,11)) | M17: =L17+INDEX(Dls_d,12)*SUM(INDEX(Dls_h,3):INDEX(Dls_h,12))
A18: 3 | D18: =INDEX(Dls_k,3) | E18: =D18+INDEX(Dls_d,4)*SUM(INDEX(Dls_h,4):INDEX(Dls_h,4)) | F18: =E18+INDEX(Dls_d,5)*SUM(INDEX(Dls_h,4):INDEX(Dls_h,5)) | G18: =F18+INDEX(Dls_d,6)*SUM(INDEX(Dls_h,4):INDEX(Dls_h,6)) | H18: =G18+INDEX(Dls_d,7)*SUM(INDEX(Dls_h,4):INDEX(Dls_h,7)) | I18: =H18+INDEX(Dls_d,8)*SUM(INDEX(Dls_h,4):INDEX(Dls_h,8)) | J18: =I18+INDEX(Dls_d,9)*SUM(INDEX(Dls_h,4):INDEX(Dls_h,9)) | K18: =J18+INDEX(Dls_d,10)*SUM(INDEX(Dls_h,4):INDEX(Dls_h,10)) | L18: =K18+INDEX(Dls_d,11)*SUM(INDEX(Dls_h,4):INDEX(Dls_h,11)) | M18: =L18+INDEX(Dls_d,12)*SUM(INDEX(Dls_h,4):INDEX(Dls_h,12))
A19: 4 | E19: =INDEX(Dls_k,4) | F19: =E19+INDEX(Dls_d,5)*SUM(INDEX(Dls_h,5):INDEX(Dls_h,5)) | G19: =F19+INDEX(Dls_d,6)*SUM(INDEX(Dls_h,5):INDEX(Dls_h,6)) | H19: =G19+INDEX(Dls_d,7)*SUM(INDEX(Dls_h,5):INDEX(Dls_h,7)) | I19: =H19+INDEX(Dls_d,8)*SUM(INDEX(Dls_h,5):INDEX(Dls_h,8)) | J19: =I19+INDEX(Dls_d,9)*SUM(INDEX(Dls_h,5):INDEX(Dls_h,9)) | K19: =J19+INDEX(Dls_d,10)*SUM(INDEX(Dls_h,5):INDEX(Dls_h,10)) | L19: =K19+INDEX(Dls_d,11)*SUM(INDEX(Dls_h,5):INDEX(Dls_h,11)) | M19: =L19+INDEX(Dls_d,12)*SUM(INDEX(Dls_h,5):INDEX(Dls_h,12))
A20: 5 | F20: =INDEX(Dls_k,5) | G20: =F20+INDEX(Dls_d,6)*SUM(INDEX(Dls_h,6):INDEX(Dls_h,6)) | H20: =G20+INDEX(Dls_d,7)*SUM(INDEX(Dls_h,6):INDEX(Dls_h,7)) | I20: =H20+INDEX(Dls_d,8)*SUM(INDEX(Dls_h,6):INDEX(Dls_h,8)) | J20: =I20+INDEX(Dls_d,9)*SUM(INDEX(Dls_h,6):INDEX(Dls_h,9)) | K20: =J20+INDEX(Dls_d,10)*SUM(INDEX(Dls_h,6):INDEX(Dls_h,10)) | L20: =K20+INDEX(Dls_d,11)*SUM(INDEX(Dls_h,6):INDEX(Dls_h,11)) | M20: =L20+INDEX(Dls_d,12)*SUM(INDEX(Dls_h,6):INDEX(Dls_h,12))
A21: 6 | G21: =INDEX(Dls_k,6) | H21: =G21+INDEX(Dls_d,7)*SUM(INDEX(Dls_h,7):INDEX(Dls_h,7)) | I21: =H21+INDEX(Dls_d,8)*SUM(INDEX(Dls_h,7):INDEX(Dls_h,8)) | J21: =I21+INDEX(Dls_d,9)*SUM(INDEX(Dls_h,7):INDEX(Dls_h,9)) | K21: =J21+INDEX(Dls_d,10)*SUM(INDEX(Dls_h,7):INDEX(Dls_h,10)) | L21: =K21+INDEX(Dls_d,11)*SUM(INDEX(Dls_h,7):INDEX(Dls_h,11)) | M21: =L21+INDEX(Dls_d,12)*SUM(INDEX(Dls_h,7):INDEX(Dls_h,12))
A22: 7 | H22: =INDEX(Dls_k,7) | I22: =H22+INDEX(Dls_d,8)*SUM(INDEX(Dls_h,8):INDEX(Dls_h,8)) | J22: =I22+INDEX(Dls_d,9)*SUM(INDEX(Dls_h,8):INDEX(Dls_h,9)) | K22: =J22+INDEX(Dls_d,10)*SUM(INDEX(Dls_h,8):INDEX(Dls_h,10)) | L22: =K22+INDEX(Dls_d,11)*SUM(INDEX(Dls_h,8):INDEX(Dls_h,11)) | M22: =L22+INDEX(Dls_d,12)*SUM(INDEX(Dls_h,8):INDEX(Dls_h,12))
A23: 8 | I23: =INDEX(Dls_k,8) | J23: =I23+INDEX(Dls_d,9)*SUM(INDEX(Dls_h,9):INDEX(Dls_h,9)) | K23: =J23+INDEX(Dls_d,10)*SUM(INDEX(Dls_h,9):INDEX(Dls_h,10)) | L23: =K23+INDEX(Dls_d,11)*SUM(INDEX(Dls_h,9):INDEX(Dls_h,11)) | M23: =L23+INDEX(Dls_d,12)*SUM(INDEX(Dls_h,9):INDEX(Dls_h,12))
A24: 9 | J24: =INDEX(Dls_k,9) | K24: =J24+INDEX(Dls_d,10)*SUM(INDEX(Dls_h,10):INDEX(Dls_h,10)) | L24: =K24+INDEX(Dls_d,11)*SUM(INDEX(Dls_h,10):INDEX(Dls_h,11)) | M24: =L24+INDEX(Dls_d,12)*SUM(INDEX(Dls_h,10):INDEX(Dls_h,12))
A25: 10 | K25: =INDEX(Dls_k,10) | L25: =K25+INDEX(Dls_d,11)*SUM(INDEX(Dls_h,11):INDEX(Dls_h,11)) | M25: =L25+INDEX(Dls_d,12)*SUM(INDEX(Dls_h,11):INDEX(Dls_h,12))
A26: 11 | L26: =INDEX(Dls_k,11) | M26: =L26+INDEX(Dls_d,12)*SUM(INDEX(Dls_h,12):INDEX(Dls_h,12))
A27: 12 | M27: =INDEX(Dls_k,12)
A28: Each cell adds one month to the cell on its left: the new requirement, carried from the order month.
A29: THE RECURSION V(u) = the least of V(t-1) + w(t,u) over the months t that could start the last order
A31: month u | B31: 1 | C31: 2 | D31: 3 | E31: 4 | F31: 5 | G31: 6 | H31: 7 | I31: 8 | J31: 9 | K31: 10 | L31: 11 | M31: 12
A32: V(u), the least cost through month u | B32: =MIN(B37:B48) | C32: =MIN(C37:C48) | D32: =MIN(D37:D48) | E32: =MIN(E37:E48) | F32: =MIN(F37:F48) | G32: =MIN(G37:G48) | H32: =MIN(H37:H48) | I32: =MIN(I37:I48) | ... M32: =MIN(M37:M48)
A33: S(u), the month that last order starts in | B33: =MATCH(B32,B37:B48,0) | C33: =MATCH(C32,C37:C48,0) | D33: =MATCH(D32,D37:D48,0) | E33: =MATCH(E32,E37:E48,0) | F33: =MATCH(F32,F37:F48,0) | G33: =MATCH(G32,G37:G48,0) | H33: =MATCH(H32,H37:H48,0) | I33: =MATCH(I32,I37:I48,0) | ... M33: =MATCH(M32,M37:M48,0)
A34: MATCH returns the first month achieving the least cost, which breaks a tie toward the earlier order.
A36: candidate V(t-1) + w(t,u) | B36: 1 | C36: 2 | D36: 3 | E36: 4 | F36: 5 | G36: 6 | H36: 7 | I36: 8 | J36: 9 | K36: 10 | L36: 11 | M36: 12
A37: last order starts in month 1 | B37: =0+B16 | C37: =0+C16 | D37: =0+D16 | E37: =0+E16 | F37: =0+F16 | G37: =0+G16 | H37: =0+H16 | I37: =0+I16 | ... M37: =0+M16
A38: last order starts in month 2 | C38: =$B$32+C17 | D38: =$B$32+D17 | E38: =$B$32+E17 | F38: =$B$32+F17 | G38: =$B$32+G17 | H38: =$B$32+H17 | I38: =$B$32+I17 | J38: =$B$32+J17 | ... M38: =$B$32+M17
A39: last order starts in month 3 | D39: =$C$32+D18 | E39: =$C$32+E18 | F39: =$C$32+F18 | G39: =$C$32+G18 | H39: =$C$32+H18 | I39: =$C$32+I18 | J39: =$C$32+J18 | K39: =$C$32+K18 | ... M39: =$C$32+M18
A40: last order starts in month 4 | E40: =$D$32+E19 | F40: =$D$32+F19 | G40: =$D$32+G19 | H40: =$D$32+H19 | I40: =$D$32+I19 | J40: =$D$32+J19 | K40: =$D$32+K19 | L40: =$D$32+L19 | M40: =$D$32+M19
A41: last order starts in month 5 | F41: =$E$32+F20 | G41: =$E$32+G20 | H41: =$E$32+H20 | I41: =$E$32+I20 | J41: =$E$32+J20 | K41: =$E$32+K20 | L41: =$E$32+L20 | M41: =$E$32+M20
A42: last order starts in month 6 | G42: =$F$32+G21 | H42: =$F$32+H21 | I42: =$F$32+I21 | J42: =$F$32+J21 | K42: =$F$32+K21 | L42: =$F$32+L21 | M42: =$F$32+M21
A43: last order starts in month 7 | H43: =$G$32+H22 | I43: =$G$32+I22 | J43: =$G$32+J22 | K43: =$G$32+K22 | L43: =$G$32+L22 | M43: =$G$32+M22
A44: last order starts in month 8 | I44: =$H$32+I23 | J44: =$H$32+J23 | K44: =$H$32+K23 | L44: =$H$32+L23 | M44: =$H$32+M23
...

Sheet Heuristics
A1: Three heuristics, one procedure
A2: Chapter 5, section 5.5. Each rule extends a window from the order month until its own test says stop.
A4: RESULTS
B5: Silver-Meal | C5: Least unit cost | D5: Part-period balancing
A6: Orders placed | B6: =COUNTIF(C73:C84,">0") | C6: =COUNTIF(G73:G84,">0") | D6: =COUNTIF(K73:K84,">0")
A7: Relevant cost | B7: =E85+F85 | C7: =I85+J85 | D7: =M85+N85
A8: Penalty against the optimum | B8: =B7/WagnerWhitin!$B$5-1 | C8: =C7/WagnerWhitin!$B$5-1 | D8: =D7/WagnerWhitin!$B$5-1
A10: CHECK with the data as shipped
A11: Silver-Meal $2,660, 7.26% above the optimum. Least unit cost $3,040, 22.58%.
A12: Part-period balancing $2,600, 4.84%. All three place five orders; the optimum places six.
A13: The optimum on the WagnerWhitin sheet is $2,480.
A14: SILVER-MEAL the relevant cost of the window, divided by its length
A15: Extend while the cost per period falls. Stop at the first month that raises it. | O15: stop here?
A16: t \ u | B16: 1 | C16: 2 | D16: 3 | E16: 4 | F16: 5 | G16: 6 | H16: 7 | I16: 8 | J16: 9 | K16: 10 | L16: 11 | M16: 12 | O16: 1 | P16: 2 | Q16: 3 | R16: 4 | S16: 5 | T16: 6 | U16: 7 | V16: 8 | W16: 9 | X16: 10 | Y16: 11 | Z16: 12 | AA16: stops at
A17: 1 | B17: =WagnerWhitin!B16/1 | C17: =WagnerWhitin!C16/2 | D17: =WagnerWhitin!D16/3 | E17: =WagnerWhitin!E16/4 | F17: =WagnerWhitin!F16/5 | G17: =WagnerWhitin!G16/6 | H17: =WagnerWhitin!H16/7 | I17: =WagnerWhitin!I16/8 | J17: =WagnerWhitin!J16/9 | K17: =WagnerWhitin!K16/10 | L17: =WagnerWhitin!L16/11 | M17: =WagnerWhitin!M16/12 | O17: =IF(C17>B17+0.000000001,1,0) | P17: =IF(D17>C17+0.000000001,1,0) | Q17: =IF(E17>D17+0.000000001,1,0) | R17: =IF(F17>E17+0.000000001,1,0) | S17: =IF(G17>F17+0.000000001,1,0) | T17: =IF(H17>G17+0.000000001,1,0) | U17: =IF(I17>H17+0.000000001,1,0) | V17: =IF(J17>I17+0.000000001,1,0) | ... Y17: =IF(M17>L17+0.000000001,1,0) | Z17: =1 | AA17: =MATCH(1,O17:Z17,0)
A18: 2 | C18: =WagnerWhitin!C17/1 | D18: =WagnerWhitin!D17/2 | E18: =WagnerWhitin!E17/3 | F18: =WagnerWhitin!F17/4 | G18: =WagnerWhitin!G17/5 | H18: =WagnerWhitin!H17/6 | I18: =WagnerWhitin!I17/7 | J18: =WagnerWhitin!J17/8 | K18: =WagnerWhitin!K17/9 | L18: =WagnerWhitin!L17/10 | M18: =WagnerWhitin!M17/11 | P18: =IF(D18>C18+0.000000001,1,0) | Q18: =IF(E18>D18+0.000000001,1,0) | R18: =IF(F18>E18+0.000000001,1,0) | S18: =IF(G18>F18+0.000000001,1,0) | T18: =IF(H18>G18+0.000000001,1,0) | U18: =IF(I18>H18+0.000000001,1,0) | V18: =IF(J18>I18+0.000000001,1,0) | W18: =IF(K18>J18+0.000000001,1,0) | ... Y18: =IF(M18>L18+0.000000001,1,0) | Z18: =1 | AA18: =MATCH(1,O18:Z18,0)
A19: 3 | D19: =WagnerWhitin!D18/1 | E19: =WagnerWhitin!E18/2 | F19: =WagnerWhitin!F18/3 | G19: =WagnerWhitin!G18/4 | H19: =WagnerWhitin!H18/5 | I19: =WagnerWhitin!I18/6 | J19: =WagnerWhitin!J18/7 | K19: =WagnerWhitin!K18/8 | L19: =WagnerWhitin!L18/9 | M19: =WagnerWhitin!M18/10 | Q19: =IF(E19>D19+0.000000001,1,0) | R19: =IF(F19>E19+0.000000001,1,0) | S19: =IF(G19>F19+0.000000001,1,0) | T19: =IF(H19>G19+0.000000001,1,0) | U19: =IF(I19>H19+0.000000001,1,0) | V19: =IF(J19>I19+0.000000001,1,0) | W19: =IF(K19>J19+0.000000001,1,0) | X19: =IF(L19>K19+0.000000001,1,0) | Y19: =IF(M19>L19+0.000000001,1,0) | Z19: =1 | AA19: =MATCH(1,O19:Z19,0)
A20: 4 | E20: =WagnerWhitin!E19/1 | F20: =WagnerWhitin!F19/2 | G20: =WagnerWhitin!G19/3 | H20: =WagnerWhitin!H19/4 | I20: =WagnerWhitin!I19/5 | J20: =WagnerWhitin!J19/6 | K20: =WagnerWhitin!K19/7 | L20: =WagnerWhitin!L19/8 | M20: =WagnerWhitin!M19/9 | R20: =IF(F20>E20+0.000000001,1,0) | S20: =IF(G20>F20+0.000000001,1,0) | T20: =IF(H20>G20+0.000000001,1,0) | U20: =IF(I20>H20+0.000000001,1,0) | V20: =IF(J20>I20+0.000000001,1,0) | W20: =IF(K20>J20+0.000000001,1,0) | X20: =IF(L20>K20+0.000000001,1,0) | Y20: =IF(M20>L20+0.000000001,1,0) | Z20: =1 | AA20: =MATCH(1,O20:Z20,0)
A21: 5 | F21: =WagnerWhitin!F20/1 | G21: =WagnerWhitin!G20/2 | H21: =WagnerWhitin!H20/3 | I21: =WagnerWhitin!I20/4 | J21: =WagnerWhitin!J20/5 | K21: =WagnerWhitin!K20/6 | L21: =WagnerWhitin!L20/7 | M21: =WagnerWhitin!M20/8 | S21: =IF(G21>F21+0.000000001,1,0) | T21: =IF(H21>G21+0.000000001,1,0) | U21: =IF(I21>H21+0.000000001,1,0) | V21: =IF(J21>I21+0.000000001,1,0) | W21: =IF(K21>J21+0.000000001,1,0) | X21: =IF(L21>K21+0.000000001,1,0) | Y21: =IF(M21>L21+0.000000001,1,0) | Z21: =1 | AA21: =MATCH(1,O21:Z21,0)
A22: 6 | G22: =WagnerWhitin!G21/1 | H22: =WagnerWhitin!H21/2 | I22: =WagnerWhitin!I21/3 | J22: =WagnerWhitin!J21/4 | K22: =WagnerWhitin!K21/5 | L22: =WagnerWhitin!L21/6 | M22: =WagnerWhitin!M21/7 | T22: =IF(H22>G22+0.000000001,1,0) | U22: =IF(I22>H22+0.000000001,1,0) | V22: =IF(J22>I22+0.000000001,1,0) | W22: =IF(K22>J22+0.000000001,1,0) | X22: =IF(L22>K22+0.000000001,1,0) | Y22: =IF(M22>L22+0.000000001,1,0) | Z22: =1 | AA22: =MATCH(1,O22:Z22,0)
A23: 7 | H23: =WagnerWhitin!H22/1 | I23: =WagnerWhitin!I22/2 | J23: =WagnerWhitin!J22/3 | K23: =WagnerWhitin!K22/4 | L23: =WagnerWhitin!L22/5 | M23: =WagnerWhitin!M22/6 | U23: =IF(I23>H23+0.000000001,1,0) | V23: =IF(J23>I23+0.000000001,1,0) | W23: =IF(K23>J23+0.000000001,1,0) | X23: =IF(L23>K23+0.000000001,1,0) | Y23: =IF(M23>L23+0.000000001,1,0) | Z23: =1 | AA23: =MATCH(1,O23:Z23,0)
A24: 8 | I24: =WagnerWhitin!I23/1 | J24: =WagnerWhitin!J23/2 | K24: =WagnerWhitin!K23/3 | L24: =WagnerWhitin!L23/4 | M24: =WagnerWhitin!M23/5 | V24: =IF(J24>I24+0.000000001,1,0) | W24: =IF(K24>J24+0.000000001,1,0) | X24: =IF(L24>K24+0.000000001,1,0) | Y24: =IF(M24>L24+0.000000001,1,0) | Z24: =1 | AA24: =MATCH(1,O24:Z24,0)
A25: 9 | J25: =WagnerWhitin!J24/1 | K25: =WagnerWhitin!K24/2 | L25: =WagnerWhitin!L24/3 | M25: =WagnerWhitin!M24/4 | W25: =IF(K25>J25+0.000000001,1,0) | X25: =IF(L25>K25+0.000000001,1,0) | Y25: =IF(M25>L25+0.000000001,1,0) | Z25: =1 | AA25: =MATCH(1,O25:Z25,0)
A26: 10 | K26: =WagnerWhitin!K25/1 | L26: =WagnerWhitin!L25/2 | M26: =WagnerWhitin!M25/3 | X26: =IF(L26>K26+0.000000001,1,0) | Y26: =IF(M26>L26+0.000000001,1,0) | Z26: =1 | AA26: =MATCH(1,O26:Z26,0)
A27: 11 | L27: =WagnerWhitin!L26/1 | M27: =WagnerWhitin!M26/2 | Y27: =IF(M27>L27+0.000000001,1,0) | Z27: =1 | AA27: =MATCH(1,O27:Z27,0)
A28: 12 | M28: =WagnerWhitin!M27/1 | Z28: =1 | AA28: =MATCH(1,O28:Z28,0)
A30: LEAST UNIT COST the relevant cost of the window, divided by the units it covers
A31: A window covering no units has no cost per unit, so it is left blank and stepped over. | O31: stop here?
A32: t \ u | B32: 1 | C32: 2 | D32: 3 | E32: 4 | F32: 5 | G32: 6 | H32: 7 | I32: 8 | J32: 9 | K32: 10 | L32: 11 | M32: 12 | O32: 1 | P32: 2 | Q32: 3 | R32: 4 | S32: 5 | T32: 6 | U32: 7 | V32: 8 | W32: 9 | X32: 10 | Y32: 11 | Z32: 12 | AA32: stops at
A33: 1 | B33: =IF(SUM(INDEX(Dls_d,1):INDEX(Dls_d,1))=0,"",WagnerWhitin!B16/SUM(INDEX(Dls_d,1):INDEX(Dls_d,1))) | C33: =IF(SUM(INDEX(Dls_d,1):INDEX(Dls_d,2))=0,"",WagnerWhitin!C16/SUM(INDEX(Dls_d,1):INDEX(Dls_d,2))) | D33: =IF(SUM(INDEX(Dls_d,1):INDEX(Dls_d,3))=0,"",WagnerWhitin!D16/SUM(INDEX(Dls_d,1):INDEX(Dls_d,3))) | E33: =IF(SUM(INDEX(Dls_d,1):INDEX(Dls_d,4))=0,"",WagnerWhitin!E16/SUM(INDEX(Dls_d,1):INDEX(Dls_d,4))) | F33: =IF(SUM(INDEX(Dls_d,1):INDEX(Dls_d,5))=0,"",WagnerWhitin!F16/SUM(INDEX(Dls_d,1):INDEX(Dls_d,5))) | G33: =IF(SUM(INDEX(Dls_d,1):INDEX(Dls_d,6))=0,"",WagnerWhitin!G16/SUM(INDEX(Dls_d,1):INDEX(Dls_d,6))) | H33: =IF(SUM(INDEX(Dls_d,1):INDEX(Dls_d,7))=0,"",WagnerWhitin!H16/SUM(INDEX(Dls_d,1):INDEX(Dls_d,7))) | I33: =IF(SUM(INDEX(Dls_d,1):INDEX(Dls_d,8))=0,"",WagnerWhitin!I16/SUM(INDEX(Dls_d,1):INDEX(Dls_d,8))) | J33: =IF(SUM(INDEX(Dls_d,1):INDEX(Dls_d,9))=0,"",WagnerWhitin!J16/SUM(INDEX(Dls_d,1):INDEX(Dls_d,9))) | K33: =IF(SUM(INDEX(Dls_d,1):INDEX(Dls_d,10))=0,"",WagnerWhitin!K16/SUM(INDEX(Dls_d,1):INDEX(Dls_d,10))) | L33: =IF(SUM(INDEX(Dls_d,1):INDEX(Dls_d,11))=0,"",WagnerWhitin!L16/SUM(INDEX(Dls_d,1):INDEX(Dls_d,11))) | M33: =IF(SUM(INDEX(Dls_d,1):INDEX(Dls_d,12))=0,"",WagnerWhitin!M16/SUM(INDEX(Dls_d,1):INDEX(Dls_d,12))) | O33: =IF(B33="",0,IF(C33="",0,IF(C33>B33+0.000000001,1,0))) | P33: =IF(C33="",0,IF(D33="",0,IF(D33>C33+0.000000001,1,0))) | Q33: =IF(D33="",0,IF(E33="",0,IF(E33>D33+0.000000001,1,0))) | R33: =IF(E33="",0,IF(F33="",0,IF(F33>E33+0.000000001,1,0))) | S33: =IF(F33="",0,IF(G33="",0,IF(G33>F33+0.000000001,1,0))) | T33: =IF(G33="",0,IF(H33="",0,IF(H33>G33+0.000000001,1,0))) | U33: =IF(H33="",0,IF(I33="",0,IF(I33>H33+0.000000001,1,0))) | V33: =IF(I33="",0,IF(J33="",0,IF(J33>I33+0.000000001,1,0))) | ... Y33: =IF(L33="",0,IF(M33="",0,IF(M33>L33+0.000000001,1,0))) | Z33: =IF(M33="",0,1) | AA33: =MATCH(1,O33:Z33,0)
A34: 2 | C34: =IF(SUM(INDEX(Dls_d,2):INDEX(Dls_d,2))=0,"",WagnerWhitin!C17/SUM(INDEX(Dls_d,2):INDEX(Dls_d,2))) | D34: =IF(SUM(INDEX(Dls_d,2):INDEX(Dls_d,3))=0,"",WagnerWhitin!D17/SUM(INDEX(Dls_d,2):INDEX(Dls_d,3))) | E34: =IF(SUM(INDEX(Dls_d,2):INDEX(Dls_d,4))=0,"",WagnerWhitin!E17/SUM(INDEX(Dls_d,2):INDEX(Dls_d,4))) | F34: =IF(SUM(INDEX(Dls_d,2):INDEX(Dls_d,5))=0,"",WagnerWhitin!F17/SUM(INDEX(Dls_d,2):INDEX(Dls_d,5))) | G34: =IF(SUM(INDEX(Dls_d,2):INDEX(Dls_d,6))=0,"",WagnerWhitin!G17/SUM(INDEX(Dls_d,2):INDEX(Dls_d,6))) | H34: =IF(SUM(INDEX(Dls_d,2):INDEX(Dls_d,7))=0,"",WagnerWhitin!H17/SUM(INDEX(Dls_d,2):INDEX(Dls_d,7))) | I34: =IF(SUM(INDEX(Dls_d,2):INDEX(Dls_d,8))=0,"",WagnerWhitin!I17/SUM(INDEX(Dls_d,2):INDEX(Dls_d,8))) | J34: =IF(SUM(INDEX(Dls_d,2):INDEX(Dls_d,9))=0,"",WagnerWhitin!J17/SUM(INDEX(Dls_d,2):INDEX(Dls_d,9))) | K34: =IF(SUM(INDEX(Dls_d,2):INDEX(Dls_d,10))=0,"",WagnerWhitin!K17/SUM(INDEX(Dls_d,2):INDEX(Dls_d,10))) | L34: =IF(SUM(INDEX(Dls_d,2):INDEX(Dls_d,11))=0,"",WagnerWhitin!L17/SUM(INDEX(Dls_d,2):INDEX(Dls_d,11))) | M34: =IF(SUM(INDEX(Dls_d,2):INDEX(Dls_d,12))=0,"",WagnerWhitin!M17/SUM(INDEX(Dls_d,2):INDEX(Dls_d,12))) | P34: =IF(C34="",0,IF(D34="",0,IF(D34>C34+0.000000001,1,0))) | Q34: =IF(D34="",0,IF(E34="",0,IF(E34>D34+0.000000001,1,0))) | R34: =IF(E34="",0,IF(F34="",0,IF(F34>E34+0.000000001,1,0))) | S34: =IF(F34="",0,IF(G34="",0,IF(G34>F34+0.000000001,1,0))) | T34: =IF(G34="",0,IF(H34="",0,IF(H34>G34+0.000000001,1,0))) | U34: =IF(H34="",0,IF(I34="",0,IF(I34>H34+0.000000001,1,0))) | V34: =IF(I34="",0,IF(J34="",0,IF(J34>I34+0.000000001,1,0))) | W34: =IF(J34="",0,IF(K34="",0,IF(K34>J34+0.000000001,1,0))) | ... Y34: =IF(L34="",0,IF(M34="",0,IF(M34>L34+0.000000001,1,0))) | Z34: =IF(M34="",0,1) | AA34: =MATCH(1,O34:Z34,0)
A35: 3 | D35: =IF(SUM(INDEX(Dls_d,3):INDEX(Dls_d,3))=0,"",WagnerWhitin!D18/SUM(INDEX(Dls_d,3):INDEX(Dls_d,3))) | E35: =IF(SUM(INDEX(Dls_d,3):INDEX(Dls_d,4))=0,"",WagnerWhitin!E18/SUM(INDEX(Dls_d,3):INDEX(Dls_d,4))) | F35: =IF(SUM(INDEX(Dls_d,3):INDEX(Dls_d,5))=0,"",WagnerWhitin!F18/SUM(INDEX(Dls_d,3):INDEX(Dls_d,5))) | G35: =IF(SUM(INDEX(Dls_d,3):INDEX(Dls_d,6))=0,"",WagnerWhitin!G18/SUM(INDEX(Dls_d,3):INDEX(Dls_d,6))) | H35: =IF(SUM(INDEX(Dls_d,3):INDEX(Dls_d,7))=0,"",WagnerWhitin!H18/SUM(INDEX(Dls_d,3):INDEX(Dls_d,7))) | I35: =IF(SUM(INDEX(Dls_d,3):INDEX(Dls_d,8))=0,"",WagnerWhitin!I18/SUM(INDEX(Dls_d,3):INDEX(Dls_d,8))) | J35: =IF(SUM(INDEX(Dls_d,3):INDEX(Dls_d,9))=0,"",WagnerWhitin!J18/SUM(INDEX(Dls_d,3):INDEX(Dls_d,9))) | K35: =IF(SUM(INDEX(Dls_d,3):INDEX(Dls_d,10))=0,"",WagnerWhitin!K18/SUM(INDEX(Dls_d,3):INDEX(Dls_d,10))) | L35: =IF(SUM(INDEX(Dls_d,3):INDEX(Dls_d,11))=0,"",WagnerWhitin!L18/SUM(INDEX(Dls_d,3):INDEX(Dls_d,11))) | M35: =IF(SUM(INDEX(Dls_d,3):INDEX(Dls_d,12))=0,"",WagnerWhitin!M18/SUM(INDEX(Dls_d,3):INDEX(Dls_d,12))) | Q35: =IF(D35="",0,IF(E35="",0,IF(E35>D35+0.000000001,1,0))) | R35: =IF(E35="",0,IF(F35="",0,IF(F35>E35+0.000000001,1,0))) | S35: =IF(F35="",0,IF(G35="",0,IF(G35>F35+0.000000001,1,0))) | T35: =IF(G35="",0,IF(H35="",0,IF(H35>G35+0.000000001,1,0))) | U35: =IF(H35="",0,IF(I35="",0,IF(I35>H35+0.000000001,1,0))) | V35: =IF(I35="",0,IF(J35="",0,IF(J35>I35+0.000000001,1,0))) | W35: =IF(J35="",0,IF(K35="",0,IF(K35>J35+0.000000001,1,0))) | X35: =IF(K35="",0,IF(L35="",0,IF(L35>K35+0.000000001,1,0))) | Y35: =IF(L35="",0,IF(M35="",0,IF(M35>L35+0.000000001,1,0))) | Z35: =IF(M35="",0,1) | AA35: =MATCH(1,O35:Z35,0)
A36: 4 | E36: =IF(SUM(INDEX(Dls_d,4):INDEX(Dls_d,4))=0,"",WagnerWhitin!E19/SUM(INDEX(Dls_d,4):INDEX(Dls_d,4))) | F36: =IF(SUM(INDEX(Dls_d,4):INDEX(Dls_d,5))=0,"",WagnerWhitin!F19/SUM(INDEX(Dls_d,4):INDEX(Dls_d,5))) | G36: =IF(SUM(INDEX(Dls_d,4):INDEX(Dls_d,6))=0,"",WagnerWhitin!G19/SUM(INDEX(Dls_d,4):INDEX(Dls_d,6))) | H36: =IF(SUM(INDEX(Dls_d,4):INDEX(Dls_d,7))=0,"",WagnerWhitin!H19/SUM(INDEX(Dls_d,4):INDEX(Dls_d,7))) | I36: =IF(SUM(INDEX(Dls_d,4):INDEX(Dls_d,8))=0,"",WagnerWhitin!I19/SUM(INDEX(Dls_d,4):INDEX(Dls_d,8))) | J36: =IF(SUM(INDEX(Dls_d,4):INDEX(Dls_d,9))=0,"",WagnerWhitin!J19/SUM(INDEX(Dls_d,4):INDEX(Dls_d,9))) | K36: =IF(SUM(INDEX(Dls_d,4):INDEX(Dls_d,10))=0,"",WagnerWhitin!K19/SUM(INDEX(Dls_d,4):INDEX(Dls_d,10))) | L36: =IF(SUM(INDEX(Dls_d,4):INDEX(Dls_d,11))=0,"",WagnerWhitin!L19/SUM(INDEX(Dls_d,4):INDEX(Dls_d,11))) | M36: =IF(SUM(INDEX(Dls_d,4):INDEX(Dls_d,12))=0,"",WagnerWhitin!M19/SUM(INDEX(Dls_d,4):INDEX(Dls_d,12))) | R36: =IF(E36="",0,IF(F36="",0,IF(F36>E36+0.000000001,1,0))) | S36: =IF(F36="",0,IF(G36="",0,IF(G36>F36+0.000000001,1,0))) | T36: =IF(G36="",0,IF(H36="",0,IF(H36>G36+0.000000001,1,0))) | U36: =IF(H36="",0,IF(I36="",0,IF(I36>H36+0.000000001,1,0))) | V36: =IF(I36="",0,IF(J36="",0,IF(J36>I36+0.000000001,1,0))) | W36: =IF(J36="",0,IF(K36="",0,IF(K36>J36+0.000000001,1,0))) | X36: =IF(K36="",0,IF(L36="",0,IF(L36>K36+0.000000001,1,0))) | Y36: =IF(L36="",0,IF(M36="",0,IF(M36>L36+0.000000001,1,0))) | Z36: =IF(M36="",0,1) | AA36: =MATCH(1,O36:Z36,0)
A37: 5 | F37: =IF(SUM(INDEX(Dls_d,5):INDEX(Dls_d,5))=0,"",WagnerWhitin!F20/SUM(INDEX(Dls_d,5):INDEX(Dls_d,5))) | G37: =IF(SUM(INDEX(Dls_d,5):INDEX(Dls_d,6))=0,"",WagnerWhitin!G20/SUM(INDEX(Dls_d,5):INDEX(Dls_d,6))) | H37: =IF(SUM(INDEX(Dls_d,5):INDEX(Dls_d,7))=0,"",WagnerWhitin!H20/SUM(INDEX(Dls_d,5):INDEX(Dls_d,7))) | I37: =IF(SUM(INDEX(Dls_d,5):INDEX(Dls_d,8))=0,"",WagnerWhitin!I20/SUM(INDEX(Dls_d,5):INDEX(Dls_d,8))) | J37: =IF(SUM(INDEX(Dls_d,5):INDEX(Dls_d,9))=0,"",WagnerWhitin!J20/SUM(INDEX(Dls_d,5):INDEX(Dls_d,9))) | K37: =IF(SUM(INDEX(Dls_d,5):INDEX(Dls_d,10))=0,"",WagnerWhitin!K20/SUM(INDEX(Dls_d,5):INDEX(Dls_d,10))) | L37: =IF(SUM(INDEX(Dls_d,5):INDEX(Dls_d,11))=0,"",WagnerWhitin!L20/SUM(INDEX(Dls_d,5):INDEX(Dls_d,11))) | M37: =IF(SUM(INDEX(Dls_d,5):INDEX(Dls_d,12))=0,"",WagnerWhitin!M20/SUM(INDEX(Dls_d,5):INDEX(Dls_d,12))) | S37: =IF(F37="",0,IF(G37="",0,IF(G37>F37+0.000000001,1,0))) | T37: =IF(G37="",0,IF(H37="",0,IF(H37>G37+0.000000001,1,0))) | U37: =IF(H37="",0,IF(I37="",0,IF(I37>H37+0.000000001,1,0))) | V37: =IF(I37="",0,IF(J37="",0,IF(J37>I37+0.000000001,1,0))) | W37: =IF(J37="",0,IF(K37="",0,IF(K37>J37+0.000000001,1,0))) | X37: =IF(K37="",0,IF(L37="",0,IF(L37>K37+0.000000001,1,0))) | Y37: =IF(L37="",0,IF(M37="",0,IF(M37>L37+0.000000001,1,0))) | Z37: =IF(M37="",0,1) | AA37: =MATCH(1,O37:Z37,0)
A38: 6 | G38: =IF(SUM(INDEX(Dls_d,6):INDEX(Dls_d,6))=0,"",WagnerWhitin!G21/SUM(INDEX(Dls_d,6):INDEX(Dls_d,6))) | H38: =IF(SUM(INDEX(Dls_d,6):INDEX(Dls_d,7))=0,"",WagnerWhitin!H21/SUM(INDEX(Dls_d,6):INDEX(Dls_d,7))) | I38: =IF(SUM(INDEX(Dls_d,6):INDEX(Dls_d,8))=0,"",WagnerWhitin!I21/SUM(INDEX(Dls_d,6):INDEX(Dls_d,8))) | J38: =IF(SUM(INDEX(Dls_d,6):INDEX(Dls_d,9))=0,"",WagnerWhitin!J21/SUM(INDEX(Dls_d,6):INDEX(Dls_d,9))) | K38: =IF(SUM(INDEX(Dls_d,6):INDEX(Dls_d,10))=0,"",WagnerWhitin!K21/SUM(INDEX(Dls_d,6):INDEX(Dls_d,10))) | L38: =IF(SUM(INDEX(Dls_d,6):INDEX(Dls_d,11))=0,"",WagnerWhitin!L21/SUM(INDEX(Dls_d,6):INDEX(Dls_d,11))) | M38: =IF(SUM(INDEX(Dls_d,6):INDEX(Dls_d,12))=0,"",WagnerWhitin!M21/SUM(INDEX(Dls_d,6):INDEX(Dls_d,12))) | T38: =IF(G38="",0,IF(H38="",0,IF(H38>G38+0.000000001,1,0))) | U38: =IF(H38="",0,IF(I38="",0,IF(I38>H38+0.000000001,1,0))) | V38: =IF(I38="",0,IF(J38="",0,IF(J38>I38+0.000000001,1,0))) | W38: =IF(J38="",0,IF(K38="",0,IF(K38>J38+0.000000001,1,0))) | X38: =IF(K38="",0,IF(L38="",0,IF(L38>K38+0.000000001,1,0))) | Y38: =IF(L38="",0,IF(M38="",0,IF(M38>L38+0.000000001,1,0))) | Z38: =IF(M38="",0,1) | AA38: =MATCH(1,O38:Z38,0)
A39: 7 | H39: =IF(SUM(INDEX(Dls_d,7):INDEX(Dls_d,7))=0,"",WagnerWhitin!H22/SUM(INDEX(Dls_d,7):INDEX(Dls_d,7))) | I39: =IF(SUM(INDEX(Dls_d,7):INDEX(Dls_d,8))=0,"",WagnerWhitin!I22/SUM(INDEX(Dls_d,7):INDEX(Dls_d,8))) | J39: =IF(SUM(INDEX(Dls_d,7):INDEX(Dls_d,9))=0,"",WagnerWhitin!J22/SUM(INDEX(Dls_d,7):INDEX(Dls_d,9))) | K39: =IF(SUM(INDEX(Dls_d,7):INDEX(Dls_d,10))=0,"",WagnerWhitin!K22/SUM(INDEX(Dls_d,7):INDEX(Dls_d,10))) | L39: =IF(SUM(INDEX(Dls_d,7):INDEX(Dls_d,11))=0,"",WagnerWhitin!L22/SUM(INDEX(Dls_d,7):INDEX(Dls_d,11))) | M39: =IF(SUM(INDEX(Dls_d,7):INDEX(Dls_d,12))=0,"",WagnerWhitin!M22/SUM(INDEX(Dls_d,7):INDEX(Dls_d,12))) | U39: =IF(H39="",0,IF(I39="",0,IF(I39>H39+0.000000001,1,0))) | V39: =IF(I39="",0,IF(J39="",0,IF(J39>I39+0.000000001,1,0))) | W39: =IF(J39="",0,IF(K39="",0,IF(K39>J39+0.000000001,1,0))) | X39: =IF(K39="",0,IF(L39="",0,IF(L39>K39+0.000000001,1,0))) | Y39: =IF(L39="",0,IF(M39="",0,IF(M39>L39+0.000000001,1,0))) | Z39: =IF(M39="",0,1) | AA39: =MATCH(1,O39:Z39,0)
A40: 8 | I40: =IF(SUM(INDEX(Dls_d,8):INDEX(Dls_d,8))=0,"",WagnerWhitin!I23/SUM(INDEX(Dls_d,8):INDEX(Dls_d,8))) | J40: =IF(SUM(INDEX(Dls_d,8):INDEX(Dls_d,9))=0,"",WagnerWhitin!J23/SUM(INDEX(Dls_d,8):INDEX(Dls_d,9))) | K40: =IF(SUM(INDEX(Dls_d,8):INDEX(Dls_d,10))=0,"",WagnerWhitin!K23/SUM(INDEX(Dls_d,8):INDEX(Dls_d,10))) | L40: =IF(SUM(INDEX(Dls_d,8):INDEX(Dls_d,11))=0,"",WagnerWhitin!L23/SUM(INDEX(Dls_d,8):INDEX(Dls_d,11))) | M40: =IF(SUM(INDEX(Dls_d,8):INDEX(Dls_d,12))=0,"",WagnerWhitin!M23/SUM(INDEX(Dls_d,8):INDEX(Dls_d,12))) | V40: =IF(I40="",0,IF(J40="",0,IF(J40>I40+0.000000001,1,0))) | W40: =IF(J40="",0,IF(K40="",0,IF(K40>J40+0.000000001,1,0))) | X40: =IF(K40="",0,IF(L40="",0,IF(L40>K40+0.000000001,1,0))) | Y40: =IF(L40="",0,IF(M40="",0,IF(M40>L40+0.000000001,1,0))) | Z40: =IF(M40="",0,1) | AA40: =MATCH(1,O40:Z40,0)
A41: 9 | J41: =IF(SUM(INDEX(Dls_d,9):INDEX(Dls_d,9))=0,"",WagnerWhitin!J24/SUM(INDEX(Dls_d,9):INDEX(Dls_d,9))) | K41: =IF(SUM(INDEX(Dls_d,9):INDEX(Dls_d,10))=0,"",WagnerWhitin!K24/SUM(INDEX(Dls_d,9):INDEX(Dls_d,10))) | L41: =IF(SUM(INDEX(Dls_d,9):INDEX(Dls_d,11))=0,"",WagnerWhitin!L24/SUM(INDEX(Dls_d,9):INDEX(Dls_d,11))) | M41: =IF(SUM(INDEX(Dls_d,9):INDEX(Dls_d,12))=0,"",WagnerWhitin!M24/SUM(INDEX(Dls_d,9):INDEX(Dls_d,12))) | W41: =IF(J41="",0,IF(K41="",0,IF(K41>J41+0.000000001,1,0))) | X41: =IF(K41="",0,IF(L41="",0,IF(L41>K41+0.000000001,1,0))) | Y41: =IF(L41="",0,IF(M41="",0,IF(M41>L41+0.000000001,1,0))) | Z41: =IF(M41="",0,1) | AA41: =MATCH(1,O41:Z41,0)
A42: 10 | K42: =IF(SUM(INDEX(Dls_d,10):INDEX(Dls_d,10))=0,"",WagnerWhitin!K25/SUM(INDEX(Dls_d,10):INDEX(Dls_d,10))) | L42: =IF(SUM(INDEX(Dls_d,10):INDEX(Dls_d,11))=0,"",WagnerWhitin!L25/SUM(INDEX(Dls_d,10):INDEX(Dls_d,11))) | M42: =IF(SUM(INDEX(Dls_d,10):INDEX(Dls_d,12))=0,"",WagnerWhitin!M25/SUM(INDEX(Dls_d,10):INDEX(Dls_d,12))) | X42: =IF(K42="",0,IF(L42="",0,IF(L42>K42+0.000000001,1,0))) | Y42: =IF(L42="",0,IF(M42="",0,IF(M42>L42+0.000000001,1,0))) | Z42: =IF(M42="",0,1) | AA42: =MATCH(1,O42:Z42,0)
A43: 11 | L43: =IF(SUM(INDEX(Dls_d,11):INDEX(Dls_d,11))=0,"",WagnerWhitin!L26/SUM(INDEX(Dls_d,11):INDEX(Dls_d,11))) | M43: =IF(SUM(INDEX(Dls_d,11):INDEX(Dls_d,12))=0,"",WagnerWhitin!M26/SUM(INDEX(Dls_d,11):INDEX(Dls_d,12))) | Y43: =IF(L43="",0,IF(M43="",0,IF(M43>L43+0.000000001,1,0))) | Z43: =IF(M43="",0,1) | AA43: =MATCH(1,O43:Z43,0)
...

Sheet Solver
A1: The same problem for Solver
A2: Chapter 5, section 5.4.3.
A4: OBJECTIVE
A5: Total relevant cost, minimize this | B5: =SUM(F14:F25)+SUM(G14:G25)
A6: Largest shortage, which must stay at zero | B6: =-MIN(0,MIN(E14:E25))
A8: HOW
A9: Data > Solver. Set objective B5 to a minimum by changing C14:D25.
A10: Subject to: D14:D25 = binary, C14:C25 >= 0, E14:E25 >= 0, H14:H25 <= 0
A11: Choose the Simplex LP engine. Section 5.4.3 explains why the model is linear in these variables.
A13: Month | B13: Requirement | C13: Order Q(t) | D13: Order? y(t) | E13: End I(t) | F13: Setup | G13: Carrying | H13: Q - My
A14: =INDEX(Dls_t,1) | B14: =INDEX(Dls_d,1) | C14: 220 | D14: 1 | E14: =0+C14-B14 | F14: =D14*INDEX(Dls_k,1) | G14: =E14*INDEX(Dls_h,1) | H14: =C14-1840*D14
A15: =INDEX(Dls_t,2) | B15: =INDEX(Dls_d,2) | C15: 0 | D15: 0 | E15: =E14+C15-B15 | F15: =D15*INDEX(Dls_k,2) | G15: =E15*INDEX(Dls_h,2) | H15: =C15-1840*D15
A16: =INDEX(Dls_t,3) | B16: =INDEX(Dls_d,3) | C16: 0 | D16: 0 | E16: =E15+C16-B16 | F16: =D16*INDEX(Dls_k,3) | G16: =E16*INDEX(Dls_h,3) | H16: =C16-1840*D16
A17: =INDEX(Dls_t,4) | B17: =INDEX(Dls_d,4) | C17: 300 | D17: 1 | E17: =E16+C17-B17 | F17: =D17*INDEX(Dls_k,4) | G17: =E17*INDEX(Dls_h,4) | H17: =C17-1840*D17
A18: =INDEX(Dls_t,5) | B18: =INDEX(Dls_d,5) | C18: 420 | D18: 1 | E18: =E17+C18-B18 | F18: =D18*INDEX(Dls_k,5) | G18: =E18*INDEX(Dls_h,5) | H18: =C18-1840*D18
A19: =INDEX(Dls_t,6) | B19: =INDEX(Dls_d,6) | C19: 420 | D19: 1 | E19: =E18+C19-B19 | F19: =D19*INDEX(Dls_k,6) | G19: =E19*INDEX(Dls_h,6) | H19: =C19-1840*D19
A20: =INDEX(Dls_t,7) | B20: =INDEX(Dls_d,7) | C20: 0 | D20: 0 | E20: =E19+C20-B20 | F20: =D20*INDEX(Dls_k,7) | G20: =E20*INDEX(Dls_h,7) | H20: =C20-1840*D20
A21: =INDEX(Dls_t,8) | B21: =INDEX(Dls_d,8) | C21: 0 | D21: 0 | E21: =E20+C21-B21 | F21: =D21*INDEX(Dls_k,8) | G21: =E21*INDEX(Dls_h,8) | H21: =C21-1840*D21
A22: =INDEX(Dls_t,9) | B22: =INDEX(Dls_d,9) | C22: 0 | D22: 0 | E22: =E21+C22-B22 | F22: =D22*INDEX(Dls_k,9) | G22: =E22*INDEX(Dls_h,9) | H22: =C22-1840*D22
A23: =INDEX(Dls_t,10) | B23: =INDEX(Dls_d,10) | C23: 260 | D23: 1 | E23: =E22+C23-B23 | F23: =D23*INDEX(Dls_k,10) | G23: =E23*INDEX(Dls_h,10) | H23: =C23-1840*D23
A24: =INDEX(Dls_t,11) | B24: =INDEX(Dls_d,11) | C24: 0 | D24: 0 | E24: =E23+C24-B24 | F24: =D24*INDEX(Dls_k,11) | G24: =E24*INDEX(Dls_h,11) | H24: =C24-1840*D24
A25: =INDEX(Dls_t,12) | B25: =INDEX(Dls_d,12) | C25: 220 | D25: 1 | E25: =E24+C25-B25 | F25: =D25*INDEX(Dls_k,12) | G25: =E25*INDEX(Dls_h,12) | H25: =C25-1840*D25
A27: Column H is the linking constraint: an order can be positive only in a month whose flag is one.
A28: M is 1840, the whole horizon's requirement, which is the most any single order would ever carry.
A30: CHECK with the data as shipped
A31: The sheet ships holding the optimal plan, so B5 already reads $2,480 and B6 reads zero.
A32: Clear C14:D25 to zero and Solver should find its way back to $2,480.
